Workbook

Sheet DIF-Rasch-GLP
A1: UJI RASCH DIF (Pendekatan PROX) — Skema GLP
A3: Ambang DIF (logit) - Moderat | B3: 0.5 | N3: Ringkasan Signifikansi Statistik (t-test) | Q3: Ringkasan Kesimpulan Praktis (Kontras)
A4: Ambang DIF (logit) - Besar | B4: 1 | N4: DIF Besar - review | O4: =COUNTIF($AA$11:$AA$110,"DIF Besar - review") -> 0 | Q4: Berpotensi Bias - Tinjau Konten | R4: =COUNTIF($AB$11:$AB$110,"Berpotensi Bias - Tinjau Konten") -> 0
A5: Ambang |t| minimum | B5: 2 | N5: DIF Moderat - cek | O5: =COUNTIF($AA$11:$AA$110,"DIF Moderat - cek") -> 0 | Q5: Indikasi Ringan - Pantau | R5: =COUNTIF($AB$11:$AB$110,"Indikasi Ringan - Pantau") -> 0
A6: Kontras DIF Maksimum (data ini) | B6: =_xlfn.AGGREGATE(14,6,ABS(X11:X110),1) -> 0 | N6: Negligible | O6: =COUNTIF($AA$11:$AA$110,"Negligible") -> 100 | Q6: Tidak Ada Indikasi Bias | R6: =COUNTIF($AB$11:$AB$110,"Tidak Ada Indikasi Bias") -> 100
A8: Jenis Kelamin | B8: =GLP!B2 -> Perempuan | C8: =GLP!C2 -> Laki-Laki | D8: =GLP!D2 -> Perempuan | E8: =GLP!E2 -> Perempuan | F8: =GLP!F2 -> Laki-Laki | G8: =GLP!G2 -> Laki-Laki | H8: =GLP!H2 -> Perempuan | I8: =GLP!I2 -> Laki-Laki | ... K8: =GLP!K2 -> Laki-Laki
A9: Soal | B9: Asesi | L9: N (L) | M9: N (P) | N9: S (L) | O9: S (P) | P9: S adj (L) | Q9: S adj (P) | R9: β mentah (L) | S9: β mentah (P) | T9: β center (L) | U9: β center (P) | V9: SE (L) | W9: SE (P) | X9: Kontras DIF | Y9: SE Gabungan | Z9: t-stat | AA9: Klasifikasi DIF | AB9: Kesimpulan Praktis (Kontras)
B10: 1 | C10: 2 | D10: 3 | E10: 4 | F10: 5 | G10: 6 | H10: 7 | I10: 8 | J10: 9 | K10: 10
A11: =GLP!A5 -> 1. Dalam penerapan GLP, pendekatan manajemen terhadap kendali analisis sangat berbeda dengan standar ISO 17025. Apa perbedaan mendasar tersebut berdasarkan kriteria unjuk kerja? | B11: =GLP!B5 -> 1 | C11: =GLP!C5 -> 1 | D11: =GLP!D5 -> 0 | E11: =GLP!E5 -> 0 | F11: =GLP!F5 -> 0 | G11: =GLP!G5 -> 0 | H11: =GLP!H5 -> 0 | ... K11: =GLP!K5 -> 0 | L11: =COUNTIF($B$8:$K$8,"Laki-Laki") -> 5 | M11: =COUNTIF($B$8:$K$8,"Perempuan") -> 5 | N11: =SUMIF($B$8:$K$8,"Laki-Laki",GLP!B5:K5) -> 1 | O11: =SUMIF($B$8:$K$8,"Perempuan",GLP!B5:K5) -> 1 | P11: =IF(N11=0,0.3,IF(N11=L11,L11-0.3,N11)) -> 1 | Q11: =IF(O11=0,0.3,IF(O11=M11,M11-0.3,O11)) -> 1 | R11: =LN((L11-P11)/P11) -> 1.3862944 | S11: =LN((M11-Q11)/Q11) -> 1.3862944 | T11: =R11-AVERAGE($R$11:$R$110) -> 1.4792803 | U11: =S11-AVERAGE($S$11:$S$110) -> 1.4792803 | V11: =SQRT(1/P11+1/(L11-P11)) -> 1.118034 | W11: =SQRT(1/Q11+1/(M11-Q11)) -> 1.118034 | X11: =T11-U11 -> 0 | Y11: =SQRT(V11^2+W11^2) -> 1.5811388 | Z11: =X11/Y11 -> 0 | AA11: =IF(AND(ABS(X11)>=$B$4,ABS(Z11)>=$B$5),"DIF Besar - review",IF(AND(ABS(X11)>=$B$3,ABS(Z11)>=$B$5),"DIF Moderat - cek","Negligible")) -> Negligible | AB11: =IF(ABS(X11)>=$B$4,"Berpotensi Bias - Tinjau Konten",IF(ABS(X11)>=$B$3,"Indikasi Ringan - Pantau","Tidak Ada Indikasi Bias")) -> Tidak Ada Indikasi Bias
A12: =GLP!A6 -> 2. Aspek paling kritis yang menjadi fokus utama dalam penilaian kesiapan struktur organisasi berstandar GLP adalah... | B12: =GLP!B6 -> 1 | C12: =GLP!C6 -> 1 | D12: =GLP!D6 -> 0 | E12: =GLP!E6 -> 0 | F12: =GLP!F6 -> 0 | G12: =GLP!G6 -> 0 | H12: =GLP!H6 -> 1 | ... K12: =GLP!K6 -> 1 | L12: =COUNTIF($B$8:$K$8,"Laki-Laki") -> 5 | M12: =COUNTIF($B$8:$K$8,"Perempuan") -> 5 | N12: =SUMIF($B$8:$K$8,"Laki-Laki",GLP!B6:K6) -> 3 | O12: =SUMIF($B$8:$K$8,"Perempuan",GLP!B6:K6) -> 3 | P12: =IF(N12=0,0.3,IF(N12=L12,L12-0.3,N12)) -> 3 | Q12: =IF(O12=0,0.3,IF(O12=M12,M12-0.3,O12)) -> 3 | R12: =LN((L12-P12)/P12) -> -0.40546511 | S12: =LN((M12-Q12)/Q12) -> -0.40546511 | T12: =R12-AVERAGE($R$11:$R$110) -> -0.31247915 | U12: =S12-AVERAGE($S$11:$S$110) -> -0.31247915 | V12: =SQRT(1/P12+1/(L12-P12)) -> 0.91287093 | W12: =SQRT(1/Q12+1/(M12-Q12)) -> 0.91287093 | X12: =T12-U12 -> 0 | Y12: =SQRT(V12^2+W12^2) -> 1.2909944 | Z12: =X12/Y12 -> 0 | AA12: =IF(AND(ABS(X12)>=$B$4,ABS(Z12)>=$B$5),"DIF Besar - review",IF(AND(ABS(X12)>=$B$3,ABS(Z12)>=$B$5),"DIF Moderat - cek","Negligible")) -> Negligible | AB12: =IF(ABS(X12)>=$B$4,"Berpotensi Bias - Tinjau Konten",IF(ABS(X12)>=$B$3,"Indikasi Ringan - Pantau","Tidak Ada Indikasi Bias")) -> Tidak Ada Indikasi Bias
A13: =GLP!A7 -> 3. Hierarki dokumen mutu dalam GLP diatur sedemikian rupa untuk memastikan kejelasan operasional. Kedudukan dokumen Rencana Analisis dalam sistem ini adalah... | B13: =GLP!B7 -> 1 | C13: =GLP!C7 -> 1 | D13: =GLP!D7 -> 0 | E13: =GLP!E7 -> 1 | F13: =GLP!F7 -> 0 | G13: =GLP!G7 -> 1 | H13: =GLP!H7 -> 1 | ... K13: =GLP!K7 -> 1 | L13: =COUNTIF($B$8:$K$8,"Laki-Laki") -> 5 | M13: =COUNTIF($B$8:$K$8,"Perempuan") -> 5 | N13: =SUMIF($B$8:$K$8,"Laki-Laki",GLP!B7:K7) -> 4 | O13: =SUMIF($B$8:$K$8,"Perempuan",GLP!B7:K7) -> 4 | P13: =IF(N13=0,0.3,IF(N13=L13,L13-0.3,N13)) -> 4 | Q13: =IF(O13=0,0.3,IF(O13=M13,M13-0.3,O13)) -> 4 | R13: =LN((L13-P13)/P13) -> -1.3862944 | S13: =LN((M13-Q13)/Q13) -> -1.3862944 | T13: =R13-AVERAGE($R$11:$R$110) -> -1.2933084 | U13: =S13-AVERAGE($S$11:$S$110) -> -1.2933084 | V13: =SQRT(1/P13+1/(L13-P13)) -> 1.118034 | W13: =SQRT(1/Q13+1/(M13-Q13)) -> 1.118034 | X13: =T13-U13 -> 0 | Y13: =SQRT(V13^2+W13^2) -> 1.5811388 | Z13: =X13/Y13 -> 0 | AA13: =IF(AND(ABS(X13)>=$B$4,ABS(Z13)>=$B$5),"DIF Besar - review",IF(AND(ABS(X13)>=$B$3,ABS(Z13)>=$B$5),"DIF Moderat - cek","Negligible")) -> Negligible | AB13: =IF(ABS(X13)>=$B$4,"Berpotensi Bias - Tinjau Konten",IF(ABS(X13)>=$B$3,"Indikasi Ringan - Pantau","Tidak Ada Indikasi Bias")) -> Tidak Ada Indikasi Bias
A14: =GLP!A8 -> 4. Jika seorang analis menemukan SOP yang sudah usang di area kerjanya, tindakan apa yang diwajibkan oleh prosedur GLP? | B14: =GLP!B8 -> 1 | C14: =GLP!C8 -> 1 | D14: =GLP!D8 -> 1 | E14: =GLP!E8 -> 1 | F14: =GLP!F8 -> 1 | G14: =GLP!G8 -> 1 | H14: =GLP!H8 -> 0 | ... K14: =GLP!K8 -> 0 | L14: =COUNTIF($B$8:$K$8,"Laki-Laki") -> 5 | M14: =COUNTIF($B$8:$K$8,"Perempuan") -> 5 | N14: =SUMIF($B$8:$K$8,"Laki-Laki",GLP!B8:K8) -> 3 | O14: =SUMIF($B$8:$K$8,"Perempuan",GLP!B8:K8) -> 3 | P14: =IF(N14=0,0.3,IF(N14=L14,L14-0.3,N14)) -> 3 | Q14: =IF(O14=0,0.3,IF(O14=M14,M14-0.3,O14)) -> 3 | R14: =LN((L14-P14)/P14) -> -0.40546511 | S14: =LN((M14-Q14)/Q14) -> -0.40546511 | T14: =R14-AVERAGE($R$11:$R$110) -> -0.31247915 | U14: =S14-AVERAGE($S$11:$S$110) -> -0.31247915 | V14: =SQRT(1/P14+1/(L14-P14)) -> 0.91287093 | W14: =SQRT(1/Q14+1/(M14-Q14)) -> 0.91287093 | X14: =T14-U14 -> 0 | Y14: =SQRT(V14^2+W14^2) -> 1.2909944 | Z14: =X14/Y14 -> 0 | AA14: =IF(AND(ABS(X14)>=$B$4,ABS(Z14)>=$B$5),"DIF Besar - review",IF(AND(ABS(X14)>=$B$3,ABS(Z14)>=$B$5),"DIF Moderat - cek","Negligible")) -> Negligible | AB14: =IF(ABS(X14)>=$B$4,"Berpotensi Bias - Tinjau Konten",IF(ABS(X14)>=$B$3,"Indikasi Ringan - Pantau","Tidak Ada Indikasi Bias")) -> Tidak Ada Indikasi Bias
A15: =GLP!A9 -> 5. Tujuan utama diterapkannya sistem pemisahan fasilitas (zoning) di dalam laboratorium GLP adalah untuk... | B15: =GLP!B9 -> 1 | C15: =GLP!C9 -> 1 | D15: =GLP!D9 -> 1 | E15: =GLP!E9 -> 0 | F15: =GLP!F9 -> 1 | G15: =GLP!G9 -> 0 | H15: =GLP!H9 -> 1 | ... K15: =GLP!K9 -> 0 | L15: =COUNTIF($B$8:$K$8,"Laki-Laki") -> 5 | M15: =COUNTIF($B$8:$K$8,"Perempuan") -> 5 | N15: =SUMIF($B$8:$K$8,"Laki-Laki",GLP!B9:K9) -> 3 | O15: =SUMIF($B$8:$K$8,"Perempuan",GLP!B9:K9) -> 3 | P15: =IF(N15=0,0.3,IF(N15=L15,L15-0.3,N15)) -> 3 | Q15: =IF(O15=0,0.3,IF(O15=M15,M15-0.3,O15)) -> 3 | R15: =LN((L15-P15)/P15) -> -0.40546511 | S15: =LN((M15-Q15)/Q15) -> -0.40546511 | T15: =R15-AVERAGE($R$11:$R$110) -> -0.31247915 | U15: =S15-AVERAGE($S$11:$S$110) -> -0.31247915 | V15: =SQRT(1/P15+1/(L15-P15)) -> 0.91287093 | W15: =SQRT(1/Q15+1/(M15-Q15)) -> 0.91287093 | X15: =T15-U15 -> 0 | Y15: =SQRT(V15^2+W15^2) -> 1.2909944 | Z15: =X15/Y15 -> 0 | AA15: =IF(AND(ABS(X15)>=$B$4,ABS(Z15)>=$B$5),"DIF Besar - review",IF(AND(ABS(X15)>=$B$3,ABS(Z15)>=$B$5),"DIF Moderat - cek","Negligible")) -> Negligible | AB15: =IF(ABS(X15)>=$B$4,"Berpotensi Bias - Tinjau Konten",IF(ABS(X15)>=$B$3,"Indikasi Ringan - Pantau","Tidak Ada Indikasi Bias")) -> Tidak Ada Indikasi Bias
A16: =GLP!A10 -> 6. Berdasarkan persyaratan manajemen bahan kimia dalam GLP, syarat mutlak sebelum bahan pengujian dapat digunakan adalah memiliki Certificate of Analysis (CoA). Komponen informasi apa saja yang wajib ada dalam CoA tersebut? | B16: =GLP!B10 -> 1 | C16: =GLP!C10 -> 1 | D16: =GLP!D10 -> 1 | E16: =GLP!E10 -> 0 | F16: =GLP!F10 -> 1 | G16: =GLP!G10 -> 0 | H16: =GLP!H10 -> 0 | ... K16: =GLP!K10 -> 1 | L16: =COUNTIF($B$8:$K$8,"Laki-Laki") -> 5 | M16: =COUNTIF($B$8:$K$8,"Perempuan") -> 5 | N16: =SUMIF($B$8:$K$8,"Laki-Laki",GLP!B10:K10) -> 3 | O16: =SUMIF($B$8:$K$8,"Perempuan",GLP!B10:K10) -> 3 | P16: =IF(N16=0,0.3,IF(N16=L16,L16-0.3,N16)) -> 3 | Q16: =IF(O16=0,0.3,IF(O16=M16,M16-0.3,O16)) -> 3 | R16: =LN((L16-P16)/P16) -> -0.40546511 | S16: =LN((M16-Q16)/Q16) -> -0.40546511 | T16: =R16-AVERAGE($R$11:$R$110) -> -0.31247915 | U16: =S16-AVERAGE($S$11:$S$110) -> -0.31247915 | V16: =SQRT(1/P16+1/(L16-P16)) -> 0.91287093 | W16: =SQRT(1/Q16+1/(M16-Q16)) -> 0.91287093 | X16: =T16-U16 -> 0 | Y16: =SQRT(V16^2+W16^2) -> 1.2909944 | Z16: =X16/Y16 -> 0 | AA16: =IF(AND(ABS(X16)>=$B$4,ABS(Z16)>=$B$5),"DIF Besar - review",IF(AND(ABS(X16)>=$B$3,ABS(Z16)>=$B$5),"DIF Moderat - cek","Negligible")) -> Negligible | AB16: =IF(ABS(X16)>=$B$4,"Berpotensi Bias - Tinjau Konten",IF(ABS(X16)>=$B$3,"Indikasi Ringan - Pantau","Tidak Ada Indikasi Bias")) -> Tidak Ada Indikasi Bias
A17: =GLP!A11 -> 7. Apa kebijakan GLP terhadap bahan kimia atau reagen yang telah melewati tanggal kadaluarsa? | B17: =GLP!B11 -> 1 | C17: =GLP!C11 -> 1 | D17: =GLP!D11 -> 1 | E17: =GLP!E11 -> 1 | F17: =GLP!F11 -> 1 | G17: =GLP!G11 -> 1 | H17: =GLP!H11 -> 0 | ... K17: =GLP!K11 -> 1 | L17: =COUNTIF($B$8:$K$8,"Laki-Laki") -> 5 | M17: =COUNTIF($B$8:$K$8,"Perempuan") -> 5 | N17: =SUMIF($B$8:$K$8,"Laki-Laki",GLP!B11:K11) -> 4 | O17: =SUMIF($B$8:$K$8,"Perempuan",GLP!B11:K11) -> 4 | P17: =IF(N17=0,0.3,IF(N17=L17,L17-0.3,N17)) -> 4 | Q17: =IF(O17=0,0.3,IF(O17=M17,M17-0.3,O17)) -> 4 | R17: =LN((L17-P17)/P17) -> -1.3862944 | S17: =LN((M17-Q17)/Q17) -> -1.3862944 | T17: =R17-AVERAGE($R$11:$R$110) -> -1.2933084 | U17: =S17-AVERAGE($S$11:$S$110) -> -1.2933084 | V17: =SQRT(1/P17+1/(L17-P17)) -> 1.118034 | W17: =SQRT(1/Q17+1/(M17-Q17)) -> 1.118034 | X17: =T17-U17 -> 0 | Y17: =SQRT(V17^2+W17^2) -> 1.5811388 | Z17: =X17/Y17 -> 0 | AA17: =IF(AND(ABS(X17)>=$B$4,ABS(Z17)>=$B$5),"DIF Besar - review",IF(AND(ABS(X17)>=$B$3,ABS(Z17)>=$B$5),"DIF Moderat - cek","Negligible")) -> Negligible | AB17: =IF(ABS(X17)>=$B$4,"Berpotensi Bias - Tinjau Konten",IF(ABS(X17)>=$B$3,"Indikasi Ringan - Pantau","Tidak Ada Indikasi Bias")) -> Tidak Ada Indikasi Bias
A18: =GLP!A12 -> 8. Bukti objektif yang sah untuk menunjukkan bahwa struktur organisasi laboratorium telah mematuhi prinsip independensi GLP adalah... | B18: =GLP!B12 -> 1 | C18: =GLP!C12 -> 1 | D18: =GLP!D12 -> 1 | E18: =GLP!E12 -> 0 | F18: =GLP!F12 -> 1 | G18: =GLP!G12 -> 0 | H18: =GLP!H12 -> 0 | ... K18: =GLP!K12 -> 0 | L18: =COUNTIF($B$8:$K$8,"Laki-Laki") -> 5 | M18: =COUNTIF($B$8:$K$8,"Perempuan") -> 5 | N18: =SUMIF($B$8:$K$8,"Laki-Laki",GLP!B12:K12) -> 2 | O18: =SUMIF($B$8:$K$8,"Perempuan",GLP!B12:K12) -> 2 | P18: =IF(N18=0,0.3,IF(N18=L18,L18-0.3,N18)) -> 2 | Q18: =IF(O18=0,0.3,IF(O18=M18,M18-0.3,O18)) -> 2 | R18: =LN((L18-P18)/P18) -> 0.40546511 | S18: =LN((M18-Q18)/Q18) -> 0.40546511 | T18: =R18-AVERAGE($R$11:$R$110) -> 0.49845106 | U18: =S18-AVERAGE($S$11:$S$110) -> 0.49845106 | V18: =SQRT(1/P18+1/(L18-P18)) -> 0.91287093 | W18: =SQRT(1/Q18+1/(M18-Q18)) -> 0.91287093 | X18: =T18-U18 -> 0 | Y18: =SQRT(V18^2+W18^2) -> 1.2909944 | Z18: =X18/Y18 -> 0 | AA18: =IF(AND(ABS(X18)>=$B$4,ABS(Z18)>=$B$5),"DIF Besar - review",IF(AND(ABS(X18)>=$B$3,ABS(Z18)>=$B$5),"DIF Moderat - cek","Negligible")) -> Negligible | AB18: =IF(ABS(X18)>=$B$4,"Berpotensi Bias - Tinjau Konten",IF(ABS(X18)>=$B$3,"Indikasi Ringan - Pantau","Tidak Ada Indikasi Bias")) -> Tidak Ada Indikasi Bias
A19: =GLP!A13 -> 9. Manajemen peralatan laboratorium dalam GLP mencakup beberapa tahapan kritikal. Rangkaian kualifikasi alat yang benar menurut panduan penilaian adalah... | B19: =GLP!B13 -> 1 | C19: =GLP!C13 -> 1 | D19: =GLP!D13 -> 1 | E19: =GLP!E13 -> 1 | F19: =GLP!F13 -> 1 | G19: =GLP!G13 -> 1 | H19: =GLP!H13 -> 0 | ... K19: =GLP!K13 -> 0 | L19: =COUNTIF($B$8:$K$8,"Laki-Laki") -> 5 | M19: =COUNTIF($B$8:$K$8,"Perempuan") -> 5 | N19: =SUMIF($B$8:$K$8,"Laki-Laki",GLP!B13:K13) -> 3 | O19: =SUMIF($B$8:$K$8,"Perempuan",GLP!B13:K13) -> 3 | P19: =IF(N19=0,0.3,IF(N19=L19,L19-0.3,N19)) -> 3 | Q19: =IF(O19=0,0.3,IF(O19=M19,M19-0.3,O19)) -> 3 | R19: =LN((L19-P19)/P19) -> -0.40546511 | S19: =LN((M19-Q19)/Q19) -> -0.40546511 | T19: =R19-AVERAGE($R$11:$R$110) -> -0.31247915 | U19: =S19-AVERAGE($S$11:$S$110) -> -0.31247915 | V19: =SQRT(1/P19+1/(L19-P19)) -> 0.91287093 | W19: =SQRT(1/Q19+1/(M19-Q19)) -> 0.91287093 | X19: =T19-U19 -> 0 | Y19: =SQRT(V19^2+W19^2) -> 1.2909944 | Z19: =X19/Y19 -> 0 | AA19: =IF(AND(ABS(X19)>=$B$4,ABS(Z19)>=$B$5),"DIF Besar - review",IF(AND(ABS(X19)>=$B$3,ABS(Z19)>=$B$5),"DIF Moderat - cek","Negligible")) -> Negligible | AB19: =IF(ABS(X19)>=$B$4,"Berpotensi Bias - Tinjau Konten",IF(ABS(X19)>=$B$3,"Indikasi Ringan - Pantau","Tidak Ada Indikasi Bias")) -> Tidak Ada Indikasi Bias
A20: =GLP!A14 -> 10. Mengapa pemantauan suhu dan kelembaban (kondisi lingkungan) secara terus-menerus sangat ditekankan ? | B20: =GLP!B14 -> 0 | C20: =GLP!C14 -> 0 | D20: =GLP!D14 -> 1 | E20: =GLP!E14 -> 0 | F20: =GLP!F14 -> 1 | G20: =GLP!G14 -> 0 | H20: =GLP!H14 -> 0 | ... K20: =GLP!K14 -> 0 | L20: =COUNTIF($B$8:$K$8,"Laki-Laki") -> 5 | M20: =COUNTIF($B$8:$K$8,"Perempuan") -> 5 | N20: =SUMIF($B$8:$K$8,"Laki-Laki",GLP!B14:K14) -> 1 | O20: =SUMIF($B$8:$K$8,"Perempuan",GLP!B14:K14) -> 1 | P20: =IF(N20=0,0.3,IF(N20=L20,L20-0.3,N20)) -> 1 | Q20: =IF(O20=0,0.3,IF(O20=M20,M20-0.3,O20)) -> 1 | R20: =LN((L20-P20)/P20) -> 1.3862944 | S20: =LN((M20-Q20)/Q20) -> 1.3862944 | T20: =R20-AVERAGE($R$11:$R$110) -> 1.4792803 | U20: =S20-AVERAGE($S$11:$S$110) -> 1.4792803 | V20: =SQRT(1/P20+1/(L20-P20)) -> 1.118034 | W20: =SQRT(1/Q20+1/(M20-Q20)) -> 1.118034 | X20: =T20-U20 -> 0 | Y20: =SQRT(V20^2+W20^2) -> 1.5811388 | Z20: =X20/Y20 -> 0 | AA20: =IF(AND(ABS(X20)>=$B$4,ABS(Z20)>=$B$5),"DIF Besar - review",IF(AND(ABS(X20)>=$B$3,ABS(Z20)>=$B$5),"DIF Moderat - cek","Negligible")) -> Negligible | AB20: =IF(ABS(X20)>=$B$4,"Berpotensi Bias - Tinjau Konten",IF(ABS(X20)>=$B$3,"Indikasi Ringan - Pantau","Tidak Ada Indikasi Bias")) -> Tidak Ada Indikasi Bias
A21: =GLP!A15 -> 11. Dokumen apa yang dituntut sebagai bukti kuat bahwa personel laboratorium benar-benar telah mengakses dan memahami dokumen mutu (SOP)? | B21: =GLP!B15 -> 1 | C21: =GLP!C15 -> 1 | D21: =GLP!D15 -> 0 | E21: =GLP!E15 -> 1 | F21: =GLP!F15 -> 0 | G21: =GLP!G15 -> 1 | H21: =GLP!H15 -> 0 | ... K21: =GLP!K15 -> 0 | L21: =COUNTIF($B$8:$K$8,"Laki-Laki") -> 5 | M21: =COUNTIF($B$8:$K$8,"Perempuan") -> 5 | N21: =SUMIF($B$8:$K$8,"Laki-Laki",GLP!B15:K15) -> 2 | O21: =SUMIF($B$8:$K$8,"Perempuan",GLP!B15:K15) -> 2 | P21: =IF(N21=0,0.3,IF(N21=L21,L21-0.3,N21)) -> 2 | Q21: =IF(O21=0,0.3,IF(O21=M21,M21-0.3,O21)) -> 2 | R21: =LN((L21-P21)/P21) -> 0.40546511 | S21: =LN((M21-Q21)/Q21) -> 0.40546511 | T21: =R21-AVERAGE($R$11:$R$110) -> 0.49845106 | U21: =S21-AVERAGE($S$11:$S$110) -> 0.49845106 | V21: =SQRT(1/P21+1/(L21-P21)) -> 0.91287093 | W21: =SQRT(1/Q21+1/(M21-Q21)) -> 0.91287093 | X21: =T21-U21 -> 0 | Y21: =SQRT(V21^2+W21^2) -> 1.2909944 | Z21: =X21/Y21 -> 0 | AA21: =IF(AND(ABS(X21)>=$B$4,ABS(Z21)>=$B$5),"DIF Besar - review",IF(AND(ABS(X21)>=$B$3,ABS(Z21)>=$B$5),"DIF Moderat - cek","Negligible")) -> Negligible | AB21: =IF(ABS(X21)>=$B$4,"Berpotensi Bias - Tinjau Konten",IF(ABS(X21)>=$B$3,"Indikasi Ringan - Pantau","Tidak Ada Indikasi Bias")) -> Tidak Ada Indikasi Bias
A22: =GLP!A16 -> 12. Manakah dari pilihan berikut yang merupakan contoh implementasi zoning (pemisahan fasilitas) yang tepat menurut panduan GLP? | B22: =GLP!B16 -> 1 | C22: =GLP!C16 -> 1 | D22: =GLP!D16 -> 1 | E22: =GLP!E16 -> 0 | F22: =GLP!F16 -> 1 | G22: =GLP!G16 -> 0 | H22: =GLP!H16 -> 0 | ... K22: =GLP!K16 -> 0 | L22: =COUNTIF($B$8:$K$8,"Laki-Laki") -> 5 | M22: =COUNTIF($B$8:$K$8,"Perempuan") -> 5 | N22: =SUMIF($B$8:$K$8,"Laki-Laki",GLP!B16:K16) -> 2 | O22: =SUMIF($B$8:$K$8,"Perempuan",GLP!B16:K16) -> 2 | P22: =IF(N22=0,0.3,IF(N22=L22,L22-0.3,N22)) -> 2 | Q22: =IF(O22=0,0.3,IF(O22=M22,M22-0.3,O22)) -> 2 | R22: =LN((L22-P22)/P22) -> 0.40546511 | S22: =LN((M22-Q22)/Q22) -> 0.40546511 | T22: =R22-AVERAGE($R$11:$R$110) -> 0.49845106 | U22: =S22-AVERAGE($S$11:$S$110) -> 0.49845106 | V22: =SQRT(1/P22+1/(L22-P22)) -> 0.91287093 | W22: =SQRT(1/Q22+1/(M22-Q22)) -> 0.91287093 | X22: =T22-U22 -> 0 | Y22: =SQRT(V22^2+W22^2) -> 1.2909944 | Z22: =X22/Y22 -> 0 | AA22: =IF(AND(ABS(X22)>=$B$4,ABS(Z22)>=$B$5),"DIF Besar - review",IF(AND(ABS(X22)>=$B$3,ABS(Z22)>=$B$5),"DIF Moderat - cek","Negligible")) -> Negligible | AB22: =IF(ABS(X22)>=$B$4,"Berpotensi Bias - Tinjau Konten",IF(ABS(X22)>=$B$3,"Indikasi Ringan - Pantau","Tidak Ada Indikasi Bias")) -> Tidak Ada Indikasi Bias
... A110: =GLP!A104 -> 100. Skenario: Dalam formulir pembuangan sisa test item, tercatat: "Diterima: 100ml. Digunakan: 20ml. Dibuang: 80ml." Proses mencocokkan angka-angka ini agar sesuai dan tidak ada bahan yang hilang tanpa jejak disebut sebagai proses... | B110: =GLP!B104 -> 1 | C110: =GLP!C104 -> 1 | D110: =GLP!D104 -> 0 | E110: =GLP!E104 -> 1 | F110: =GLP!F104 -> 0 | G110: =GLP!G104 -> 1 | H110: =GLP!H104 -> 0 | ... K110: =GLP!K104 -> 0 | L110: =COUNTIF($B$8:$K$8,"Laki-Laki") -> 5 | M110: =COUNTIF($B$8:$K$8,"Perempuan") -> 5 | N110: =SUMIF($B$8:$K$8,"Laki-Laki",GLP!B104:K104) -> 2 | O110: =SUMIF($B$8:$K$8,"Perempuan",GLP!B104:K104) -> 2 | P110: =IF(N110=0,0.3,IF(N110=L110,L110-0.3,N110)) -> 2 | Q110: =IF(O110=0,0.3,IF(O110=M110,M110-0.3,O110)) -> 2 | R110: =LN((L110-P110)/P110) -> 0.40546511 | S110: =LN((M110-Q110)/Q110) -> 0.40546511 | T110: =R110-AVERAGE($R$11:$R$110) -> 0.49845106 | U110: =S110-AVERAGE($S$11:$S$110) -> 0.49845106 | V110: =SQRT(1/P110+1/(L110-P110)) -> 0.91287093 | W110: =SQRT(1/Q110+1/(M110-Q110)) -> 0.91287093 | X110: =T110-U110 -> 0 | Y110: =SQRT(V110^2+W110^2) -> 1.2909944 | Z110: =X110/Y110 -> 0 | AA110: =IF(AND(ABS(X110)>=$B$4,ABS(Z110)>=$B$5),"DIF Besar - review",IF(AND(ABS(X110)>=$B$3,ABS(Z110)>=$B$5),"DIF Moderat - cek","Negligible")) -> Negligible | AB110: =IF(ABS(X110)>=$B$4,"Berpotensi Bias - Tinjau Konten",IF(ABS(X110)>=$B$3,"Indikasi Ringan - Pantau","Tidak Ada Indikasi Bias")) -> Tidak Ada Indikasi Bias
B111: =SUM(B11:B110) -> 82 | C111: =SUM(C11:C110) -> 82 | D111: =SUM(D11:D110) -> 80 | E111: =SUM(E11:E110) -> 55 | F111: =SUM(F11:F110) -> 80 | G111: =SUM(G11:G110) -> 55 | H111: =SUM(H11:H110) -> 19 | I111: =SUM(I11:I110) -> 19 | ... K111: =SUM(K11:K110) -> 24

Sheet DIF-Rasch-LQO
A1: UJI RASCH DIF (Pendekatan PROX) — Skema LQO
A3: Ambang DIF (logit) - Moderat | B3: 0.5 | N3: Ringkasan Signifikansi Statistik (t-test) | Q3: Ringkasan Kesimpulan Praktis (Kontras)
A4: Ambang DIF (logit) - Besar | B4: 1 | N4: DIF Besar - review | O4: =COUNTIF($AA$11:$AA$110,"DIF Besar - review") -> 0 | Q4: Berpotensi Bias - Tinjau Konten | R4: =COUNTIF($AB$11:$AB$110,"Berpotensi Bias - Tinjau Konten") -> 0
A5: Ambang |t| minimum | B5: 2 | N5: DIF Moderat - cek | O5: =COUNTIF($AA$11:$AA$110,"DIF Moderat - cek") -> 0 | Q5: Indikasi Ringan - Pantau | R5: =COUNTIF($AB$11:$AB$110,"Indikasi Ringan - Pantau") -> 0
A6: Kontras DIF Maksimum (data ini) | B6: =_xlfn.AGGREGATE(14,6,ABS(X11:X110),1) -> 0 | N6: Negligible | O6: =COUNTIF($AA$11:$AA$110,"Negligible") -> 100 | Q6: Tidak Ada Indikasi Bias | R6: =COUNTIF($AB$11:$AB$110,"Tidak Ada Indikasi Bias") -> 100
A8: Jenis Kelamin | B8: =LQO!B2 -> Perempuan | C8: =LQO!C2 -> Laki-Laki | D8: =LQO!D2 -> Perempuan | E8: =LQO!E2 -> Perempuan | F8: =LQO!F2 -> Laki-Laki | G8: =LQO!G2 -> Laki-Laki | H8: =LQO!H2 -> Perempuan | I8: =LQO!I2 -> Laki-Laki | ... K8: =LQO!K2 -> Laki-Laki
A9: Soal | B9: Asesi | L9: N (L) | M9: N (P) | N9: S (L) | O9: S (P) | P9: S adj (L) | Q9: S adj (P) | R9: β mentah (L) | S9: β mentah (P) | T9: β center (L) | U9: β center (P) | V9: SE (L) | W9: SE (P) | X9: Kontras DIF | Y9: SE Gabungan | Z9: t-stat | AA9: Klasifikasi DIF | AB9: Kesimpulan Praktis (Kontras)
B10: 1 | C10: 2 | D10: 3 | E10: 4 | F10: 5 | G10: 6 | H10: 7 | I10: 8 | J10: 9 | K10: 10
A11: =LQO!A5 -> 1. Apa makna "Ketidakberpihakan" dalam konteks laboratorium ISO 17025? | B11: =LQO!B5 -> 1 | C11: =LQO!C5 -> 1 | D11: =LQO!D5 -> 1 | E11: =LQO!E5 -> 0 | F11: =LQO!F5 -> 1 | G11: =LQO!G5 -> 0 | H11: =LQO!H5 -> 0 | ... K11: =LQO!K5 -> 1 | L11: =COUNTIF($B$8:$K$8,"Laki-Laki") -> 5 | M11: =COUNTIF($B$8:$K$8,"Perempuan") -> 5 | N11: =SUMIF($B$8:$K$8,"Laki-Laki",LQO!B5:K5) -> 3 | O11: =SUMIF($B$8:$K$8,"Perempuan",LQO!B5:K5) -> 3 | P11: =IF(N11=0,0.3,IF(N11=L11,L11-0.3,N11)) -> 3 | Q11: =IF(O11=0,0.3,IF(O11=M11,M11-0.3,O11)) -> 3 | R11: =LN((L11-P11)/P11) -> -0.40546511 | S11: =LN((M11-Q11)/Q11) -> -0.40546511 | T11: =R11-AVERAGE($R$11:$R$110) -> -0.13670119 | U11: =S11-AVERAGE($S$11:$S$110) -> -0.13670119 | V11: =SQRT(1/P11+1/(L11-P11)) -> 0.91287093 | W11: =SQRT(1/Q11+1/(M11-Q11)) -> 0.91287093 | X11: =T11-U11 -> 0 | Y11: =SQRT(V11^2+W11^2) -> 1.2909944 | Z11: =X11/Y11 -> 0 | AA11: =IF(AND(ABS(X11)>=$B$4,ABS(Z11)>=$B$5),"DIF Besar - review",IF(AND(ABS(X11)>=$B$3,ABS(Z11)>=$B$5),"DIF Moderat - cek","Negligible")) -> Negligible | AB11: =IF(ABS(X11)>=$B$4,"Berpotensi Bias - Tinjau Konten",IF(ABS(X11)>=$B$3,"Indikasi Ringan - Pantau","Tidak Ada Indikasi Bias")) -> Tidak Ada Indikasi Bias
A12: =LQO!A6 -> 2. Anda bekerja di laboratorium internal pabrik makanan dan ditekan meluluskan sampel out of spec. Apa yang harus dilakukan? | B12: =LQO!B6 -> 1 | C12: =LQO!C6 -> 1 | D12: =LQO!D6 -> 1 | E12: =LQO!E6 -> 0 | F12: =LQO!F6 -> 1 | G12: =LQO!G6 -> 0 | H12: =LQO!H6 -> 1 | ... K12: =LQO!K6 -> 0 | L12: =COUNTIF($B$8:$K$8,"Laki-Laki") -> 5 | M12: =COUNTIF($B$8:$K$8,"Perempuan") -> 5 | N12: =SUMIF($B$8:$K$8,"Laki-Laki",LQO!B6:K6) -> 3 | O12: =SUMIF($B$8:$K$8,"Perempuan",LQO!B6:K6) -> 3 | P12: =IF(N12=0,0.3,IF(N12=L12,L12-0.3,N12)) -> 3 | Q12: =IF(O12=0,0.3,IF(O12=M12,M12-0.3,O12)) -> 3 | R12: =LN((L12-P12)/P12) -> -0.40546511 | S12: =LN((M12-Q12)/Q12) -> -0.40546511 | T12: =R12-AVERAGE($R$11:$R$110) -> -0.13670119 | U12: =S12-AVERAGE($S$11:$S$110) -> -0.13670119 | V12: =SQRT(1/P12+1/(L12-P12)) -> 0.91287093 | W12: =SQRT(1/Q12+1/(M12-Q12)) -> 0.91287093 | X12: =T12-U12 -> 0 | Y12: =SQRT(V12^2+W12^2) -> 1.2909944 | Z12: =X12/Y12 -> 0 | AA12: =IF(AND(ABS(X12)>=$B$4,ABS(Z12)>=$B$5),"DIF Besar - review",IF(AND(ABS(X12)>=$B$3,ABS(Z12)>=$B$5),"DIF Moderat - cek","Negligible")) -> Negligible | AB12: =IF(ABS(X12)>=$B$4,"Berpotensi Bias - Tinjau Konten",IF(ABS(X12)>=$B$3,"Indikasi Ringan - Pantau","Tidak Ada Indikasi Bias")) -> Tidak Ada Indikasi Bias
A13: =LQO!A7 -> 3. Manakah situasi berikut yang merupakan risiko terhadap ketidakberpihakan? | B13: =LQO!B7 -> 1 | C13: =LQO!C7 -> 1 | D13: =LQO!D7 -> 0 | E13: =LQO!E7 -> 1 | F13: =LQO!F7 -> 0 | G13: =LQO!G7 -> 1 | H13: =LQO!H7 -> 0 | ... K13: =LQO!K7 -> 0 | L13: =COUNTIF($B$8:$K$8,"Laki-Laki") -> 5 | M13: =COUNTIF($B$8:$K$8,"Perempuan") -> 5 | N13: =SUMIF($B$8:$K$8,"Laki-Laki",LQO!B7:K7) -> 2 | O13: =SUMIF($B$8:$K$8,"Perempuan",LQO!B7:K7) -> 2 | P13: =IF(N13=0,0.3,IF(N13=L13,L13-0.3,N13)) -> 2 | Q13: =IF(O13=0,0.3,IF(O13=M13,M13-0.3,O13)) -> 2 | R13: =LN((L13-P13)/P13) -> 0.40546511 | S13: =LN((M13-Q13)/Q13) -> 0.40546511 | T13: =R13-AVERAGE($R$11:$R$110) -> 0.67422903 | U13: =S13-AVERAGE($S$11:$S$110) -> 0.67422903 | V13: =SQRT(1/P13+1/(L13-P13)) -> 0.91287093 | W13: =SQRT(1/Q13+1/(M13-Q13)) -> 0.91287093 | X13: =T13-U13 -> 0 | Y13: =SQRT(V13^2+W13^2) -> 1.2909944 | Z13: =X13/Y13 -> 0 | AA13: =IF(AND(ABS(X13)>=$B$4,ABS(Z13)>=$B$5),"DIF Besar - review",IF(AND(ABS(X13)>=$B$3,ABS(Z13)>=$B$5),"DIF Moderat - cek","Negligible")) -> Negligible | AB13: =IF(ABS(X13)>=$B$4,"Berpotensi Bias - Tinjau Konten",IF(ABS(X13)>=$B$3,"Indikasi Ringan - Pantau","Tidak Ada Indikasi Bias")) -> Tidak Ada Indikasi Bias
A14: =LQO!A8 -> 4. Jika risiko ketidakberpihakan teridentifikasi, laboratorium harus: | B14: =LQO!B8 -> 1 | C14: =LQO!C8 -> 1 | D14: =LQO!D8 -> 1 | E14: =LQO!E8 -> 1 | F14: =LQO!F8 -> 1 | G14: =LQO!G8 -> 1 | H14: =LQO!H8 -> 0 | ... K14: =LQO!K8 -> 1 | L14: =COUNTIF($B$8:$K$8,"Laki-Laki") -> 5 | M14: =COUNTIF($B$8:$K$8,"Perempuan") -> 5 | N14: =SUMIF($B$8:$K$8,"Laki-Laki",LQO!B8:K8) -> 4 | O14: =SUMIF($B$8:$K$8,"Perempuan",LQO!B8:K8) -> 4 | P14: =IF(N14=0,0.3,IF(N14=L14,L14-0.3,N14)) -> 4 | Q14: =IF(O14=0,0.3,IF(O14=M14,M14-0.3,O14)) -> 4 | R14: =LN((L14-P14)/P14) -> -1.3862944 | S14: =LN((M14-Q14)/Q14) -> -1.3862944 | T14: =R14-AVERAGE($R$11:$R$110) -> -1.1175304 | U14: =S14-AVERAGE($S$11:$S$110) -> -1.1175304 | V14: =SQRT(1/P14+1/(L14-P14)) -> 1.118034 | W14: =SQRT(1/Q14+1/(M14-Q14)) -> 1.118034 | X14: =T14-U14 -> 0 | Y14: =SQRT(V14^2+W14^2) -> 1.5811388 | Z14: =X14/Y14 -> 0 | AA14: =IF(AND(ABS(X14)>=$B$4,ABS(Z14)>=$B$5),"DIF Besar - review",IF(AND(ABS(X14)>=$B$3,ABS(Z14)>=$B$5),"DIF Moderat - cek","Negligible")) -> Negligible | AB14: =IF(ABS(X14)>=$B$4,"Berpotensi Bias - Tinjau Konten",IF(ABS(X14)>=$B$3,"Indikasi Ringan - Pantau","Tidak Ada Indikasi Bias")) -> Tidak Ada Indikasi Bias
A15: =LQO!A9 -> 5. Untuk menjaga integritas, personel laboratorium tidak boleh: | B15: =LQO!B9 -> 0 | C15: =LQO!C9 -> 0 | D15: =LQO!D9 -> 1 | E15: =LQO!E9 -> 1 | F15: =LQO!F9 -> 1 | G15: =LQO!G9 -> 1 | H15: =LQO!H9 -> 0 | ... K15: =LQO!K9 -> 0 | L15: =COUNTIF($B$8:$K$8,"Laki-Laki") -> 5 | M15: =COUNTIF($B$8:$K$8,"Perempuan") -> 5 | N15: =SUMIF($B$8:$K$8,"Laki-Laki",LQO!B9:K9) -> 2 | O15: =SUMIF($B$8:$K$8,"Perempuan",LQO!B9:K9) -> 2 | P15: =IF(N15=0,0.3,IF(N15=L15,L15-0.3,N15)) -> 2 | Q15: =IF(O15=0,0.3,IF(O15=M15,M15-0.3,O15)) -> 2 | R15: =LN((L15-P15)/P15) -> 0.40546511 | S15: =LN((M15-Q15)/Q15) -> 0.40546511 | T15: =R15-AVERAGE($R$11:$R$110) -> 0.67422903 | U15: =S15-AVERAGE($S$11:$S$110) -> 0.67422903 | V15: =SQRT(1/P15+1/(L15-P15)) -> 0.91287093 | W15: =SQRT(1/Q15+1/(M15-Q15)) -> 0.91287093 | X15: =T15-U15 -> 0 | Y15: =SQRT(V15^2+W15^2) -> 1.2909944 | Z15: =X15/Y15 -> 0 | AA15: =IF(AND(ABS(X15)>=$B$4,ABS(Z15)>=$B$5),"DIF Besar - review",IF(AND(ABS(X15)>=$B$3,ABS(Z15)>=$B$5),"DIF Moderat - cek","Negligible")) -> Negligible | AB15: =IF(ABS(X15)>=$B$4,"Berpotensi Bias - Tinjau Konten",IF(ABS(X15)>=$B$3,"Indikasi Ringan - Pantau","Tidak Ada Indikasi Bias")) -> Tidak Ada Indikasi Bias
A16: =LQO!A10 -> 6. Komitmen manajemen puncak terhadap ketidakberpihakan harus: | B16: =LQO!B10 -> 0 | C16: =LQO!C10 -> 0 | D16: =LQO!D10 -> 1 | E16: =LQO!E10 -> 0 | F16: =LQO!F10 -> 1 | G16: =LQO!G10 -> 0 | H16: =LQO!H10 -> 0 | ... K16: =LQO!K10 -> 0 | L16: =COUNTIF($B$8:$K$8,"Laki-Laki") -> 5 | M16: =COUNTIF($B$8:$K$8,"Perempuan") -> 5 | N16: =SUMIF($B$8:$K$8,"Laki-Laki",LQO!B10:K10) -> 1 | O16: =SUMIF($B$8:$K$8,"Perempuan",LQO!B10:K10) -> 1 | P16: =IF(N16=0,0.3,IF(N16=L16,L16-0.3,N16)) -> 1 | Q16: =IF(O16=0,0.3,IF(O16=M16,M16-0.3,O16)) -> 1 | R16: =LN((L16-P16)/P16) -> 1.3862944 | S16: =LN((M16-Q16)/Q16) -> 1.3862944 | T16: =R16-AVERAGE($R$11:$R$110) -> 1.6550583 | U16: =S16-AVERAGE($S$11:$S$110) -> 1.6550583 | V16: =SQRT(1/P16+1/(L16-P16)) -> 1.118034 | W16: =SQRT(1/Q16+1/(M16-Q16)) -> 1.118034 | X16: =T16-U16 -> 0 | Y16: =SQRT(V16^2+W16^2) -> 1.5811388 | Z16: =X16/Y16 -> 0 | AA16: =IF(AND(ABS(X16)>=$B$4,ABS(Z16)>=$B$5),"DIF Besar - review",IF(AND(ABS(X16)>=$B$3,ABS(Z16)>=$B$5),"DIF Moderat - cek","Negligible")) -> Negligible | AB16: =IF(ABS(X16)>=$B$4,"Berpotensi Bias - Tinjau Konten",IF(ABS(X16)>=$B$3,"Indikasi Ringan - Pantau","Tidak Ada Indikasi Bias")) -> Tidak Ada Indikasi Bias
A17: =LQO!A11 -> 7. Tekanan finansial yang mengganggu ketidakberpihakan contohnya: | B17: =LQO!B11 -> 1 | C17: =LQO!C11 -> 1 | D17: =LQO!D11 -> 1 | E17: =LQO!E11 -> 1 | F17: =LQO!F11 -> 1 | G17: =LQO!G11 -> 1 | H17: =LQO!H11 -> 0 | ... K17: =LQO!K11 -> 0 | L17: =COUNTIF($B$8:$K$8,"Laki-Laki") -> 5 | M17: =COUNTIF($B$8:$K$8,"Perempuan") -> 5 | N17: =SUMIF($B$8:$K$8,"Laki-Laki",LQO!B11:K11) -> 3 | O17: =SUMIF($B$8:$K$8,"Perempuan",LQO!B11:K11) -> 3 | P17: =IF(N17=0,0.3,IF(N17=L17,L17-0.3,N17)) -> 3 | Q17: =IF(O17=0,0.3,IF(O17=M17,M17-0.3,O17)) -> 3 | R17: =LN((L17-P17)/P17) -> -0.40546511 | S17: =LN((M17-Q17)/Q17) -> -0.40546511 | T17: =R17-AVERAGE($R$11:$R$110) -> -0.13670119 | U17: =S17-AVERAGE($S$11:$S$110) -> -0.13670119 | V17: =SQRT(1/P17+1/(L17-P17)) -> 0.91287093 | W17: =SQRT(1/Q17+1/(M17-Q17)) -> 0.91287093 | X17: =T17-U17 -> 0 | Y17: =SQRT(V17^2+W17^2) -> 1.2909944 | Z17: =X17/Y17 -> 0 | AA17: =IF(AND(ABS(X17)>=$B$4,ABS(Z17)>=$B$5),"DIF Besar - review",IF(AND(ABS(X17)>=$B$3,ABS(Z17)>=$B$5),"DIF Moderat - cek","Negligible")) -> Negligible | AB17: =IF(ABS(X17)>=$B$4,"Berpotensi Bias - Tinjau Konten",IF(ABS(X17)>=$B$3,"Indikasi Ringan - Pantau","Tidak Ada Indikasi Bias")) -> Tidak Ada Indikasi Bias
A18: =LQO!A12 -> 8. Siapa yang bertanggung jawab atas pengelolaan informasi laboratorium? | B18: =LQO!B12 -> 1 | C18: =LQO!C12 -> 1 | D18: =LQO!D12 -> 1 | E18: =LQO!E12 -> 1 | F18: =LQO!F12 -> 1 | G18: =LQO!G12 -> 1 | H18: =LQO!H12 -> 1 | ... K18: =LQO!K12 -> 0 | L18: =COUNTIF($B$8:$K$8,"Laki-Laki") -> 5 | M18: =COUNTIF($B$8:$K$8,"Perempuan") -> 5 | N18: =SUMIF($B$8:$K$8,"Laki-Laki",LQO!B12:K12) -> 4 | O18: =SUMIF($B$8:$K$8,"Perempuan",LQO!B12:K12) -> 4 | P18: =IF(N18=0,0.3,IF(N18=L18,L18-0.3,N18)) -> 4 | Q18: =IF(O18=0,0.3,IF(O18=M18,M18-0.3,O18)) -> 4 | R18: =LN((L18-P18)/P18) -> -1.3862944 | S18: =LN((M18-Q18)/Q18) -> -1.3862944 | T18: =R18-AVERAGE($R$11:$R$110) -> -1.1175304 | U18: =S18-AVERAGE($S$11:$S$110) -> -1.1175304 | V18: =SQRT(1/P18+1/(L18-P18)) -> 1.118034 | W18: =SQRT(1/Q18+1/(M18-Q18)) -> 1.118034 | X18: =T18-U18 -> 0 | Y18: =SQRT(V18^2+W18^2) -> 1.5811388 | Z18: =X18/Y18 -> 0 | AA18: =IF(AND(ABS(X18)>=$B$4,ABS(Z18)>=$B$5),"DIF Besar - review",IF(AND(ABS(X18)>=$B$3,ABS(Z18)>=$B$5),"DIF Moderat - cek","Negligible")) -> Negligible | AB18: =IF(ABS(X18)>=$B$4,"Berpotensi Bias - Tinjau Konten",IF(ABS(X18)>=$B$3,"Indikasi Ringan - Pantau","Tidak Ada Indikasi Bias")) -> Tidak Ada Indikasi Bias
A19: =LQO!A13 -> 9. Kapan laboratorium boleh membuka data pelanggan tanpa persetujuan? | B19: =LQO!B13 -> 1 | C19: =LQO!C13 -> 1 | D19: =LQO!D13 -> 1 | E19: =LQO!E13 -> 0 | F19: =LQO!F13 -> 1 | G19: =LQO!G13 -> 0 | H19: =LQO!H13 -> 0 | ... K19: =LQO!K13 -> 0 | L19: =COUNTIF($B$8:$K$8,"Laki-Laki") -> 5 | M19: =COUNTIF($B$8:$K$8,"Perempuan") -> 5 | N19: =SUMIF($B$8:$K$8,"Laki-Laki",LQO!B13:K13) -> 2 | O19: =SUMIF($B$8:$K$8,"Perempuan",LQO!B13:K13) -> 2 | P19: =IF(N19=0,0.3,IF(N19=L19,L19-0.3,N19)) -> 2 | Q19: =IF(O19=0,0.3,IF(O19=M19,M19-0.3,O19)) -> 2 | R19: =LN((L19-P19)/P19) -> 0.40546511 | S19: =LN((M19-Q19)/Q19) -> 0.40546511 | T19: =R19-AVERAGE($R$11:$R$110) -> 0.67422903 | U19: =S19-AVERAGE($S$11:$S$110) -> 0.67422903 | V19: =SQRT(1/P19+1/(L19-P19)) -> 0.91287093 | W19: =SQRT(1/Q19+1/(M19-Q19)) -> 0.91287093 | X19: =T19-U19 -> 0 | Y19: =SQRT(V19^2+W19^2) -> 1.2909944 | Z19: =X19/Y19 -> 0 | AA19: =IF(AND(ABS(X19)>=$B$4,ABS(Z19)>=$B$5),"DIF Besar - review",IF(AND(ABS(X19)>=$B$3,ABS(Z19)>=$B$5),"DIF Moderat - cek","Negligible")) -> Negligible | AB19: =IF(ABS(X19)>=$B$4,"Berpotensi Bias - Tinjau Konten",IF(ABS(X19)>=$B$3,"Indikasi Ringan - Pantau","Tidak Ada Indikasi Bias")) -> Tidak Ada Indikasi Bias
A20: =LQO!A14 -> 10. Jika data pelanggan dibuka karena hukum, apa yang harus dilakukan lab? | B20: =LQO!B14 -> 1 | C20: =LQO!C14 -> 1 | D20: =LQO!D14 -> 1 | E20: =LQO!E14 -> 0 | F20: =LQO!F14 -> 1 | G20: =LQO!G14 -> 0 | H20: =LQO!H14 -> 1 | ... K20: =LQO!K14 -> 0 | L20: =COUNTIF($B$8:$K$8,"Laki-Laki") -> 5 | M20: =COUNTIF($B$8:$K$8,"Perempuan") -> 5 | N20: =SUMIF($B$8:$K$8,"Laki-Laki",LQO!B14:K14) -> 3 | O20: =SUMIF($B$8:$K$8,"Perempuan",LQO!B14:K14) -> 3 | P20: =IF(N20=0,0.3,IF(N20=L20,L20-0.3,N20)) -> 3 | Q20: =IF(O20=0,0.3,IF(O20=M20,M20-0.3,O20)) -> 3 | R20: =LN((L20-P20)/P20) -> -0.40546511 | S20: =LN((M20-Q20)/Q20) -> -0.40546511 | T20: =R20-AVERAGE($R$11:$R$110) -> -0.13670119 | U20: =S20-AVERAGE($S$11:$S$110) -> -0.13670119 | V20: =SQRT(1/P20+1/(L20-P20)) -> 0.91287093 | W20: =SQRT(1/Q20+1/(M20-Q20)) -> 0.91287093 | X20: =T20-U20 -> 0 | Y20: =SQRT(V20^2+W20^2) -> 1.2909944 | Z20: =X20/Y20 -> 0 | AA20: =IF(AND(ABS(X20)>=$B$4,ABS(Z20)>=$B$5),"DIF Besar - review",IF(AND(ABS(X20)>=$B$3,ABS(Z20)>=$B$5),"DIF Moderat - cek","Negligible")) -> Negligible | AB20: =IF(ABS(X20)>=$B$4,"Berpotensi Bias - Tinjau Konten",IF(ABS(X20)>=$B$3,"Indikasi Ringan - Pantau","Tidak Ada Indikasi Bias")) -> Tidak Ada Indikasi Bias
A21: =LQO!A15 -> 11. Informasi tentang pelanggan dari sumber selain pelanggan harus: | B21: =LQO!B15 -> 1 | C21: =LQO!C15 -> 1 | D21: =LQO!D15 -> 0 | E21: =LQO!E15 -> 0 | F21: =LQO!F15 -> 0 | G21: =LQO!G15 -> 0 | H21: =LQO!H15 -> 0 | ... K21: =LQO!K15 -> 0 | L21: =COUNTIF($B$8:$K$8,"Laki-Laki") -> 5 | M21: =COUNTIF($B$8:$K$8,"Perempuan") -> 5 | N21: =SUMIF($B$8:$K$8,"Laki-Laki",LQO!B15:K15) -> 1 | O21: =SUMIF($B$8:$K$8,"Perempuan",LQO!B15:K15) -> 1 | P21: =IF(N21=0,0.3,IF(N21=L21,L21-0.3,N21)) -> 1 | Q21: =IF(O21=0,0.3,IF(O21=M21,M21-0.3,O21)) -> 1 | R21: =LN((L21-P21)/P21) -> 1.3862944 | S21: =LN((M21-Q21)/Q21) -> 1.3862944 | T21: =R21-AVERAGE($R$11:$R$110) -> 1.6550583 | U21: =S21-AVERAGE($S$11:$S$110) -> 1.6550583 | V21: =SQRT(1/P21+1/(L21-P21)) -> 1.118034 | W21: =SQRT(1/Q21+1/(M21-Q21)) -> 1.118034 | X21: =T21-U21 -> 0 | Y21: =SQRT(V21^2+W21^2) -> 1.5811388 | Z21: =X21/Y21 -> 0 | AA21: =IF(AND(ABS(X21)>=$B$4,ABS(Z21)>=$B$5),"DIF Besar - review",IF(AND(ABS(X21)>=$B$3,ABS(Z21)>=$B$5),"DIF Moderat - cek","Negligible")) -> Negligible | AB21: =IF(ABS(X21)>=$B$4,"Berpotensi Bias - Tinjau Konten",IF(ABS(X21)>=$B$3,"Indikasi Ringan - Pantau","Tidak Ada Indikasi Bias")) -> Tidak Ada Indikasi Bias
A22: =LQO!A16 -> 12. Secara legalitas, laboratorium harus: | B22: =LQO!B16 -> 1 | C22: =LQO!C16 -> 1 | D22: =LQO!D16 -> 1 | E22: =LQO!E16 -> 0 | F22: =LQO!F16 -> 1 | G22: =LQO!G16 -> 0 | H22: =LQO!H16 -> 0 | ... K22: =LQO!K16 -> 0 | L22: =COUNTIF($B$8:$K$8,"Laki-Laki") -> 5 | M22: =COUNTIF($B$8:$K$8,"Perempuan") -> 5 | N22: =SUMIF($B$8:$K$8,"Laki-Laki",LQO!B16:K16) -> 2 | O22: =SUMIF($B$8:$K$8,"Perempuan",LQO!B16:K16) -> 2 | P22: =IF(N22=0,0.3,IF(N22=L22,L22-0.3,N22)) -> 2 | Q22: =IF(O22=0,0.3,IF(O22=M22,M22-0.3,O22)) -> 2 | R22: =LN((L22-P22)/P22) -> 0.40546511 | S22: =LN((M22-Q22)/Q22) -> 0.40546511 | T22: =R22-AVERAGE($R$11:$R$110) -> 0.67422903 | U22: =S22-AVERAGE($S$11:$S$110) -> 0.67422903 | V22: =SQRT(1/P22+1/(L22-P22)) -> 0.91287093 | W22: =SQRT(1/Q22+1/(M22-Q22)) -> 0.91287093 | X22: =T22-U22 -> 0 | Y22: =SQRT(V22^2+W22^2) -> 1.2909944 | Z22: =X22/Y22 -> 0 | AA22: =IF(AND(ABS(X22)>=$B$4,ABS(Z22)>=$B$5),"DIF Besar - review",IF(AND(ABS(X22)>=$B$3,ABS(Z22)>=$B$5),"DIF Moderat - cek","Negligible")) -> Negligible | AB22: =IF(ABS(X22)>=$B$4,"Berpotensi Bias - Tinjau Konten",IF(ABS(X22)>=$B$3,"Indikasi Ringan - Pantau","Tidak Ada Indikasi Bias")) -> Tidak Ada Indikasi Bias
... A110: =LQO!A104 -> 100. Perbedaan audit internal vs TM adalah: | B110: =LQO!B104 -> 1 | C110: =LQO!C104 -> 1 | D110: =LQO!D104 -> 1 | E110: =LQO!E104 -> 0 | F110: =LQO!F104 -> 1 | G110: =LQO!G104 -> 0 | H110: =LQO!H104 -> 1 | ... K110: =LQO!K104 -> 0 | L110: =COUNTIF($B$8:$K$8,"Laki-Laki") -> 5 | M110: =COUNTIF($B$8:$K$8,"Perempuan") -> 5 | N110: =SUMIF($B$8:$K$8,"Laki-Laki",LQO!B104:K104) -> 3 | O110: =SUMIF($B$8:$K$8,"Perempuan",LQO!B104:K104) -> 3 | P110: =IF(N110=0,0.3,IF(N110=L110,L110-0.3,N110)) -> 3 | Q110: =IF(O110=0,0.3,IF(O110=M110,M110-0.3,O110)) -> 3 | R110: =LN((L110-P110)/P110) -> -0.40546511 | S110: =LN((M110-Q110)/Q110) -> -0.40546511 | T110: =R110-AVERAGE($R$11:$R$110) -> -0.13670119 | U110: =S110-AVERAGE($S$11:$S$110) -> -0.13670119 | V110: =SQRT(1/P110+1/(L110-P110)) -> 0.91287093 | W110: =SQRT(1/Q110+1/(M110-Q110)) -> 0.91287093 | X110: =T110-U110 -> 0 | Y110: =SQRT(V110^2+W110^2) -> 1.2909944 | Z110: =X110/Y110 -> 0 | AA110: =IF(AND(ABS(X110)>=$B$4,ABS(Z110)>=$B$5),"DIF Besar - review",IF(AND(ABS(X110)>=$B$3,ABS(Z110)>=$B$5),"DIF Moderat - cek","Negligible")) -> Negligible | AB110: =IF(ABS(X110)>=$B$4,"Berpotensi Bias - Tinjau Konten",IF(ABS(X110)>=$B$3,"Indikasi Ringan - Pantau","Tidak Ada Indikasi Bias")) -> Tidak Ada Indikasi Bias
B111: =SUM(B11:B110) -> 88 | C111: =SUM(C11:C110) -> 88 | D111: =SUM(D11:D110) -> 83 | E111: =SUM(E11:E110) -> 52 | F111: =SUM(F11:F110) -> 83 | G111: =SUM(G11:G110) -> 52 | H111: =SUM(H11:H110) -> 26 | I111: =SUM(I11:I110) -> 26 | ... K111: =SUM(K11:K110) -> 31

Sheet DIF-Rasch-FMO
A1: UJI RASCH DIF (Pendekatan PROX) — Skema FMO
A3: Ambang DIF (logit) - Moderat | B3: 0.5 | N3: Ringkasan Signifikansi Statistik (t-test) | Q3: Ringkasan Kesimpulan Praktis (Kontras)
A4: Ambang DIF (logit) - Besar | B4: 1 | N4: DIF Besar - review | O4: =COUNTIF($AA$11:$AA$110,"DIF Besar - review") -> 0 | Q4: Berpotensi Bias - Tinjau Konten | R4: =COUNTIF($AB$11:$AB$110,"Berpotensi Bias - Tinjau Konten") -> 0
A5: Ambang |t| minimum | B5: 2 | N5: DIF Moderat - cek | O5: =COUNTIF($AA$11:$AA$110,"DIF Moderat - cek") -> 0 | Q5: Indikasi Ringan - Pantau | R5: =COUNTIF($AB$11:$AB$110,"Indikasi Ringan - Pantau") -> 0
A6: Kontras DIF Maksimum (data ini) | B6: =_xlfn.AGGREGATE(14,6,ABS(X11:X110),1) -> 0 | N6: Negligible | O6: =COUNTIF($AA$11:$AA$110,"Negligible") -> 100 | Q6: Tidak Ada Indikasi Bias | R6: =COUNTIF($AB$11:$AB$110,"Tidak Ada Indikasi Bias") -> 100
A8: Jenis Kelamin | B8: =FMO!B2 -> Perempuan | C8: =FMO!C2 -> Laki-Laki | D8: =FMO!D2 -> Perempuan | E8: =FMO!E2 -> Perempuan | F8: =FMO!F2 -> Laki-Laki | G8: =FMO!G2 -> Laki-Laki | H8: =FMO!H2 -> Perempuan | I8: =FMO!I2 -> Laki-Laki | ... K8: =FMO!K2 -> Laki-Laki
A9: Soal | B9: Asesi | L9: N (L) | M9: N (P) | N9: S (L) | O9: S (P) | P9: S adj (L) | Q9: S adj (P) | R9: β mentah (L) | S9: β mentah (P) | T9: β center (L) | U9: β center (P) | V9: SE (L) | W9: SE (P) | X9: Kontras DIF | Y9: SE Gabungan | Z9: t-stat | AA9: Klasifikasi DIF | AB9: Kesimpulan Praktis (Kontras)
B10: 1 | C10: 2 | D10: 3 | E10: 4 | F10: 5 | G10: 6 | H10: 7 | I10: 8 | J10: 9 | K10: 10
A11: =FMO!A5 -> 1. Tujuan utama penerapan sistem keamanan pangan di industri adalah: | B11: =FMO!B5 -> 1 | C11: =FMO!C5 -> 1 | D11: =FMO!D5 -> 1 | E11: =FMO!E5 -> 0 | F11: =FMO!F5 -> 1 | G11: =FMO!G5 -> 0 | H11: =FMO!H5 -> 0 | ... K11: =FMO!K5 -> 0 | L11: =COUNTIF($B$8:$K$8,"Laki-Laki") -> 5 | M11: =COUNTIF($B$8:$K$8,"Perempuan") -> 5 | N11: =SUMIF($B$8:$K$8,"Laki-Laki",FMO!B5:K5) -> 2 | O11: =SUMIF($B$8:$K$8,"Perempuan",FMO!B5:K5) -> 2 | P11: =IF(N11=0,0.3,IF(N11=L11,L11-0.3,N11)) -> 2 | Q11: =IF(O11=0,0.3,IF(O11=M11,M11-0.3,O11)) -> 2 | R11: =LN((L11-P11)/P11) -> 0.40546511 | S11: =LN((M11-Q11)/Q11) -> 0.40546511 | T11: =R11-AVERAGE($R$11:$R$110) -> 0.58973803 | U11: =S11-AVERAGE($S$11:$S$110) -> 0.58973803 | V11: =SQRT(1/P11+1/(L11-P11)) -> 0.91287093 | W11: =SQRT(1/Q11+1/(M11-Q11)) -> 0.91287093 | X11: =T11-U11 -> 0 | Y11: =SQRT(V11^2+W11^2) -> 1.2909944 | Z11: =X11/Y11 -> 0 | AA11: =IF(AND(ABS(X11)>=$B$4,ABS(Z11)>=$B$5),"DIF Besar - review",IF(AND(ABS(X11)>=$B$3,ABS(Z11)>=$B$5),"DIF Moderat - cek","Negligible")) -> Negligible | AB11: =IF(ABS(X11)>=$B$4,"Berpotensi Bias - Tinjau Konten",IF(ABS(X11)>=$B$3,"Indikasi Ringan - Pantau","Tidak Ada Indikasi Bias")) -> Tidak Ada Indikasi Bias
A12: =FMO!A6 -> 2. Manakah di bawah ini yang merupakan contoh "Bahaya Biologis" dalam keamanan pangan? | B12: =FMO!B6 -> 1 | C12: =FMO!C6 -> 1 | D12: =FMO!D6 -> 1 | E12: =FMO!E6 -> 0 | F12: =FMO!F6 -> 1 | G12: =FMO!G6 -> 0 | H12: =FMO!H6 -> 0 | ... K12: =FMO!K6 -> 1 | L12: =COUNTIF($B$8:$K$8,"Laki-Laki") -> 5 | M12: =COUNTIF($B$8:$K$8,"Perempuan") -> 5 | N12: =SUMIF($B$8:$K$8,"Laki-Laki",FMO!B6:K6) -> 3 | O12: =SUMIF($B$8:$K$8,"Perempuan",FMO!B6:K6) -> 3 | P12: =IF(N12=0,0.3,IF(N12=L12,L12-0.3,N12)) -> 3 | Q12: =IF(O12=0,0.3,IF(O12=M12,M12-0.3,O12)) -> 3 | R12: =LN((L12-P12)/P12) -> -0.40546511 | S12: =LN((M12-Q12)/Q12) -> -0.40546511 | T12: =R12-AVERAGE($R$11:$R$110) -> -0.22119219 | U12: =S12-AVERAGE($S$11:$S$110) -> -0.22119219 | V12: =SQRT(1/P12+1/(L12-P12)) -> 0.91287093 | W12: =SQRT(1/Q12+1/(M12-Q12)) -> 0.91287093 | X12: =T12-U12 -> 0 | Y12: =SQRT(V12^2+W12^2) -> 1.2909944 | Z12: =X12/Y12 -> 0 | AA12: =IF(AND(ABS(X12)>=$B$4,ABS(Z12)>=$B$5),"DIF Besar - review",IF(AND(ABS(X12)>=$B$3,ABS(Z12)>=$B$5),"DIF Moderat - cek","Negligible")) -> Negligible | AB12: =IF(ABS(X12)>=$B$4,"Berpotensi Bias - Tinjau Konten",IF(ABS(X12)>=$B$3,"Indikasi Ringan - Pantau","Tidak Ada Indikasi Bias")) -> Tidak Ada Indikasi Bias
A13: =FMO!A7 -> 3. Undang-Undang Republik Indonesia yang menjadi landasan utama tentang Pangan adalah: | B13: =FMO!B7 -> 1 | C13: =FMO!C7 -> 1 | D13: =FMO!D7 -> 1 | E13: =FMO!E7 -> 1 | F13: =FMO!F7 -> 1 | G13: =FMO!G7 -> 1 | H13: =FMO!H7 -> 0 | ... K13: =FMO!K7 -> 0 | L13: =COUNTIF($B$8:$K$8,"Laki-Laki") -> 5 | M13: =COUNTIF($B$8:$K$8,"Perempuan") -> 5 | N13: =SUMIF($B$8:$K$8,"Laki-Laki",FMO!B7:K7) -> 3 | O13: =SUMIF($B$8:$K$8,"Perempuan",FMO!B7:K7) -> 3 | P13: =IF(N13=0,0.3,IF(N13=L13,L13-0.3,N13)) -> 3 | Q13: =IF(O13=0,0.3,IF(O13=M13,M13-0.3,O13)) -> 3 | R13: =LN((L13-P13)/P13) -> -0.40546511 | S13: =LN((M13-Q13)/Q13) -> -0.40546511 | T13: =R13-AVERAGE($R$11:$R$110) -> -0.22119219 | U13: =S13-AVERAGE($S$11:$S$110) -> -0.22119219 | V13: =SQRT(1/P13+1/(L13-P13)) -> 0.91287093 | W13: =SQRT(1/Q13+1/(M13-Q13)) -> 0.91287093 | X13: =T13-U13 -> 0 | Y13: =SQRT(V13^2+W13^2) -> 1.2909944 | Z13: =X13/Y13 -> 0 | AA13: =IF(AND(ABS(X13)>=$B$4,ABS(Z13)>=$B$5),"DIF Besar - review",IF(AND(ABS(X13)>=$B$3,ABS(Z13)>=$B$5),"DIF Moderat - cek","Negligible")) -> Negligible | AB13: =IF(ABS(X13)>=$B$4,"Berpotensi Bias - Tinjau Konten",IF(ABS(X13)>=$B$3,"Indikasi Ringan - Pantau","Tidak Ada Indikasi Bias")) -> Tidak Ada Indikasi Bias
A14: =FMO!A8 -> 4. Apa perbedaan mendasar antara "Keamanan Pangan" (Food Safety) dan "Mutu Pangan" (Food Quality)? | B14: =FMO!B8 -> 1 | C14: =FMO!C8 -> 1 | D14: =FMO!D8 -> 1 | E14: =FMO!E8 -> 0 | F14: =FMO!F8 -> 1 | G14: =FMO!G8 -> 0 | H14: =FMO!H8 -> 0 | ... K14: =FMO!K8 -> 1 | L14: =COUNTIF($B$8:$K$8,"Laki-Laki") -> 5 | M14: =COUNTIF($B$8:$K$8,"Perempuan") -> 5 | N14: =SUMIF($B$8:$K$8,"Laki-Laki",FMO!B8:K8) -> 3 | O14: =SUMIF($B$8:$K$8,"Perempuan",FMO!B8:K8) -> 3 | P14: =IF(N14=0,0.3,IF(N14=L14,L14-0.3,N14)) -> 3 | Q14: =IF(O14=0,0.3,IF(O14=M14,M14-0.3,O14)) -> 3 | R14: =LN((L14-P14)/P14) -> -0.40546511 | S14: =LN((M14-Q14)/Q14) -> -0.40546511 | T14: =R14-AVERAGE($R$11:$R$110) -> -0.22119219 | U14: =S14-AVERAGE($S$11:$S$110) -> -0.22119219 | V14: =SQRT(1/P14+1/(L14-P14)) -> 0.91287093 | W14: =SQRT(1/Q14+1/(M14-Q14)) -> 0.91287093 | X14: =T14-U14 -> 0 | Y14: =SQRT(V14^2+W14^2) -> 1.2909944 | Z14: =X14/Y14 -> 0 | AA14: =IF(AND(ABS(X14)>=$B$4,ABS(Z14)>=$B$5),"DIF Besar - review",IF(AND(ABS(X14)>=$B$3,ABS(Z14)>=$B$5),"DIF Moderat - cek","Negligible")) -> Negligible | AB14: =IF(ABS(X14)>=$B$4,"Berpotensi Bias - Tinjau Konten",IF(ABS(X14)>=$B$3,"Indikasi Ringan - Pantau","Tidak Ada Indikasi Bias")) -> Tidak Ada Indikasi Bias
A15: =FMO!A9 -> 5. Salah satu elemen kunci dalam ISO 22000 adalah "Komunikasi Interaktif". Apa tujuannya? | B15: =FMO!B9 -> 1 | C15: =FMO!C9 -> 1 | D15: =FMO!D9 -> 1 | E15: =FMO!E9 -> 1 | F15: =FMO!F9 -> 1 | G15: =FMO!G9 -> 1 | H15: =FMO!H9 -> 0 | ... K15: =FMO!K9 -> 0 | L15: =COUNTIF($B$8:$K$8,"Laki-Laki") -> 5 | M15: =COUNTIF($B$8:$K$8,"Perempuan") -> 5 | N15: =SUMIF($B$8:$K$8,"Laki-Laki",FMO!B9:K9) -> 3 | O15: =SUMIF($B$8:$K$8,"Perempuan",FMO!B9:K9) -> 3 | P15: =IF(N15=0,0.3,IF(N15=L15,L15-0.3,N15)) -> 3 | Q15: =IF(O15=0,0.3,IF(O15=M15,M15-0.3,O15)) -> 3 | R15: =LN((L15-P15)/P15) -> -0.40546511 | S15: =LN((M15-Q15)/Q15) -> -0.40546511 | T15: =R15-AVERAGE($R$11:$R$110) -> -0.22119219 | U15: =S15-AVERAGE($S$11:$S$110) -> -0.22119219 | V15: =SQRT(1/P15+1/(L15-P15)) -> 0.91287093 | W15: =SQRT(1/Q15+1/(M15-Q15)) -> 0.91287093 | X15: =T15-U15 -> 0 | Y15: =SQRT(V15^2+W15^2) -> 1.2909944 | Z15: =X15/Y15 -> 0 | AA15: =IF(AND(ABS(X15)>=$B$4,ABS(Z15)>=$B$5),"DIF Besar - review",IF(AND(ABS(X15)>=$B$3,ABS(Z15)>=$B$5),"DIF Moderat - cek","Negligible")) -> Negligible | AB15: =IF(ABS(X15)>=$B$4,"Berpotensi Bias - Tinjau Konten",IF(ABS(X15)>=$B$3,"Indikasi Ringan - Pantau","Tidak Ada Indikasi Bias")) -> Tidak Ada Indikasi Bias
A16: =FMO!A10 -> 6. Food Safety Culture (Budaya Keamanan Pangan) menuntut komitmen dari: | B16: =FMO!B10 -> 1 | C16: =FMO!C10 -> 1 | D16: =FMO!D10 -> 1 | E16: =FMO!E10 -> 0 | F16: =FMO!F10 -> 1 | G16: =FMO!G10 -> 0 | H16: =FMO!H10 -> 0 | ... K16: =FMO!K10 -> 0 | L16: =COUNTIF($B$8:$K$8,"Laki-Laki") -> 5 | M16: =COUNTIF($B$8:$K$8,"Perempuan") -> 5 | N16: =SUMIF($B$8:$K$8,"Laki-Laki",FMO!B10:K10) -> 2 | O16: =SUMIF($B$8:$K$8,"Perempuan",FMO!B10:K10) -> 2 | P16: =IF(N16=0,0.3,IF(N16=L16,L16-0.3,N16)) -> 2 | Q16: =IF(O16=0,0.3,IF(O16=M16,M16-0.3,O16)) -> 2 | R16: =LN((L16-P16)/P16) -> 0.40546511 | S16: =LN((M16-Q16)/Q16) -> 0.40546511 | T16: =R16-AVERAGE($R$11:$R$110) -> 0.58973803 | U16: =S16-AVERAGE($S$11:$S$110) -> 0.58973803 | V16: =SQRT(1/P16+1/(L16-P16)) -> 0.91287093 | W16: =SQRT(1/Q16+1/(M16-Q16)) -> 0.91287093 | X16: =T16-U16 -> 0 | Y16: =SQRT(V16^2+W16^2) -> 1.2909944 | Z16: =X16/Y16 -> 0 | AA16: =IF(AND(ABS(X16)>=$B$4,ABS(Z16)>=$B$5),"DIF Besar - review",IF(AND(ABS(X16)>=$B$3,ABS(Z16)>=$B$5),"DIF Moderat - cek","Negligible")) -> Negligible | AB16: =IF(ABS(X16)>=$B$4,"Berpotensi Bias - Tinjau Konten",IF(ABS(X16)>=$B$3,"Indikasi Ringan - Pantau","Tidak Ada Indikasi Bias")) -> Tidak Ada Indikasi Bias
A17: =FMO!A11 -> 7. Organisasi internasional yang menerbitkan standar dasar HACCP dan prinsip kebersihan pangan (General Principles of Food Hygiene) adalah: | B17: =FMO!B11 -> 1 | C17: =FMO!C11 -> 1 | D17: =FMO!D11 -> 1 | E17: =FMO!E11 -> 1 | F17: =FMO!F11 -> 1 | G17: =FMO!G11 -> 1 | H17: =FMO!H11 -> 0 | ... K17: =FMO!K11 -> 0 | L17: =COUNTIF($B$8:$K$8,"Laki-Laki") -> 5 | M17: =COUNTIF($B$8:$K$8,"Perempuan") -> 5 | N17: =SUMIF($B$8:$K$8,"Laki-Laki",FMO!B11:K11) -> 3 | O17: =SUMIF($B$8:$K$8,"Perempuan",FMO!B11:K11) -> 3 | P17: =IF(N17=0,0.3,IF(N17=L17,L17-0.3,N17)) -> 3 | Q17: =IF(O17=0,0.3,IF(O17=M17,M17-0.3,O17)) -> 3 | R17: =LN((L17-P17)/P17) -> -0.40546511 | S17: =LN((M17-Q17)/Q17) -> -0.40546511 | T17: =R17-AVERAGE($R$11:$R$110) -> -0.22119219 | U17: =S17-AVERAGE($S$11:$S$110) -> -0.22119219 | V17: =SQRT(1/P17+1/(L17-P17)) -> 0.91287093 | W17: =SQRT(1/Q17+1/(M17-Q17)) -> 0.91287093 | X17: =T17-U17 -> 0 | Y17: =SQRT(V17^2+W17^2) -> 1.2909944 | Z17: =X17/Y17 -> 0 | AA17: =IF(AND(ABS(X17)>=$B$4,ABS(Z17)>=$B$5),"DIF Besar - review",IF(AND(ABS(X17)>=$B$3,ABS(Z17)>=$B$5),"DIF Moderat - cek","Negligible")) -> Negligible | AB17: =IF(ABS(X17)>=$B$4,"Berpotensi Bias - Tinjau Konten",IF(ABS(X17)>=$B$3,"Indikasi Ringan - Pantau","Tidak Ada Indikasi Bias")) -> Tidak Ada Indikasi Bias
A18: =FMO!A12 -> 8. Kontaminasi yang terjadi karena perpindahan bakteri dari bahan mentah ke produk matang melalui perantara (pisau, tangan, talenan) disebut: | B18: =FMO!B12 -> 1 | C18: =FMO!C12 -> 1 | D18: =FMO!D12 -> 1 | E18: =FMO!E12 -> 1 | F18: =FMO!F12 -> 1 | G18: =FMO!G12 -> 1 | H18: =FMO!H12 -> 1 | ... K18: =FMO!K12 -> 0 | L18: =COUNTIF($B$8:$K$8,"Laki-Laki") -> 5 | M18: =COUNTIF($B$8:$K$8,"Perempuan") -> 5 | N18: =SUMIF($B$8:$K$8,"Laki-Laki",FMO!B12:K12) -> 4 | O18: =SUMIF($B$8:$K$8,"Perempuan",FMO!B12:K12) -> 4 | P18: =IF(N18=0,0.3,IF(N18=L18,L18-0.3,N18)) -> 4 | Q18: =IF(O18=0,0.3,IF(O18=M18,M18-0.3,O18)) -> 4 | R18: =LN((L18-P18)/P18) -> -1.3862944 | S18: =LN((M18-Q18)/Q18) -> -1.3862944 | T18: =R18-AVERAGE($R$11:$R$110) -> -1.2020214 | U18: =S18-AVERAGE($S$11:$S$110) -> -1.2020214 | V18: =SQRT(1/P18+1/(L18-P18)) -> 1.118034 | W18: =SQRT(1/Q18+1/(M18-Q18)) -> 1.118034 | X18: =T18-U18 -> 0 | Y18: =SQRT(V18^2+W18^2) -> 1.5811388 | Z18: =X18/Y18 -> 0 | AA18: =IF(AND(ABS(X18)>=$B$4,ABS(Z18)>=$B$5),"DIF Besar - review",IF(AND(ABS(X18)>=$B$3,ABS(Z18)>=$B$5),"DIF Moderat - cek","Negligible")) -> Negligible | AB18: =IF(ABS(X18)>=$B$4,"Berpotensi Bias - Tinjau Konten",IF(ABS(X18)>=$B$3,"Indikasi Ringan - Pantau","Tidak Ada Indikasi Bias")) -> Tidak Ada Indikasi Bias
A19: =FMO!A13 -> 9. Benda asing seperti rambut, staples, atau kerikil dalam makanan dikategorikan sebagai: | B19: =FMO!B13 -> 1 | C19: =FMO!C13 -> 1 | D19: =FMO!D13 -> 1 | E19: =FMO!E13 -> 0 | F19: =FMO!F13 -> 1 | G19: =FMO!G13 -> 0 | H19: =FMO!H13 -> 0 | ... K19: =FMO!K13 -> 1 | L19: =COUNTIF($B$8:$K$8,"Laki-Laki") -> 5 | M19: =COUNTIF($B$8:$K$8,"Perempuan") -> 5 | N19: =SUMIF($B$8:$K$8,"Laki-Laki",FMO!B13:K13) -> 3 | O19: =SUMIF($B$8:$K$8,"Perempuan",FMO!B13:K13) -> 3 | P19: =IF(N19=0,0.3,IF(N19=L19,L19-0.3,N19)) -> 3 | Q19: =IF(O19=0,0.3,IF(O19=M19,M19-0.3,O19)) -> 3 | R19: =LN((L19-P19)/P19) -> -0.40546511 | S19: =LN((M19-Q19)/Q19) -> -0.40546511 | T19: =R19-AVERAGE($R$11:$R$110) -> -0.22119219 | U19: =S19-AVERAGE($S$11:$S$110) -> -0.22119219 | V19: =SQRT(1/P19+1/(L19-P19)) -> 0.91287093 | W19: =SQRT(1/Q19+1/(M19-Q19)) -> 0.91287093 | X19: =T19-U19 -> 0 | Y19: =SQRT(V19^2+W19^2) -> 1.2909944 | Z19: =X19/Y19 -> 0 | AA19: =IF(AND(ABS(X19)>=$B$4,ABS(Z19)>=$B$5),"DIF Besar - review",IF(AND(ABS(X19)>=$B$3,ABS(Z19)>=$B$5),"DIF Moderat - cek","Negligible")) -> Negligible | AB19: =IF(ABS(X19)>=$B$4,"Berpotensi Bias - Tinjau Konten",IF(ABS(X19)>=$B$3,"Indikasi Ringan - Pantau","Tidak Ada Indikasi Bias")) -> Tidak Ada Indikasi Bias
A20: =FMO!A14 -> 10. Alergen pangan (seperti kacang, susu, telur) dikategorikan sebagai bahaya jenis apa dalam sistem HACCP modern? | B20: =FMO!B14 -> 1 | C20: =FMO!C14 -> 1 | D20: =FMO!D14 -> 1 | E20: =FMO!E14 -> 0 | F20: =FMO!F14 -> 1 | G20: =FMO!G14 -> 0 | H20: =FMO!H14 -> 1 | ... K20: =FMO!K14 -> 0 | L20: =COUNTIF($B$8:$K$8,"Laki-Laki") -> 5 | M20: =COUNTIF($B$8:$K$8,"Perempuan") -> 5 | N20: =SUMIF($B$8:$K$8,"Laki-Laki",FMO!B14:K14) -> 3 | O20: =SUMIF($B$8:$K$8,"Perempuan",FMO!B14:K14) -> 3 | P20: =IF(N20=0,0.3,IF(N20=L20,L20-0.3,N20)) -> 3 | Q20: =IF(O20=0,0.3,IF(O20=M20,M20-0.3,O20)) -> 3 | R20: =LN((L20-P20)/P20) -> -0.40546511 | S20: =LN((M20-Q20)/Q20) -> -0.40546511 | T20: =R20-AVERAGE($R$11:$R$110) -> -0.22119219 | U20: =S20-AVERAGE($S$11:$S$110) -> -0.22119219 | V20: =SQRT(1/P20+1/(L20-P20)) -> 0.91287093 | W20: =SQRT(1/Q20+1/(M20-Q20)) -> 0.91287093 | X20: =T20-U20 -> 0 | Y20: =SQRT(V20^2+W20^2) -> 1.2909944 | Z20: =X20/Y20 -> 0 | AA20: =IF(AND(ABS(X20)>=$B$4,ABS(Z20)>=$B$5),"DIF Besar - review",IF(AND(ABS(X20)>=$B$3,ABS(Z20)>=$B$5),"DIF Moderat - cek","Negligible")) -> Negligible | AB20: =IF(ABS(X20)>=$B$4,"Berpotensi Bias - Tinjau Konten",IF(ABS(X20)>=$B$3,"Indikasi Ringan - Pantau","Tidak Ada Indikasi Bias")) -> Tidak Ada Indikasi Bias
A21: =FMO!A15 -> 11. Program Prasyarat (PRP) atau sering disebut GMP berfungsi untuk: | B21: =FMO!B15 -> 1 | C21: =FMO!C15 -> 1 | D21: =FMO!D15 -> 0 | E21: =FMO!E15 -> 1 | F21: =FMO!F15 -> 0 | G21: =FMO!G15 -> 1 | H21: =FMO!H15 -> 0 | ... K21: =FMO!K15 -> 0 | L21: =COUNTIF($B$8:$K$8,"Laki-Laki") -> 5 | M21: =COUNTIF($B$8:$K$8,"Perempuan") -> 5 | N21: =SUMIF($B$8:$K$8,"Laki-Laki",FMO!B15:K15) -> 2 | O21: =SUMIF($B$8:$K$8,"Perempuan",FMO!B15:K15) -> 2 | P21: =IF(N21=0,0.3,IF(N21=L21,L21-0.3,N21)) -> 2 | Q21: =IF(O21=0,0.3,IF(O21=M21,M21-0.3,O21)) -> 2 | R21: =LN((L21-P21)/P21) -> 0.40546511 | S21: =LN((M21-Q21)/Q21) -> 0.40546511 | T21: =R21-AVERAGE($R$11:$R$110) -> 0.58973803 | U21: =S21-AVERAGE($S$11:$S$110) -> 0.58973803 | V21: =SQRT(1/P21+1/(L21-P21)) -> 0.91287093 | W21: =SQRT(1/Q21+1/(M21-Q21)) -> 0.91287093 | X21: =T21-U21 -> 0 | Y21: =SQRT(V21^2+W21^2) -> 1.2909944 | Z21: =X21/Y21 -> 0 | AA21: =IF(AND(ABS(X21)>=$B$4,ABS(Z21)>=$B$5),"DIF Besar - review",IF(AND(ABS(X21)>=$B$3,ABS(Z21)>=$B$5),"DIF Moderat - cek","Negligible")) -> Negligible | AB21: =IF(ABS(X21)>=$B$4,"Berpotensi Bias - Tinjau Konten",IF(ABS(X21)>=$B$3,"Indikasi Ringan - Pantau","Tidak Ada Indikasi Bias")) -> Tidak Ada Indikasi Bias
A22: =FMO!A16 -> 12. Dalam desain layout pabrik, alur proses (flow process) sebaiknya: | B22: =FMO!B16 -> 1 | C22: =FMO!C16 -> 1 | D22: =FMO!D16 -> 0 | E22: =FMO!E16 -> 0 | F22: =FMO!F16 -> 0 | G22: =FMO!G16 -> 0 | H22: =FMO!H16 -> 0 | ... K22: =FMO!K16 -> 0 | L22: =COUNTIF($B$8:$K$8,"Laki-Laki") -> 5 | M22: =COUNTIF($B$8:$K$8,"Perempuan") -> 5 | N22: =SUMIF($B$8:$K$8,"Laki-Laki",FMO!B16:K16) -> 1 | O22: =SUMIF($B$8:$K$8,"Perempuan",FMO!B16:K16) -> 1 | P22: =IF(N22=0,0.3,IF(N22=L22,L22-0.3,N22)) -> 1 | Q22: =IF(O22=0,0.3,IF(O22=M22,M22-0.3,O22)) -> 1 | R22: =LN((L22-P22)/P22) -> 1.3862944 | S22: =LN((M22-Q22)/Q22) -> 1.3862944 | T22: =R22-AVERAGE($R$11:$R$110) -> 1.5705673 | U22: =S22-AVERAGE($S$11:$S$110) -> 1.5705673 | V22: =SQRT(1/P22+1/(L22-P22)) -> 1.118034 | W22: =SQRT(1/Q22+1/(M22-Q22)) -> 1.118034 | X22: =T22-U22 -> 0 | Y22: =SQRT(V22^2+W22^2) -> 1.5811388 | Z22: =X22/Y22 -> 0 | AA22: =IF(AND(ABS(X22)>=$B$4,ABS(Z22)>=$B$5),"DIF Besar - review",IF(AND(ABS(X22)>=$B$3,ABS(Z22)>=$B$5),"DIF Moderat - cek","Negligible")) -> Negligible | AB22: =IF(ABS(X22)>=$B$4,"Berpotensi Bias - Tinjau Konten",IF(ABS(X22)>=$B$3,"Indikasi Ringan - Pantau","Tidak Ada Indikasi Bias")) -> Tidak Ada Indikasi Bias
... A110: =FMO!A104 -> 100. Refresher Training (Pelatihan Penyegaran) perlu dilakukan: | B110: =FMO!B104 -> 1 | C110: =FMO!C104 -> 1 | D110: =FMO!D104 -> 1 | E110: =FMO!E104 -> 0 | F110: =FMO!F104 -> 1 | G110: =FMO!G104 -> 0 | H110: =FMO!H104 -> 0 | ... K110: =FMO!K104 -> 0 | L110: =COUNTIF($B$8:$K$8,"Laki-Laki") -> 5 | M110: =COUNTIF($B$8:$K$8,"Perempuan") -> 5 | N110: =SUMIF($B$8:$K$8,"Laki-Laki",FMO!B104:K104) -> 2 | O110: =SUMIF($B$8:$K$8,"Perempuan",FMO!B104:K104) -> 2 | P110: =IF(N110=0,0.3,IF(N110=L110,L110-0.3,N110)) -> 2 | Q110: =IF(O110=0,0.3,IF(O110=M110,M110-0.3,O110)) -> 2 | R110: =LN((L110-P110)/P110) -> 0.40546511 | S110: =LN((M110-Q110)/Q110) -> 0.40546511 | T110: =R110-AVERAGE($R$11:$R$110) -> 0.58973803 | U110: =S110-AVERAGE($S$11:$S$110) -> 0.58973803 | V110: =SQRT(1/P110+1/(L110-P110)) -> 0.91287093 | W110: =SQRT(1/Q110+1/(M110-Q110)) -> 0.91287093 | X110: =T110-U110 -> 0 | Y110: =SQRT(V110^2+W110^2) -> 1.2909944 | Z110: =X110/Y110 -> 0 | AA110: =IF(AND(ABS(X110)>=$B$4,ABS(Z110)>=$B$5),"DIF Besar - review",IF(AND(ABS(X110)>=$B$3,ABS(Z110)>=$B$5),"DIF Moderat - cek","Negligible")) -> Negligible | AB110: =IF(ABS(X110)>=$B$4,"Berpotensi Bias - Tinjau Konten",IF(ABS(X110)>=$B$3,"Indikasi Ringan - Pantau","Tidak Ada Indikasi Bias")) -> Tidak Ada Indikasi Bias
B111: =SUM(B11:B110) -> 81 | C111: =SUM(C11:C110) -> 81 | D111: =SUM(D11:D110) -> 83 | E111: =SUM(E11:E110) -> 58 | F111: =SUM(F11:F110) -> 83 | G111: =SUM(G11:G110) -> 58 | H111: =SUM(H11:H110) -> 20 | I111: =SUM(I11:I110) -> 20 | ... K111: =SUM(K11:K110) -> 28

Sheet DIF-Rasch-PSP
A1: UJI RASCH DIF (Pendekatan PROX) — Skema PSP
A3: Ambang DIF (logit) - Moderat | B3: 0.5 | N3: Ringkasan Signifikansi Statistik (t-test) | Q3: Ringkasan Kesimpulan Praktis (Kontras)
A4: Ambang DIF (logit) - Besar | B4: 1 | N4: DIF Besar - review | O4: =COUNTIF($AA$11:$AA$110,"DIF Besar - review") -> 0 | Q4: Berpotensi Bias - Tinjau Konten | R4: =COUNTIF($AB$11:$AB$110,"Berpotensi Bias - Tinjau Konten") -> 0
A5: Ambang |t| minimum | B5: 2 | N5: DIF Moderat - cek | O5: =COUNTIF($AA$11:$AA$110,"DIF Moderat - cek") -> 0 | Q5: Indikasi Ringan - Pantau | R5: =COUNTIF($AB$11:$AB$110,"Indikasi Ringan - Pantau") -> 0
A6: Kontras DIF Maksimum (data ini) | B6: =_xlfn.AGGREGATE(14,6,ABS(X11:X110),1) -> 0 | N6: Negligible | O6: =COUNTIF($AA$11:$AA$110,"Negligible") -> 100 | Q6: Tidak Ada Indikasi Bias | R6: =COUNTIF($AB$11:$AB$110,"Tidak Ada Indikasi Bias") -> 100
A8: Jenis Kelamin | B8: =PSP!B2 -> Perempuan | C8: =PSP!C2 -> Laki-Laki | D8: =PSP!D2 -> Perempuan | E8: =PSP!E2 -> Perempuan | F8: =PSP!F2 -> Laki-Laki | G8: =PSP!G2 -> Laki-Laki | H8: =PSP!H2 -> Perempuan | I8: =PSP!I2 -> Laki-Laki | ... K8: =PSP!K2 -> Laki-Laki
A9: Soal | B9: Asesi | L9: N (L) | M9: N (P) | N9: S (L) | O9: S (P) | P9: S adj (L) | Q9: S adj (P) | R9: β mentah (L) | S9: β mentah (P) | T9: β center (L) | U9: β center (P) | V9: SE (L) | W9: SE (P) | X9: Kontras DIF | Y9: SE Gabungan | Z9: t-stat | AA9: Klasifikasi DIF | AB9: Kesimpulan Praktis (Kontras)
B10: 1 | C10: 2 | D10: 3 | E10: 4 | F10: 5 | G10: 6 | H10: 7 | I10: 8 | J10: 9 | K10: 10
A11: =PSP!A5 -> 1. Dalam konteks industri pangan, peran utama evaluasi sensori adalah: | B11: =PSP!B5 -> 0 | C11: =PSP!C5 -> 0 | D11: =PSP!D5 -> 0 | E11: =PSP!E5 -> 0 | F11: =PSP!F5 -> 0 | G11: =PSP!G5 -> 0 | H11: =PSP!H5 -> 1 | ... K11: =PSP!K5 -> 0 | L11: =COUNTIF($B$8:$K$8,"Laki-Laki") -> 5 | M11: =COUNTIF($B$8:$K$8,"Perempuan") -> 5 | N11: =SUMIF($B$8:$K$8,"Laki-Laki",PSP!B5:K5) -> 1 | O11: =SUMIF($B$8:$K$8,"Perempuan",PSP!B5:K5) -> 1 | P11: =IF(N11=0,0.3,IF(N11=L11,L11-0.3,N11)) -> 1 | Q11: =IF(O11=0,0.3,IF(O11=M11,M11-0.3,O11)) -> 1 | R11: =LN((L11-P11)/P11) -> 1.3862944 | S11: =LN((M11-Q11)/Q11) -> 1.3862944 | T11: =R11-AVERAGE($R$11:$R$110) -> 1.5232248 | U11: =S11-AVERAGE($S$11:$S$110) -> 1.5232248 | V11: =SQRT(1/P11+1/(L11-P11)) -> 1.118034 | W11: =SQRT(1/Q11+1/(M11-Q11)) -> 1.118034 | X11: =T11-U11 -> 0 | Y11: =SQRT(V11^2+W11^2) -> 1.5811388 | Z11: =X11/Y11 -> 0 | AA11: =IF(AND(ABS(X11)>=$B$4,ABS(Z11)>=$B$5),"DIF Besar - review",IF(AND(ABS(X11)>=$B$3,ABS(Z11)>=$B$5),"DIF Moderat - cek","Negligible")) -> Negligible | AB11: =IF(ABS(X11)>=$B$4,"Berpotensi Bias - Tinjau Konten",IF(ABS(X11)>=$B$3,"Indikasi Ringan - Pantau","Tidak Ada Indikasi Bias")) -> Tidak Ada Indikasi Bias
A12: =PSP!A6 -> 2. Seorang panelis terlatih dalam pengujian sensori dipandang sebagai: | B12: =PSP!B6 -> 1 | C12: =PSP!C6 -> 1 | D12: =PSP!D6 -> 1 | E12: =PSP!E6 -> 1 | F12: =PSP!F6 -> 1 | G12: =PSP!G6 -> 1 | H12: =PSP!H6 -> 0 | ... K12: =PSP!K6 -> 1 | L12: =COUNTIF($B$8:$K$8,"Laki-Laki") -> 5 | M12: =COUNTIF($B$8:$K$8,"Perempuan") -> 5 | N12: =SUMIF($B$8:$K$8,"Laki-Laki",PSP!B6:K6) -> 4 | O12: =SUMIF($B$8:$K$8,"Perempuan",PSP!B6:K6) -> 4 | P12: =IF(N12=0,0.3,IF(N12=L12,L12-0.3,N12)) -> 4 | Q12: =IF(O12=0,0.3,IF(O12=M12,M12-0.3,O12)) -> 4 | R12: =LN((L12-P12)/P12) -> -1.3862944 | S12: =LN((M12-Q12)/Q12) -> -1.3862944 | T12: =R12-AVERAGE($R$11:$R$110) -> -1.2493639 | U12: =S12-AVERAGE($S$11:$S$110) -> -1.2493639 | V12: =SQRT(1/P12+1/(L12-P12)) -> 1.118034 | W12: =SQRT(1/Q12+1/(M12-Q12)) -> 1.118034 | X12: =T12-U12 -> 0 | Y12: =SQRT(V12^2+W12^2) -> 1.5811388 | Z12: =X12/Y12 -> 0 | AA12: =IF(AND(ABS(X12)>=$B$4,ABS(Z12)>=$B$5),"DIF Besar - review",IF(AND(ABS(X12)>=$B$3,ABS(Z12)>=$B$5),"DIF Moderat - cek","Negligible")) -> Negligible | AB12: =IF(ABS(X12)>=$B$4,"Berpotensi Bias - Tinjau Konten",IF(ABS(X12)>=$B$3,"Indikasi Ringan - Pantau","Tidak Ada Indikasi Bias")) -> Tidak Ada Indikasi Bias
A13: =PSP!A7 -> 3. Tujuan utama sertifikasi kompetensi panelis adalah: | B13: =PSP!B7 -> 1 | C13: =PSP!C7 -> 1 | D13: =PSP!D7 -> 1 | E13: =PSP!E7 -> 0 | F13: =PSP!F7 -> 1 | G13: =PSP!G7 -> 0 | H13: =PSP!H7 -> 0 | ... K13: =PSP!K7 -> 1 | L13: =COUNTIF($B$8:$K$8,"Laki-Laki") -> 5 | M13: =COUNTIF($B$8:$K$8,"Perempuan") -> 5 | N13: =SUMIF($B$8:$K$8,"Laki-Laki",PSP!B7:K7) -> 3 | O13: =SUMIF($B$8:$K$8,"Perempuan",PSP!B7:K7) -> 3 | P13: =IF(N13=0,0.3,IF(N13=L13,L13-0.3,N13)) -> 3 | Q13: =IF(O13=0,0.3,IF(O13=M13,M13-0.3,O13)) -> 3 | R13: =LN((L13-P13)/P13) -> -0.40546511 | S13: =LN((M13-Q13)/Q13) -> -0.40546511 | T13: =R13-AVERAGE($R$11:$R$110) -> -0.26853466 | U13: =S13-AVERAGE($S$11:$S$110) -> -0.26853466 | V13: =SQRT(1/P13+1/(L13-P13)) -> 0.91287093 | W13: =SQRT(1/Q13+1/(M13-Q13)) -> 0.91287093 | X13: =T13-U13 -> 0 | Y13: =SQRT(V13^2+W13^2) -> 1.2909944 | Z13: =X13/Y13 -> 0 | AA13: =IF(AND(ABS(X13)>=$B$4,ABS(Z13)>=$B$5),"DIF Besar - review",IF(AND(ABS(X13)>=$B$3,ABS(Z13)>=$B$5),"DIF Moderat - cek","Negligible")) -> Negligible | AB13: =IF(ABS(X13)>=$B$4,"Berpotensi Bias - Tinjau Konten",IF(ABS(X13)>=$B$3,"Indikasi Ringan - Pantau","Tidak Ada Indikasi Bias")) -> Tidak Ada Indikasi Bias
