Workbook

Sheet AIL
A1: UJI VALIDITAS DAN RELIABILITAS SKEMA AUDITOR INTERNAL SPMI TERINTEGRASI ISO 21001:2018
A2: Jenis Kelamin | B2: Perempuan | C2: Laki-Laki | D2: Perempuan | E2: Laki-Laki | F2: Perempuan | G2: Laki-Laki | H2: Perempuan | I2: Laki-Laki | J2: Perempuan | K2: Laki-Laki
A3: Soal | B3: Asesi | L3: Tingkat Kesukaran | M3: Keterangan | N3: Daya Pembeda | O3: Keterangan | Q3: Reliabilitas
B4: 1 | C4: 2 | D4: 3 | E4: 4 | F4: 5 | G4: 6 | H4: 7 | I4: 8 | J4: 9 | K4: 10 | Q4: Soal | R4: Asesi | AB4: p | AC4: 1-p | AD4: p*(1-p)
A5: 1. Hal-hal yang mempengaruhi cakupan program audit adalah … | B5: 1 | C5: 1 | D5: 1 | E5: 1 | F5: 1 | G5: 1 | H5: 0 | I5: 0 | J5: 0 | K5: 0 | L5: =SUM(B5:K5)/10 -> 0.6 | M5: =IF(L5<0.31,"sukar",IF(L5<0.71,"sedang","mudah")) -> sedang | N5: =ABS((SUM(B5:E5)-SUM(F5:I5))*2/8) -> 0.5 | O5: =IF(N5<0.2,"soal dibuang",IF(N5<0.3,"soal diperbaiki",IF(N5<0.4,"soal diterima tapi perlu diperbaiki","soal diterima baik"))) -> soal diterima baik | R5: 1 | S5: 2 | T5: 3 | U5: 4 | V5: 5 | W5: 6 | X5: 7 | Y5: 8 | Z5: 9 | AA5: 10
A6: 2. Manakah dari berikut ini yang merupakan manfaat terbesar dari program audit internal bagi suatu organisasi? | B6: 1 | C6: 1 | D6: 1 | E6: 1 | F6: 0 | G6: 0 | H6: 1 | I6: 1 | J6: 0 | K6: 0 | L6: =SUM(B6:K6)/10 -> 0.6 | M6: =IF(L6<0.31,"sukar",IF(L6<0.71,"sedang","mudah")) -> sedang | N6: =ABS((SUM(B6:E6)-SUM(F6:I6))*2/8) -> 0.5 | O6: =IF(N6<0.2,"soal dibuang",IF(N6<0.3,"soal diperbaiki",IF(N6<0.4,"soal diterima tapi perlu diperbaiki","soal diterima baik"))) -> soal diterima baik | Q6: 1 | R6: =B5 -> 1 | S6: =C5 -> 1 | T6: =D5 -> 1 | U6: =E5 -> 1 | V6: =F5 -> 1 | W6: =G5 -> 1 | X6: =H5 -> 0 | Y6: =I5 -> 0 | ... AA6: =K5 -> 0 | AB6: =SUM(R6:AA6)/COUNT(R6:AA6) -> 0.6 | AC6: =1-AB6 -> 0.4 | AD6: =AB6*AC6 -> 0.24
A7: 3. Manakah dari berikut ini yang merupakan peran paling mendasar dari fungsi audit? | B7: 1 | C7: 1 | D7: 1 | E7: 1 | F7: 1 | G7: 1 | H7: 0 | I7: 0 | J7: 1 | K7: 1 | L7: =SUM(B7:K7)/10 -> 0.8 | M7: =IF(L7<0.31,"sukar",IF(L7<0.71,"sedang","mudah")) -> mudah | N7: =ABS((SUM(B7:E7)-SUM(F7:I7))*2/8) -> 0.5 | O7: =IF(N7<0.2,"soal dibuang",IF(N7<0.3,"soal diperbaiki",IF(N7<0.4,"soal diterima tapi perlu diperbaiki","soal diterima baik"))) -> soal diterima baik | Q7: 2 | R7: =B6 -> 1 | S7: =C6 -> 1 | T7: =D6 -> 1 | U7: =E6 -> 1 | V7: =F6 -> 0 | W7: =G6 -> 0 | X7: =H6 -> 1 | Y7: =I6 -> 1 | ... AA7: =K6 -> 0 | AB7: =SUM(R7:AA7)/COUNT(R7:AA7) -> 0.6 | AC7: =1-AB7 -> 0.4 | AD7: =AB7*AC7 -> 0.24
A8: 4. Personal behavior yang diperlukan untuk menjadi auditor yang ideal, kecuali … | B8: 1 | C8: 1 | D8: 1 | E8: 1 | F8: 1 | G8: 1 | H8: 0 | I8: 0 | J8: 1 | K8: 1 | L8: =SUM(B8:K8)/10 -> 0.8 | M8: =IF(L8<0.31,"sukar",IF(L8<0.71,"sedang","mudah")) -> mudah | N8: =ABS((SUM(B8:E8)-SUM(F8:I8))*2/8) -> 0.5 | O8: =IF(N8<0.2,"soal dibuang",IF(N8<0.3,"soal diperbaiki",IF(N8<0.4,"soal diterima tapi perlu diperbaiki","soal diterima baik"))) -> soal diterima baik | Q8: 3 | R8: =B7 -> 1 | S8: =C7 -> 1 | T8: =D7 -> 1 | U8: =E7 -> 1 | V8: =F7 -> 1 | W8: =G7 -> 1 | X8: =H7 -> 0 | Y8: =I7 -> 0 | ... AA8: =K7 -> 1 | AB8: =SUM(R8:AA8)/COUNT(R8:AA8) -> 0.8 | AC8: =1-AB8 -> 0.2 | AD8: =AB8*AC8 -> 0.16
A9: 5. Pengetahuan umum dan keahlian auditor mencakup, kecuali … | B9: 1 | C9: 1 | D9: 1 | E9: 1 | F9: 0 | G9: 0 | H9: 0 | I9: 0 | J9: 1 | K9: 1 | L9: =SUM(B9:K9)/10 -> 0.6 | M9: =IF(L9<0.31,"sukar",IF(L9<0.71,"sedang","mudah")) -> sedang | N9: =ABS((SUM(B9:E9)-SUM(F9:I9))*2/8) -> 1 | O9: =IF(N9<0.2,"soal dibuang",IF(N9<0.3,"soal diperbaiki",IF(N9<0.4,"soal diterima tapi perlu diperbaiki","soal diterima baik"))) -> soal diterima baik | Q9: 4 | R9: =B8 -> 1 | S9: =C8 -> 1 | T9: =D8 -> 1 | U9: =E8 -> 1 | V9: =F8 -> 1 | W9: =G8 -> 1 | X9: =H8 -> 0 | Y9: =I8 -> 0 | ... AA9: =K8 -> 1 | AB9: =SUM(R9:AA9)/COUNT(R9:AA9) -> 0.8 | AC9: =1-AB9 -> 0.2 | AD9: =AB9*AC9 -> 0.16
A10: 6. Kriteria independen auditor mencakup kebebasan dari … | B10: 0 | C10: 0 | D10: 1 | E10: 1 | F10: 0 | G10: 0 | H10: 0 | I10: 0 | J10: 0 | K10: 0 | L10: =SUM(B10:K10)/10 -> 0.2 | M10: =IF(L10<0.31,"sukar",IF(L10<0.71,"sedang","mudah")) -> sukar | N10: =ABS((SUM(B10:E10)-SUM(F10:I10))*2/8) -> 0.5 | O10: =IF(N10<0.2,"soal dibuang",IF(N10<0.3,"soal diperbaiki",IF(N10<0.4,"soal diterima tapi perlu diperbaiki","soal diterima baik"))) -> soal diterima baik | Q10: 5 | R10: =B9 -> 1 | S10: =C9 -> 1 | T10: =D9 -> 1 | U10: =E9 -> 1 | V10: =F9 -> 0 | W10: =G9 -> 0 | X10: =H9 -> 0 | Y10: =I9 -> 0 | ... AA10: =K9 -> 1 | AB10: =SUM(R10:AA10)/COUNT(R10:AA10) -> 0.6 | AC10: =1-AB10 -> 0.4 | AD10: =AB10*AC10 -> 0.24
A11: 7. Auditor dapat menggunakan flowchart dalam melaksanakan kegiatan untuk … | B11: 1 | C11: 1 | D11: 1 | E11: 1 | F11: 1 | G11: 1 | H11: 0 | I11: 0 | J11: 0 | K11: 0 | L11: =SUM(B11:K11)/10 -> 0.6 | M11: =IF(L11<0.31,"sukar",IF(L11<0.71,"sedang","mudah")) -> sedang | N11: =ABS((SUM(B11:E11)-SUM(F11:I11))*2/8) -> 0.5 | O11: =IF(N11<0.2,"soal dibuang",IF(N11<0.3,"soal diperbaiki",IF(N11<0.4,"soal diterima tapi perlu diperbaiki","soal diterima baik"))) -> soal diterima baik | Q11: 6 | R11: =B10 -> 0 | S11: =C10 -> 0 | T11: =D10 -> 1 | U11: =E10 -> 1 | V11: =F10 -> 0 | W11: =G10 -> 0 | X11: =H10 -> 0 | Y11: =I10 -> 0 | ... AA11: =K10 -> 0 | AB11: =SUM(R11:AA11)/COUNT(R11:AA11) -> 0.2 | AC11: =1-AB11 -> 0.8 | AD11: =AB11*AC11 -> 0.16
A12: 8. Berikut merupakan komponen yang umum diidentifikasi pada diagram sebab akibat, kecuali … | B12: 1 | C12: 1 | D12: 1 | E12: 1 | F12: 0 | G12: 0 | H12: 1 | I12: 1 | J12: 0 | K12: 0 | L12: =SUM(B12:K12)/10 -> 0.6 | M12: =IF(L12<0.31,"sukar",IF(L12<0.71,"sedang","mudah")) -> sedang | N12: =ABS((SUM(B12:E12)-SUM(F12:I12))*2/8) -> 0.5 | O12: =IF(N12<0.2,"soal dibuang",IF(N12<0.3,"soal diperbaiki",IF(N12<0.4,"soal diterima tapi perlu diperbaiki","soal diterima baik"))) -> soal diterima baik | Q12: 7 | R12: =B11 -> 1 | S12: =C11 -> 1 | T12: =D11 -> 1 | U12: =E11 -> 1 | V12: =F11 -> 1 | W12: =G11 -> 1 | X12: =H11 -> 0 | Y12: =I11 -> 0 | ... AA12: =K11 -> 0 | AB12: =SUM(R12:AA12)/COUNT(R12:AA12) -> 0.6 | AC12: =1-AB12 -> 0.4 | AD12: =AB12*AC12 -> 0.24
A13: 9. Alat statisitik mana yang tergolong kualitatif? | B13: 1 | C13: 1 | D13: 1 | E13: 1 | F13: 1 | G13: 1 | H13: 0 | I13: 0 | J13: 0 | K13: 0 | L13: =SUM(B13:K13)/10 -> 0.6 | M13: =IF(L13<0.31,"sukar",IF(L13<0.71,"sedang","mudah")) -> sedang | N13: =ABS((SUM(B13:E13)-SUM(F13:I13))*2/8) -> 0.5 | O13: =IF(N13<0.2,"soal dibuang",IF(N13<0.3,"soal diperbaiki",IF(N13<0.4,"soal diterima tapi perlu diperbaiki","soal diterima baik"))) -> soal diterima baik | Q13: 8 | R13: =B12 -> 1 | S13: =C12 -> 1 | T13: =D12 -> 1 | U13: =E12 -> 1 | V13: =F12 -> 0 | W13: =G12 -> 0 | X13: =H12 -> 1 | Y13: =I12 -> 1 | ... AA13: =K12 -> 0 | AB13: =SUM(R13:AA13)/COUNT(R13:AA13) -> 0.6 | AC13: =1-AB13 -> 0.4 | AD13: =AB13*AC13 -> 0.24
A14: 10. Variasi dalam proses dibagi menjadi 2 yaitu, variasi umum dan variasi khusus. Variasi umum adalah … | B14: 1 | C14: 1 | D14: 1 | E14: 1 | F14: 0 | G14: 0 | H14: 1 | I14: 1 | J14: 0 | K14: 0 | L14: =SUM(B14:K14)/10 -> 0.6 | M14: =IF(L14<0.31,"sukar",IF(L14<0.71,"sedang","mudah")) -> sedang | N14: =ABS((SUM(B14:E14)-SUM(F14:I14))*2/8) -> 0.5 | O14: =IF(N14<0.2,"soal dibuang",IF(N14<0.3,"soal diperbaiki",IF(N14<0.4,"soal diterima tapi perlu diperbaiki","soal diterima baik"))) -> soal diterima baik | Q14: 9 | R14: =B13 -> 1 | S14: =C13 -> 1 | T14: =D13 -> 1 | U14: =E13 -> 1 | V14: =F13 -> 1 | W14: =G13 -> 1 | X14: =H13 -> 0 | Y14: =I13 -> 0 | ... AA14: =K13 -> 0 | AB14: =SUM(R14:AA14)/COUNT(R14:AA14) -> 0.6 | AC14: =1-AB14 -> 0.4 | AD14: =AB14*AC14 -> 0.24
A15: 11. Apa yang dimaksud dengan confidence level dalam sampling? | B15: 1 | C15: 1 | D15: 0 | E15: 0 | F15: 0 | G15: 0 | H15: 0 | I15: 0 | J15: 1 | K15: 1 | L15: =SUM(B15:K15)/10 -> 0.4 | M15: =IF(L15<0.31,"sukar",IF(L15<0.71,"sedang","mudah")) -> sedang | N15: =ABS((SUM(B15:E15)-SUM(F15:I15))*2/8) -> 0.5 | O15: =IF(N15<0.2,"soal dibuang",IF(N15<0.3,"soal diperbaiki",IF(N15<0.4,"soal diterima tapi perlu diperbaiki","soal diterima baik"))) -> soal diterima baik | Q15: 10 | R15: =B14 -> 1 | S15: =C14 -> 1 | T15: =D14 -> 1 | U15: =E14 -> 1 | V15: =F14 -> 0 | W15: =G14 -> 0 | X15: =H14 -> 1 | Y15: =I14 -> 1 | ... AA15: =K14 -> 0 | AB15: =SUM(R15:AA15)/COUNT(R15:AA15) -> 0.6 | AC15: =1-AB15 -> 0.4 | AD15: =AB15*AC15 -> 0.24
A16: 12. Jika pendamping audit untuk suatu area berulang kali terlambat atau tidak tersedia, pilihan terbaik apa yang tersedia bagi auditor? | B16: 1 | C16: 1 | D16: 1 | E16: 1 | F16: 0 | G16: 0 | H16: 1 | I16: 1 | J16: 1 | K16: 1 | L16: =SUM(B16:K16)/10 -> 0.8 | M16: =IF(L16<0.31,"sukar",IF(L16<0.71,"sedang","mudah")) -> mudah | N16: =ABS((SUM(B16:E16)-SUM(F16:I16))*2/8) -> 0.5 | O16: =IF(N16<0.2,"soal dibuang",IF(N16<0.3,"soal diperbaiki",IF(N16<0.4,"soal diterima tapi perlu diperbaiki","soal diterima baik"))) -> soal diterima baik | Q16: 11 | R16: =B15 -> 1 | S16: =C15 -> 1 | T16: =D15 -> 0 | U16: =E15 -> 0 | V16: =F15 -> 0 | W16: =G15 -> 0 | X16: =H15 -> 0 | Y16: =I15 -> 0 | ... AA16: =K15 -> 1 | AB16: =SUM(R16:AA16)/COUNT(R16:AA16) -> 0.4 | AC16: =1-AB16 -> 0.6 | AD16: =AB16*AC16 -> 0.24
A17: 13. Dalam pelaksanaan audit, auditor dapat menggunakan checklist sebagai alat bantu dalam pelaksanaan audit. Beberapa fungsi dari checklist audit adalah, kecuali … | B17: 1 | C17: 1 | D17: 1 | E17: 1 | F17: 0 | G17: 0 | H17: 1 | I17: 1 | J17: 0 | K17: 0 | L17: =SUM(B17:K17)/10 -> 0.6 | M17: =IF(L17<0.31,"sukar",IF(L17<0.71,"sedang","mudah")) -> sedang | N17: =ABS((SUM(B17:E17)-SUM(F17:I17))*2/8) -> 0.5 | O17: =IF(N17<0.2,"soal dibuang",IF(N17<0.3,"soal diperbaiki",IF(N17<0.4,"soal diterima tapi perlu diperbaiki","soal diterima baik"))) -> soal diterima baik | Q17: 12 | R17: =B16 -> 1 | S17: =C16 -> 1 | T17: =D16 -> 1 | U17: =E16 -> 1 | V17: =F16 -> 0 | W17: =G16 -> 0 | X17: =H16 -> 1 | Y17: =I16 -> 1 | ... AA17: =K16 -> 1 | AB17: =SUM(R17:AA17)/COUNT(R17:AA17) -> 0.8 | AC17: =1-AB17 -> 0.2 | AD17: =AB17*AC17 -> 0.16
... A104: 100. Analisis akar masalah / root cause analysis digunakan untuk … | B104: 1 | C104: 1 | D104: 1 | E104: 1 | F104: 0 | G104: 0 | H104: 1 | I104: 1 | J104: 1 | K104: 1 | L104: =SUM(B104:K104)/10 -> 0.8 | M104: =IF(L104<0.31,"sukar",IF(L104<0.71,"sedang","mudah")) -> mudah | N104: =ABS((SUM(B104:E104)-SUM(F104:I104))*2/8) -> 0.5 | O104: =IF(N104<0.2,"soal dibuang",IF(N104<0.3,"soal diperbaiki",IF(N104<0.4,"soal diterima tapi perlu diperbaiki","soal diterima baik"))) -> soal diterima baik | Q104: 99 | R104: =B103 -> 1 | S104: =C103 -> 1 | T104: =D103 -> 0 | U104: =E103 -> 0 | V104: =F103 -> 0 | W104: =G103 -> 0 | X104: =H103 -> 0 | Y104: =I103 -> 0 | ... AA104: =K103 -> 0 | AB104: =SUM(R104:AA104)/COUNT(R104:AA104) -> 0.2 | AC104: =1-AB104 -> 0.8 | AD104: =AB104*AC104 -> 0.16
B105: =SUM(B5:B104) -> 84 | C105: =SUM(C5:C104) -> 84 | D105: =SUM(D5:D104) -> 80 | E105: =SUM(E5:E104) -> 80 | F105: =SUM(F5:F104) -> 21 | G105: =SUM(G5:G104) -> 21 | H105: =SUM(H5:H104) -> 22 | I105: =SUM(I5:I104) -> 22 | ... K105: =SUM(K5:K104) -> 46 | O105: =COUNTIF(O5:O104,"soal dibuang") -> 0 | Q105: 100 | R105: =B104 -> 1 | S105: =C104 -> 1 | T105: =D104 -> 1 | U105: =E104 -> 1 | V105: =F104 -> 0 | W105: =G104 -> 0 | X105: =H104 -> 1 | Y105: =I104 -> 1 | ... AA105: =K104 -> 1 | AB105: =SUM(R105:AA105)/COUNT(R105:AA105) -> 0.8 | AC105: =1-AB105 -> 0.2 | AD105: =AB105*AC105 -> 0.16
B106: Bawah | C106: Bawah | D106: Bawah | E106: Bawah | F106: Atas | G106: Atas | H106: Atas | I106: Atas | J106: Atas | K106: Atas | M106: =COUNTIF(M5:M104,"mudah") -> 16 | Q106: Skor | R106: =SUM(R6:R105) -> 84 | S106: =SUM(S6:S105) -> 84 | T106: =SUM(T6:T105) -> 80 | U106: =SUM(U6:U105) -> 80 | V106: =SUM(V6:V105) -> 21 | W106: =SUM(W6:W105) -> 21 | X106: =SUM(X6:X105) -> 22 | Y106: =SUM(Y6:Y105) -> 22 | ... AA106: =SUM(AA6:AA105) -> 46 | AD106: =SUM(AD6:AD105) -> 21.36 | AE106: Total
M107: =COUNTIF(M5:M104,"sedang") -> 67 | Q107: Jumlah Skor | R107: =SUM(R106:AA106) -> 506
B108: Soal Mudah | E108: 40 | M108: =100-M106-M107 -> 17 | Q108: X bar | R108: =$R$107/10 -> 50.6 | S108: =$R$107/10 -> 50.6 | T108: =$R$107/10 -> 50.6 | U108: =$R$107/10 -> 50.6 | V108: =$R$107/10 -> 50.6 | W108: =$R$107/10 -> 50.6 | X108: =$R$107/10 -> 50.6 | Y108: =$R$107/10 -> 50.6 | ... AA108: =$R$107/10 -> 50.6
B109: Soal Sedang | E109: 30 | Q109: X-Xbar | R109: =R106-R108 -> 33.4 | S109: =S106-S108 -> 33.4 | T109: =T106-T108 -> 29.4 | U109: =U106-U108 -> 29.4 | V109: =V106-V108 -> -29.6 | W109: =W106-W108 -> -29.6 | X109: =X106-X108 -> -28.6 | Y109: =Y106-Y108 -> -28.6 | ... AA109: =AA106-AA108 -> -4.6
B110: Soal Sukar | E110: 30 | Q110: (X-Xbar)^2 | R110: =R109^2 -> 1115.56 | S110: =S109^2 -> 1115.56 | T110: =T109^2 -> 864.36 | U110: =U109^2 -> 864.36 | V110: =V109^2 -> 876.16 | W110: =W109^2 -> 876.16 | X110: =X109^2 -> 817.96 | Y110: =Y109^2 -> 817.96 | ... AA110: =AA109^2 -> 21.16
Q111: variance | R111: =SUM(R110:AA110)/10 -> 739.04
Q112: st dev | R112: =SQRT(R111) -> 27.18529
Q113: Reliabilitas | R113: =100/(100-1)*(1-AD106/R111) -> 0.98090671 | S113: Tinggi

Sheet DIF-Rasch-AIL
A1: UJI RASCH DIF (Pendekatan PROX) — Auditor Internal SPMI Terintegrasi ISO 21001:2018
A3: Ambang DIF (logit) - Moderat | B3: 0.5 | K3: Ringkasan Signifikansi Statistik (t-test) | Q3: Ringkasan Kesimpulan Praktis (Kontras)
A4: Ambang DIF (logit) - Besar | B4: 1 | L4: DIF Besar - review | O4: =COUNTIF($AA$11:$AA$110,"DIF Besar - review") -> 0 | Q4: Berpotensi Bias - Tinjau Konten | U4: =COUNTIF($AB$11:$AB$110,"Berpotensi Bias - Tinjau Konten") -> 0
A5: Ambang |t| minimum | B5: 2 | L5: DIF Moderat - cek | O5: =COUNTIF($AA$11:$AA$110,"DIF Moderat - cek") -> 0 | Q5: Indikasi Ringan - Pantau | U5: =COUNTIF($AB$11:$AB$110,"Indikasi Ringan - Pantau") -> 0
A6: Kontras DIF Maksimum (data ini) | B6: =_xlfn.AGGREGATE(14,6,ABS(X11:X110),1) -> 0 | L6: Negligible | O6: =COUNTIF($AA$11:$AA$110,"Negligible") -> 100 | Q6: Tidak Ada Indikasi Bias | U6: =COUNTIF($AB$11:$AB$110,"Tidak Ada Indikasi Bias") -> 100
K7: Keterangan: Tidak Ada Indikasi Bias artinya butir soal telah objektif, netral, serta adil tanpa terpengaruh pandangan pribadi maupun kepentingan kelompok
A8: Jenis Kelamin | B8: =AIL!B2 -> Perempuan | C8: =AIL!C2 -> Laki-Laki | D8: =AIL!D2 -> Perempuan | E8: =AIL!E2 -> Laki-Laki | F8: =AIL!F2 -> Perempuan | G8: =AIL!G2 -> Laki-Laki | H8: =AIL!H2 -> Perempuan | I8: =AIL!I2 -> Laki-Laki | ... K8: =AIL!K2 -> Laki-Laki
A9: Soal | B9: Asesi | L9: N (L) | M9: N (P) | N9: S (L) | O9: S (P) | P9: S adj (L) | Q9: S adj (P) | R9: β mentah (L) | S9: β mentah (P) | T9: β center (L) | U9: β center (P) | V9: SE (L) | W9: SE (P) | X9: Kontras DIF | Y9: SE Gabungan | Z9: t-stat | AA9: Klasifikasi DIF | AB9: Kesimpulan Praktis (Kontras)
B10: 1 | C10: 2 | D10: 3 | E10: 4 | F10: 5 | G10: 6 | H10: 7 | I10: 8 | J10: 9 | K10: 10
A11: =AIL!A5 -> 1. Hal-hal yang mempengaruhi cakupan program audit adalah … | B11: =AIL!B5 -> 1 | C11: =AIL!C5 -> 1 | D11: =AIL!D5 -> 1 | E11: =AIL!E5 -> 1 | F11: =AIL!F5 -> 1 | G11: =AIL!G5 -> 1 | H11: =AIL!H5 -> 0 | ... K11: =AIL!K5 -> 0 | L11: =COUNTIF($B$8:$K$8,"Laki-Laki") -> 5 | M11: =COUNTIF($B$8:$K$8,"Perempuan") -> 5 | N11: =SUMIF($B$8:$K$8,"Laki-Laki",B11:K11) -> 3 | O11: =SUMIF($B$8:$K$8,"Perempuan",B11:K11) -> 3 | P11: =IF(N11=0,0.3,IF(N11=L11,L11-0.3,N11)) -> 3 | Q11: =IF(O11=0,0.3,IF(O11=M11,M11-0.3,O11)) -> 3 | R11: =LN((L11-P11)/P11) -> -0.40546511 | S11: =LN((M11-Q11)/Q11) -> -0.40546511 | T11: =R11-AVERAGE($R$11:$R$110) -> -0.38283619 | U11: =S11-AVERAGE($S$11:$S$110) -> -0.38283619 | V11: =SQRT(1/P11+1/(L11-P11)) -> 0.91287093 | W11: =SQRT(1/Q11+1/(M11-Q11)) -> 0.91287093 | X11: =T11-U11 -> 0 | Y11: =SQRT(V11^2+W11^2) -> 1.2909944 | Z11: =X11/Y11 -> 0 | AA11: =IF(AND(ABS(X11)>=$B$4,ABS(Z11)>=$B$5),"DIF Besar - review",IF(AND(ABS(X11)>=$B$3,ABS(Z11)>=$B$5),"DIF Moderat - cek","Negligible")) -> Negligible | AB11: =IF(ABS(X11)>=$B$4,"Berpotensi Bias - Tinjau Konten",IF(ABS(X11)>=$B$3,"Indikasi Ringan - Pantau","Tidak Ada Indikasi Bias")) -> Tidak Ada Indikasi Bias
A12: =AIL!A6 -> 2. Manakah dari berikut ini yang merupakan manfaat terbesar dari program audit internal bagi suatu organisasi? | B12: =AIL!B6 -> 1 | C12: =AIL!C6 -> 1 | D12: =AIL!D6 -> 1 | E12: =AIL!E6 -> 1 | F12: =AIL!F6 -> 0 | G12: =AIL!G6 -> 0 | H12: =AIL!H6 -> 1 | ... K12: =AIL!K6 -> 0 | L12: =COUNTIF($B$8:$K$8,"Laki-Laki") -> 5 | M12: =COUNTIF($B$8:$K$8,"Perempuan") -> 5 | N12: =SUMIF($B$8:$K$8,"Laki-Laki",B12:K12) -> 3 | O12: =SUMIF($B$8:$K$8,"Perempuan",B12:K12) -> 3 | P12: =IF(N12=0,0.3,IF(N12=L12,L12-0.3,N12)) -> 3 | Q12: =IF(O12=0,0.3,IF(O12=M12,M12-0.3,O12)) -> 3 | R12: =LN((L12-P12)/P12) -> -0.40546511 | S12: =LN((M12-Q12)/Q12) -> -0.40546511 | T12: =R12-AVERAGE($R$11:$R$110) -> -0.38283619 | U12: =S12-AVERAGE($S$11:$S$110) -> -0.38283619 | V12: =SQRT(1/P12+1/(L12-P12)) -> 0.91287093 | W12: =SQRT(1/Q12+1/(M12-Q12)) -> 0.91287093 | X12: =T12-U12 -> 0 | Y12: =SQRT(V12^2+W12^2) -> 1.2909944 | Z12: =X12/Y12 -> 0 | AA12: =IF(AND(ABS(X12)>=$B$4,ABS(Z12)>=$B$5),"DIF Besar - review",IF(AND(ABS(X12)>=$B$3,ABS(Z12)>=$B$5),"DIF Moderat - cek","Negligible")) -> Negligible | AB12: =IF(ABS(X12)>=$B$4,"Berpotensi Bias - Tinjau Konten",IF(ABS(X12)>=$B$3,"Indikasi Ringan - Pantau","Tidak Ada Indikasi Bias")) -> Tidak Ada Indikasi Bias
A13: =AIL!A7 -> 3. Manakah dari berikut ini yang merupakan peran paling mendasar dari fungsi audit? | B13: =AIL!B7 -> 1 | C13: =AIL!C7 -> 1 | D13: =AIL!D7 -> 1 | E13: =AIL!E7 -> 1 | F13: =AIL!F7 -> 1 | G13: =AIL!G7 -> 1 | H13: =AIL!H7 -> 0 | ... K13: =AIL!K7 -> 1 | L13: =COUNTIF($B$8:$K$8,"Laki-Laki") -> 5 | M13: =COUNTIF($B$8:$K$8,"Perempuan") -> 5 | N13: =SUMIF($B$8:$K$8,"Laki-Laki",B13:K13) -> 4 | O13: =SUMIF($B$8:$K$8,"Perempuan",B13:K13) -> 4 | P13: =IF(N13=0,0.3,IF(N13=L13,L13-0.3,N13)) -> 4 | Q13: =IF(O13=0,0.3,IF(O13=M13,M13-0.3,O13)) -> 4 | R13: =LN((L13-P13)/P13) -> -1.3862944 | S13: =LN((M13-Q13)/Q13) -> -1.3862944 | T13: =R13-AVERAGE($R$11:$R$110) -> -1.3636654 | U13: =S13-AVERAGE($S$11:$S$110) -> -1.3636654 | V13: =SQRT(1/P13+1/(L13-P13)) -> 1.118034 | W13: =SQRT(1/Q13+1/(M13-Q13)) -> 1.118034 | X13: =T13-U13 -> 0 | Y13: =SQRT(V13^2+W13^2) -> 1.5811388 | Z13: =X13/Y13 -> 0 | AA13: =IF(AND(ABS(X13)>=$B$4,ABS(Z13)>=$B$5),"DIF Besar - review",IF(AND(ABS(X13)>=$B$3,ABS(Z13)>=$B$5),"DIF Moderat - cek","Negligible")) -> Negligible | AB13: =IF(ABS(X13)>=$B$4,"Berpotensi Bias - Tinjau Konten",IF(ABS(X13)>=$B$3,"Indikasi Ringan - Pantau","Tidak Ada Indikasi Bias")) -> Tidak Ada Indikasi Bias
A14: =AIL!A8 -> 4. Personal behavior yang diperlukan untuk menjadi auditor yang ideal, kecuali … | B14: =AIL!B8 -> 1 | C14: =AIL!C8 -> 1 | D14: =AIL!D8 -> 1 | E14: =AIL!E8 -> 1 | F14: =AIL!F8 -> 1 | G14: =AIL!G8 -> 1 | H14: =AIL!H8 -> 0 | ... K14: =AIL!K8 -> 1 | L14: =COUNTIF($B$8:$K$8,"Laki-Laki") -> 5 | M14: =COUNTIF($B$8:$K$8,"Perempuan") -> 5 | N14: =SUMIF($B$8:$K$8,"Laki-Laki",B14:K14) -> 4 | O14: =SUMIF($B$8:$K$8,"Perempuan",B14:K14) -> 4 | P14: =IF(N14=0,0.3,IF(N14=L14,L14-0.3,N14)) -> 4 | Q14: =IF(O14=0,0.3,IF(O14=M14,M14-0.3,O14)) -> 4 | R14: =LN((L14-P14)/P14) -> -1.3862944 | S14: =LN((M14-Q14)/Q14) -> -1.3862944 | T14: =R14-AVERAGE($R$11:$R$110) -> -1.3636654 | U14: =S14-AVERAGE($S$11:$S$110) -> -1.3636654 | V14: =SQRT(1/P14+1/(L14-P14)) -> 1.118034 | W14: =SQRT(1/Q14+1/(M14-Q14)) -> 1.118034 | X14: =T14-U14 -> 0 | Y14: =SQRT(V14^2+W14^2) -> 1.5811388 | Z14: =X14/Y14 -> 0 | AA14: =IF(AND(ABS(X14)>=$B$4,ABS(Z14)>=$B$5),"DIF Besar - review",IF(AND(ABS(X14)>=$B$3,ABS(Z14)>=$B$5),"DIF Moderat - cek","Negligible")) -> Negligible | AB14: =IF(ABS(X14)>=$B$4,"Berpotensi Bias - Tinjau Konten",IF(ABS(X14)>=$B$3,"Indikasi Ringan - Pantau","Tidak Ada Indikasi Bias")) -> Tidak Ada Indikasi Bias
A15: =AIL!A9 -> 5. Pengetahuan umum dan keahlian auditor mencakup, kecuali … | B15: =AIL!B9 -> 1 | C15: =AIL!C9 -> 1 | D15: =AIL!D9 -> 1 | E15: =AIL!E9 -> 1 | F15: =AIL!F9 -> 0 | G15: =AIL!G9 -> 0 | H15: =AIL!H9 -> 0 | ... K15: =AIL!K9 -> 1 | L15: =COUNTIF($B$8:$K$8,"Laki-Laki") -> 5 | M15: =COUNTIF($B$8:$K$8,"Perempuan") -> 5 | N15: =SUMIF($B$8:$K$8,"Laki-Laki",B15:K15) -> 3 | O15: =SUMIF($B$8:$K$8,"Perempuan",B15:K15) -> 3 | P15: =IF(N15=0,0.3,IF(N15=L15,L15-0.3,N15)) -> 3 | Q15: =IF(O15=0,0.3,IF(O15=M15,M15-0.3,O15)) -> 3 | R15: =LN((L15-P15)/P15) -> -0.40546511 | S15: =LN((M15-Q15)/Q15) -> -0.40546511 | T15: =R15-AVERAGE($R$11:$R$110) -> -0.38283619 | U15: =S15-AVERAGE($S$11:$S$110) -> -0.38283619 | V15: =SQRT(1/P15+1/(L15-P15)) -> 0.91287093 | W15: =SQRT(1/Q15+1/(M15-Q15)) -> 0.91287093 | X15: =T15-U15 -> 0 | Y15: =SQRT(V15^2+W15^2) -> 1.2909944 | Z15: =X15/Y15 -> 0 | AA15: =IF(AND(ABS(X15)>=$B$4,ABS(Z15)>=$B$5),"DIF Besar - review",IF(AND(ABS(X15)>=$B$3,ABS(Z15)>=$B$5),"DIF Moderat - cek","Negligible")) -> Negligible | AB15: =IF(ABS(X15)>=$B$4,"Berpotensi Bias - Tinjau Konten",IF(ABS(X15)>=$B$3,"Indikasi Ringan - Pantau","Tidak Ada Indikasi Bias")) -> Tidak Ada Indikasi Bias
A16: =AIL!A10 -> 6. Kriteria independen auditor mencakup kebebasan dari … | B16: =AIL!B10 -> 0 | C16: =AIL!C10 -> 0 | D16: =AIL!D10 -> 1 | E16: =AIL!E10 -> 1 | F16: =AIL!F10 -> 0 | G16: =AIL!G10 -> 0 | H16: =AIL!H10 -> 0 | ... K16: =AIL!K10 -> 0 | L16: =COUNTIF($B$8:$K$8,"Laki-Laki") -> 5 | M16: =COUNTIF($B$8:$K$8,"Perempuan") -> 5 | N16: =SUMIF($B$8:$K$8,"Laki-Laki",B16:K16) -> 1 | O16: =SUMIF($B$8:$K$8,"Perempuan",B16:K16) -> 1 | P16: =IF(N16=0,0.3,IF(N16=L16,L16-0.3,N16)) -> 1 | Q16: =IF(O16=0,0.3,IF(O16=M16,M16-0.3,O16)) -> 1 | R16: =LN((L16-P16)/P16) -> 1.3862944 | S16: =LN((M16-Q16)/Q16) -> 1.3862944 | T16: =R16-AVERAGE($R$11:$R$110) -> 1.4089233 | U16: =S16-AVERAGE($S$11:$S$110) -> 1.4089233 | V16: =SQRT(1/P16+1/(L16-P16)) -> 1.118034 | W16: =SQRT(1/Q16+1/(M16-Q16)) -> 1.118034 | X16: =T16-U16 -> 0 | Y16: =SQRT(V16^2+W16^2) -> 1.5811388 | Z16: =X16/Y16 -> 0 | AA16: =IF(AND(ABS(X16)>=$B$4,ABS(Z16)>=$B$5),"DIF Besar - review",IF(AND(ABS(X16)>=$B$3,ABS(Z16)>=$B$5),"DIF Moderat - cek","Negligible")) -> Negligible | AB16: =IF(ABS(X16)>=$B$4,"Berpotensi Bias - Tinjau Konten",IF(ABS(X16)>=$B$3,"Indikasi Ringan - Pantau","Tidak Ada Indikasi Bias")) -> Tidak Ada Indikasi Bias
A17: =AIL!A11 -> 7. Auditor dapat menggunakan flowchart dalam melaksanakan kegiatan untuk … | B17: =AIL!B11 -> 1 | C17: =AIL!C11 -> 1 | D17: =AIL!D11 -> 1 | E17: =AIL!E11 -> 1 | F17: =AIL!F11 -> 1 | G17: =AIL!G11 -> 1 | H17: =AIL!H11 -> 0 | ... K17: =AIL!K11 -> 0 | L17: =COUNTIF($B$8:$K$8,"Laki-Laki") -> 5 | M17: =COUNTIF($B$8:$K$8,"Perempuan") -> 5 | N17: =SUMIF($B$8:$K$8,"Laki-Laki",B17:K17) -> 3 | O17: =SUMIF($B$8:$K$8,"Perempuan",B17:K17) -> 3 | P17: =IF(N17=0,0.3,IF(N17=L17,L17-0.3,N17)) -> 3 | Q17: =IF(O17=0,0.3,IF(O17=M17,M17-0.3,O17)) -> 3 | R17: =LN((L17-P17)/P17) -> -0.40546511 | S17: =LN((M17-Q17)/Q17) -> -0.40546511 | T17: =R17-AVERAGE($R$11:$R$110) -> -0.38283619 | U17: =S17-AVERAGE($S$11:$S$110) -> -0.38283619 | V17: =SQRT(1/P17+1/(L17-P17)) -> 0.91287093 | W17: =SQRT(1/Q17+1/(M17-Q17)) -> 0.91287093 | X17: =T17-U17 -> 0 | Y17: =SQRT(V17^2+W17^2) -> 1.2909944 | Z17: =X17/Y17 -> 0 | AA17: =IF(AND(ABS(X17)>=$B$4,ABS(Z17)>=$B$5),"DIF Besar - review",IF(AND(ABS(X17)>=$B$3,ABS(Z17)>=$B$5),"DIF Moderat - cek","Negligible")) -> Negligible | AB17: =IF(ABS(X17)>=$B$4,"Berpotensi Bias - Tinjau Konten",IF(ABS(X17)>=$B$3,"Indikasi Ringan - Pantau","Tidak Ada Indikasi Bias")) -> Tidak Ada Indikasi Bias
A18: =AIL!A12 -> 8. Berikut merupakan komponen yang umum diidentifikasi pada diagram sebab akibat, kecuali … | B18: =AIL!B12 -> 1 | C18: =AIL!C12 -> 1 | D18: =AIL!D12 -> 1 | E18: =AIL!E12 -> 1 | F18: =AIL!F12 -> 0 | G18: =AIL!G12 -> 0 | H18: =AIL!H12 -> 1 | ... K18: =AIL!K12 -> 0 | L18: =COUNTIF($B$8:$K$8,"Laki-Laki") -> 5 | M18: =COUNTIF($B$8:$K$8,"Perempuan") -> 5 | N18: =SUMIF($B$8:$K$8,"Laki-Laki",B18:K18) -> 3 | O18: =SUMIF($B$8:$K$8,"Perempuan",B18:K18) -> 3 | P18: =IF(N18=0,0.3,IF(N18=L18,L18-0.3,N18)) -> 3 | Q18: =IF(O18=0,0.3,IF(O18=M18,M18-0.3,O18)) -> 3 | R18: =LN((L18-P18)/P18) -> -0.40546511 | S18: =LN((M18-Q18)/Q18) -> -0.40546511 | T18: =R18-AVERAGE($R$11:$R$110) -> -0.38283619 | U18: =S18-AVERAGE($S$11:$S$110) -> -0.38283619 | V18: =SQRT(1/P18+1/(L18-P18)) -> 0.91287093 | W18: =SQRT(1/Q18+1/(M18-Q18)) -> 0.91287093 | X18: =T18-U18 -> 0 | Y18: =SQRT(V18^2+W18^2) -> 1.2909944 | Z18: =X18/Y18 -> 0 | AA18: =IF(AND(ABS(X18)>=$B$4,ABS(Z18)>=$B$5),"DIF Besar - review",IF(AND(ABS(X18)>=$B$3,ABS(Z18)>=$B$5),"DIF Moderat - cek","Negligible")) -> Negligible | AB18: =IF(ABS(X18)>=$B$4,"Berpotensi Bias - Tinjau Konten",IF(ABS(X18)>=$B$3,"Indikasi Ringan - Pantau","Tidak Ada Indikasi Bias")) -> Tidak Ada Indikasi Bias
A19: =AIL!A13 -> 9. Alat statisitik mana yang tergolong kualitatif? | B19: =AIL!B13 -> 1 | C19: =AIL!C13 -> 1 | D19: =AIL!D13 -> 1 | E19: =AIL!E13 -> 1 | F19: =AIL!F13 -> 1 | G19: =AIL!G13 -> 1 | H19: =AIL!H13 -> 0 | ... K19: =AIL!K13 -> 0 | L19: =COUNTIF($B$8:$K$8,"Laki-Laki") -> 5 | M19: =COUNTIF($B$8:$K$8,"Perempuan") -> 5 | N19: =SUMIF($B$8:$K$8,"Laki-Laki",B19:K19) -> 3 | O19: =SUMIF($B$8:$K$8,"Perempuan",B19:K19) -> 3 | P19: =IF(N19=0,0.3,IF(N19=L19,L19-0.3,N19)) -> 3 | Q19: =IF(O19=0,0.3,IF(O19=M19,M19-0.3,O19)) -> 3 | R19: =LN((L19-P19)/P19) -> -0.40546511 | S19: =LN((M19-Q19)/Q19) -> -0.40546511 | T19: =R19-AVERAGE($R$11:$R$110) -> -0.38283619 | U19: =S19-AVERAGE($S$11:$S$110) -> -0.38283619 | V19: =SQRT(1/P19+1/(L19-P19)) -> 0.91287093 | W19: =SQRT(1/Q19+1/(M19-Q19)) -> 0.91287093 | X19: =T19-U19 -> 0 | Y19: =SQRT(V19^2+W19^2) -> 1.2909944 | Z19: =X19/Y19 -> 0 | AA19: =IF(AND(ABS(X19)>=$B$4,ABS(Z19)>=$B$5),"DIF Besar - review",IF(AND(ABS(X19)>=$B$3,ABS(Z19)>=$B$5),"DIF Moderat - cek","Negligible")) -> Negligible | AB19: =IF(ABS(X19)>=$B$4,"Berpotensi Bias - Tinjau Konten",IF(ABS(X19)>=$B$3,"Indikasi Ringan - Pantau","Tidak Ada Indikasi Bias")) -> Tidak Ada Indikasi Bias
A20: =AIL!A14 -> 10. Variasi dalam proses dibagi menjadi 2 yaitu, variasi umum dan variasi khusus. Variasi umum adalah … | B20: =AIL!B14 -> 1 | C20: =AIL!C14 -> 1 | D20: =AIL!D14 -> 1 | E20: =AIL!E14 -> 1 | F20: =AIL!F14 -> 0 | G20: =AIL!G14 -> 0 | H20: =AIL!H14 -> 1 | ... K20: =AIL!K14 -> 0 | L20: =COUNTIF($B$8:$K$8,"Laki-Laki") -> 5 | M20: =COUNTIF($B$8:$K$8,"Perempuan") -> 5 | N20: =SUMIF($B$8:$K$8,"Laki-Laki",B20:K20) -> 3 | O20: =SUMIF($B$8:$K$8,"Perempuan",B20:K20) -> 3 | P20: =IF(N20=0,0.3,IF(N20=L20,L20-0.3,N20)) -> 3 | Q20: =IF(O20=0,0.3,IF(O20=M20,M20-0.3,O20)) -> 3 | R20: =LN((L20-P20)/P20) -> -0.40546511 | S20: =LN((M20-Q20)/Q20) -> -0.40546511 | T20: =R20-AVERAGE($R$11:$R$110) -> -0.38283619 | U20: =S20-AVERAGE($S$11:$S$110) -> -0.38283619 | V20: =SQRT(1/P20+1/(L20-P20)) -> 0.91287093 | W20: =SQRT(1/Q20+1/(M20-Q20)) -> 0.91287093 | X20: =T20-U20 -> 0 | Y20: =SQRT(V20^2+W20^2) -> 1.2909944 | Z20: =X20/Y20 -> 0 | AA20: =IF(AND(ABS(X20)>=$B$4,ABS(Z20)>=$B$5),"DIF Besar - review",IF(AND(ABS(X20)>=$B$3,ABS(Z20)>=$B$5),"DIF Moderat - cek","Negligible")) -> Negligible | AB20: =IF(ABS(X20)>=$B$4,"Berpotensi Bias - Tinjau Konten",IF(ABS(X20)>=$B$3,"Indikasi Ringan - Pantau","Tidak Ada Indikasi Bias")) -> Tidak Ada Indikasi Bias
A21: =AIL!A15 -> 11. Apa yang dimaksud dengan confidence level dalam sampling? | B21: =AIL!B15 -> 1 | C21: =AIL!C15 -> 1 | D21: =AIL!D15 -> 0 | E21: =AIL!E15 -> 0 | F21: =AIL!F15 -> 0 | G21: =AIL!G15 -> 0 | H21: =AIL!H15 -> 0 | ... K21: =AIL!K15 -> 1 | L21: =COUNTIF($B$8:$K$8,"Laki-Laki") -> 5 | M21: =COUNTIF($B$8:$K$8,"Perempuan") -> 5 | N21: =SUMIF($B$8:$K$8,"Laki-Laki",B21:K21) -> 2 | O21: =SUMIF($B$8:$K$8,"Perempuan",B21:K21) -> 2 | P21: =IF(N21=0,0.3,IF(N21=L21,L21-0.3,N21)) -> 2 | Q21: =IF(O21=0,0.3,IF(O21=M21,M21-0.3,O21)) -> 2 | R21: =LN((L21-P21)/P21) -> 0.40546511 | S21: =LN((M21-Q21)/Q21) -> 0.40546511 | T21: =R21-AVERAGE($R$11:$R$110) -> 0.42809402 | U21: =S21-AVERAGE($S$11:$S$110) -> 0.42809402 | V21: =SQRT(1/P21+1/(L21-P21)) -> 0.91287093 | W21: =SQRT(1/Q21+1/(M21-Q21)) -> 0.91287093 | X21: =T21-U21 -> 0 | Y21: =SQRT(V21^2+W21^2) -> 1.2909944 | Z21: =X21/Y21 -> 0 | AA21: =IF(AND(ABS(X21)>=$B$4,ABS(Z21)>=$B$5),"DIF Besar - review",IF(AND(ABS(X21)>=$B$3,ABS(Z21)>=$B$5),"DIF Moderat - cek","Negligible")) -> Negligible | AB21: =IF(ABS(X21)>=$B$4,"Berpotensi Bias - Tinjau Konten",IF(ABS(X21)>=$B$3,"Indikasi Ringan - Pantau","Tidak Ada Indikasi Bias")) -> Tidak Ada Indikasi Bias
A22: =AIL!A16 -> 12. Jika pendamping audit untuk suatu area berulang kali terlambat atau tidak tersedia, pilihan terbaik apa yang tersedia bagi auditor? | B22: =AIL!B16 -> 1 | C22: =AIL!C16 -> 1 | D22: =AIL!D16 -> 1 | E22: =AIL!E16 -> 1 | F22: =AIL!F16 -> 0 | G22: =AIL!G16 -> 0 | H22: =AIL!H16 -> 1 | ... K22: =AIL!K16 -> 1 | L22: =COUNTIF($B$8:$K$8,"Laki-Laki") -> 5 | M22: =COUNTIF($B$8:$K$8,"Perempuan") -> 5 | N22: =SUMIF($B$8:$K$8,"Laki-Laki",B22:K22) -> 4 | O22: =SUMIF($B$8:$K$8,"Perempuan",B22:K22) -> 4 | P22: =IF(N22=0,0.3,IF(N22=L22,L22-0.3,N22)) -> 4 | Q22: =IF(O22=0,0.3,IF(O22=M22,M22-0.3,O22)) -> 4 | R22: =LN((L22-P22)/P22) -> -1.3862944 | S22: =LN((M22-Q22)/Q22) -> -1.3862944 | T22: =R22-AVERAGE($R$11:$R$110) -> -1.3636654 | U22: =S22-AVERAGE($S$11:$S$110) -> -1.3636654 | V22: =SQRT(1/P22+1/(L22-P22)) -> 1.118034 | W22: =SQRT(1/Q22+1/(M22-Q22)) -> 1.118034 | X22: =T22-U22 -> 0 | Y22: =SQRT(V22^2+W22^2) -> 1.5811388 | Z22: =X22/Y22 -> 0 | AA22: =IF(AND(ABS(X22)>=$B$4,ABS(Z22)>=$B$5),"DIF Besar - review",IF(AND(ABS(X22)>=$B$3,ABS(Z22)>=$B$5),"DIF Moderat - cek","Negligible")) -> Negligible | AB22: =IF(ABS(X22)>=$B$4,"Berpotensi Bias - Tinjau Konten",IF(ABS(X22)>=$B$3,"Indikasi Ringan - Pantau","Tidak Ada Indikasi Bias")) -> Tidak Ada Indikasi Bias
... A110: =AIL!A104 -> 100. Analisis akar masalah / root cause analysis digunakan untuk … | B110: =AIL!B104 -> 1 | C110: =AIL!C104 -> 1 | D110: =AIL!D104 -> 1 | E110: =AIL!E104 -> 1 | F110: =AIL!F104 -> 0 | G110: =AIL!G104 -> 0 | H110: =AIL!H104 -> 1 | ... K110: =AIL!K104 -> 1 | L110: =COUNTIF($B$8:$K$8,"Laki-Laki") -> 5 | M110: =COUNTIF($B$8:$K$8,"Perempuan") -> 5 | N110: =SUMIF($B$8:$K$8,"Laki-Laki",B110:K110) -> 4 | O110: =SUMIF($B$8:$K$8,"Perempuan",B110:K110) -> 4 | P110: =IF(N110=0,0.3,IF(N110=L110,L110-0.3,N110)) -> 4 | Q110: =IF(O110=0,0.3,IF(O110=M110,M110-0.3,O110)) -> 4 | R110: =LN((L110-P110)/P110) -> -1.3862944 | S110: =LN((M110-Q110)/Q110) -> -1.3862944 | T110: =R110-AVERAGE($R$11:$R$110) -> -1.3636654 | U110: =S110-AVERAGE($S$11:$S$110) -> -1.3636654 | V110: =SQRT(1/P110+1/(L110-P110)) -> 1.118034 | W110: =SQRT(1/Q110+1/(M110-Q110)) -> 1.118034 | X110: =T110-U110 -> 0 | Y110: =SQRT(V110^2+W110^2) -> 1.5811388 | Z110: =X110/Y110 -> 0 | AA110: =IF(AND(ABS(X110)>=$B$4,ABS(Z110)>=$B$5),"DIF Besar - review",IF(AND(ABS(X110)>=$B$3,ABS(Z110)>=$B$5),"DIF Moderat - cek","Negligible")) -> Negligible | AB110: =IF(ABS(X110)>=$B$4,"Berpotensi Bias - Tinjau Konten",IF(ABS(X110)>=$B$3,"Indikasi Ringan - Pantau","Tidak Ada Indikasi Bias")) -> Tidak Ada Indikasi Bias
B111: =SUM(B11:B110) -> 84 | C111: =SUM(C11:C110) -> 84 | D111: =SUM(D11:D110) -> 80 | E111: =SUM(E11:E110) -> 80 | F111: =SUM(F11:F110) -> 21 | G111: =SUM(G11:G110) -> 21 | H111: =SUM(H11:H110) -> 22 | I111: =SUM(I11:I110) -> 22 | ... K111: =SUM(K11:K110) -> 46

Sheet LAD
A1: UJI VALIDITAS DAN RELIABILITAS SKEMA LEAD AUDITOR SPMI TERINTEGRASI ISO 21001:2018
A2: Jenis Kelamin | B2: Perempuan | C2: Laki-Laki | D2: Perempuan | E2: Laki-Laki | F2: Perempuan | G2: Perempuan | H2: Laki-Laki | I2: Perempuan | J2: Laki-Laki | K2: Laki-Laki
A3: Soal | B3: Asesi | L3: Tingkat Kesukaran | M3: Keterangan | N3: Daya Pembeda | O3: Keterangan | Q3: Reliabilitas
B4: 1 | C4: 2 | D4: 3 | E4: 4 | F4: 5 | G4: 6 | H4: 7 | I4: 8 | J4: 9 | K4: 10 | Q4: Soal | R4: Asesi | AB4: p | AC4: 1-p | AD4: p*(1-p)
A5: 1. Hal-hal yang mempengaruhi cakupan program audit adalah … | B5: 0 | C5: 0 | D5: 1 | E5: 1 | F5: 1 | G5: 0 | H5: 1 | I5: 1 | J5: 1 | K5: 0 | L5: =SUM(B5:K5)/10 -> 0.6 | M5: =IF(L5<0.31,"sukar",IF(L5<0.71,"sedang","mudah")) -> sedang | N5: =ABS((SUM(B5:E5)-SUM(F5,H5:J5))*2/8) -> 0.5 | O5: =IF(N5<0.2,"soal dibuang",IF(N5<0.3,"soal diperbaiki",IF(N5<0.4,"soal diterima tapi perlu diperbaiki","soal diterima baik"))) -> soal diterima baik | R5: 1 | S5: 2 | T5: 3 | U5: 4 | V5: 5 | W5: 6 | X5: 7 | Y5: 8 | Z5: 9 | AA5: 10
A6: 2. Manakah dari berikut ini yang merupakan manfaat terbesar dari program audit internal bagi suatu organisasi? | B6: 1 | C6: 1 | D6: 1 | E6: 1 | F6: 0 | G6: 0 | H6: 0 | I6: 0 | J6: 0 | K6: 0 | L6: =SUM(B6:K6)/10 -> 0.4 | M6: =IF(L6<0.31,"sukar",IF(L6<0.71,"sedang","mudah")) -> sedang | N6: =ABS((SUM(B6:E6)-SUM(F6,H6:J6))*2/8) -> 1 | O6: =IF(N6<0.2,"soal dibuang",IF(N6<0.3,"soal diperbaiki",IF(N6<0.4,"soal diterima tapi perlu diperbaiki","soal diterima baik"))) -> soal diterima baik | Q6: 1 | R6: =B5 -> 0 | S6: =C5 -> 0 | T6: =D5 -> 1 | U6: =E5 -> 1 | V6: =F5 -> 1 | W6: =G5 -> 0 | X6: =H5 -> 1 | Y6: =I5 -> 1 | ... AA6: =K5 -> 0 | AB6: =SUM(R6:AA6)/COUNT(R6:AA6) -> 0.6 | AC6: =1-AB6 -> 0.4 | AD6: =AB6*AC6 -> 0.24
A7: 3. Manakah dari berikut ini yang merupakan peran paling mendasar dari fungsi audit? | B7: 1 | C7: 1 | D7: 1 | E7: 1 | F7: 0 | G7: 0 | H7: 0 | I7: 0 | J7: 0 | K7: 0 | L7: =SUM(B7:K7)/10 -> 0.4 | M7: =IF(L7<0.31,"sukar",IF(L7<0.71,"sedang","mudah")) -> sedang | N7: =ABS((SUM(B7:E7)-SUM(F7,H7:J7))*2/8) -> 1 | O7: =IF(N7<0.2,"soal dibuang",IF(N7<0.3,"soal diperbaiki",IF(N7<0.4,"soal diterima tapi perlu diperbaiki","soal diterima baik"))) -> soal diterima baik | Q7: 2 | R7: =B6 -> 1 | S7: =C6 -> 1 | T7: =D6 -> 1 | U7: =E6 -> 1 | V7: =F6 -> 0 | W7: =G6 -> 0 | X7: =H6 -> 0 | Y7: =I6 -> 0 | ... AA7: =K6 -> 0 | AB7: =SUM(R7:AA7)/COUNT(R7:AA7) -> 0.4 | AC7: =1-AB7 -> 0.6 | AD7: =AB7*AC7 -> 0.24
A8: 4. Personal behavior yang diperlukan untuk menjadi auditor yang ideal, kecuali … | B8: 1 | C8: 1 | D8: 0 | E8: 0 | F8: 0 | G8: 1 | H8: 0 | I8: 0 | J8: 0 | K8: 1 | L8: =SUM(B8:K8)/10 -> 0.4 | M8: =IF(L8<0.31,"sukar",IF(L8<0.71,"sedang","mudah")) -> sedang | N8: =ABS((SUM(B8:E8)-SUM(F8,H8:J8))*2/8) -> 0.5 | O8: =IF(N8<0.2,"soal dibuang",IF(N8<0.3,"soal diperbaiki",IF(N8<0.4,"soal diterima tapi perlu diperbaiki","soal diterima baik"))) -> soal diterima baik | Q8: 3 | R8: =B7 -> 1 | S8: =C7 -> 1 | T8: =D7 -> 1 | U8: =E7 -> 1 | V8: =F7 -> 0 | W8: =G7 -> 0 | X8: =H7 -> 0 | Y8: =I7 -> 0 | ... AA8: =K7 -> 0 | AB8: =SUM(R8:AA8)/COUNT(R8:AA8) -> 0.4 | AC8: =1-AB8 -> 0.6 | AD8: =AB8*AC8 -> 0.24
A9: 5. Pengetahuan umum dan keahlian auditor mencakup, kecuali … | B9: 1 | C9: 1 | D9: 0 | E9: 0 | F9: 0 | G9: 0 | H9: 0 | I9: 0 | J9: 0 | K9: 0 | L9: =SUM(B9:K9)/10 -> 0.2 | M9: =IF(L9<0.31,"sukar",IF(L9<0.71,"sedang","mudah")) -> sukar | N9: =ABS((SUM(B9:E9)-SUM(F9,H9:J9))*2/8) -> 0.5 | O9: =IF(N9<0.2,"soal dibuang",IF(N9<0.3,"soal diperbaiki",IF(N9<0.4,"soal diterima tapi perlu diperbaiki","soal diterima baik"))) -> soal diterima baik | Q9: 4 | R9: =B8 -> 1 | S9: =C8 -> 1 | T9: =D8 -> 0 | U9: =E8 -> 0 | V9: =F8 -> 0 | W9: =G8 -> 1 | X9: =H8 -> 0 | Y9: =I8 -> 0 | ... AA9: =K8 -> 1 | AB9: =SUM(R9:AA9)/COUNT(R9:AA9) -> 0.4 | AC9: =1-AB9 -> 0.6 | AD9: =AB9*AC9 -> 0.24
A10: 6. Kriteria independen auditor mencakup kebebasan dari … | B10: 1 | C10: 1 | D10: 0 | E10: 0 | F10: 0 | G10: 1 | H10: 0 | I10: 0 | J10: 0 | K10: 1 | L10: =SUM(B10:K10)/10 -> 0.4 | M10: =IF(L10<0.31,"sukar",IF(L10<0.71,"sedang","mudah")) -> sedang | N10: =ABS((SUM(B10:E10)-SUM(F10,H10:J10))*2/8) -> 0.5 | O10: =IF(N10<0.2,"soal dibuang",IF(N10<0.3,"soal diperbaiki",IF(N10<0.4,"soal diterima tapi perlu diperbaiki","soal diterima baik"))) -> soal diterima baik | Q10: 5 | R10: =B9 -> 1 | S10: =C9 -> 1 | T10: =D9 -> 0 | U10: =E9 -> 0 | V10: =F9 -> 0 | W10: =G9 -> 0 | X10: =H9 -> 0 | Y10: =I9 -> 0 | ... AA10: =K9 -> 0 | AB10: =SUM(R10:AA10)/COUNT(R10:AA10) -> 0.2 | AC10: =1-AB10 -> 0.8 | AD10: =AB10*AC10 -> 0.16
A11: 7. Auditor dapat menggunakan flowchart dalam melaksanakan kegiatan untuk … | B11: 1 | C11: 1 | D11: 1 | E11: 1 | F11: 0 | G11: 1 | H11: 0 | I11: 0 | J11: 0 | K11: 1 | L11: =SUM(B11:K11)/10 -> 0.6 | M11: =IF(L11<0.31,"sukar",IF(L11<0.71,"sedang","mudah")) -> sedang | N11: =ABS((SUM(B11:E11)-SUM(F11,H11:J11))*2/8) -> 1 | O11: =IF(N11<0.2,"soal dibuang",IF(N11<0.3,"soal diperbaiki",IF(N11<0.4,"soal diterima tapi perlu diperbaiki","soal diterima baik"))) -> soal diterima baik | Q11: 6 | R11: =B10 -> 1 | S11: =C10 -> 1 | T11: =D10 -> 0 | U11: =E10 -> 0 | V11: =F10 -> 0 | W11: =G10 -> 1 | X11: =H10 -> 0 | Y11: =I10 -> 0 | ... AA11: =K10 -> 1 | AB11: =SUM(R11:AA11)/COUNT(R11:AA11) -> 0.4 | AC11: =1-AB11 -> 0.6 | AD11: =AB11*AC11 -> 0.24
A12: 8. Berikut merupakan komponen yang umum diidentifikasi pada diagram sebab akibat, kecuali … | B12: 0 | C12: 0 | D12: 1 | E12: 1 | F12: 0 | G12: 1 | H12: 0 | I12: 0 | J12: 0 | K12: 1 | L12: =SUM(B12:K12)/10 -> 0.4 | M12: =IF(L12<0.31,"sukar",IF(L12<0.71,"sedang","mudah")) -> sedang | N12: =ABS((SUM(B12:E12)-SUM(F12,H12:J12))*2/8) -> 0.5 | O12: =IF(N12<0.2,"soal dibuang",IF(N12<0.3,"soal diperbaiki",IF(N12<0.4,"soal diterima tapi perlu diperbaiki","soal diterima baik"))) -> soal diterima baik | Q12: 7 | R12: =B11 -> 1 | S12: =C11 -> 1 | T12: =D11 -> 1 | U12: =E11 -> 1 | V12: =F11 -> 0 | W12: =G11 -> 1 | X12: =H11 -> 0 | Y12: =I11 -> 0 | ... AA12: =K11 -> 1 | AB12: =SUM(R12:AA12)/COUNT(R12:AA12) -> 0.6 | AC12: =1-AB12 -> 0.4 | AD12: =AB12*AC12 -> 0.24
A13: 9. Alat statisitik mana yang tergolong kualitatif? | B13: 1 | C13: 1 | D13: 1 | E13: 1 | F13: 0 | G13: 1 | H13: 0 | I13: 1 | J13: 1 | K13: 1 | L13: =SUM(B13:K13)/10 -> 0.8 | M13: =IF(L13<0.31,"sukar",IF(L13<0.71,"sedang","mudah")) -> mudah | N13: =ABS((SUM(B13:E13)-SUM(F13,H13:J13))*2/8) -> 0.5 | O13: =IF(N13<0.2,"soal dibuang",IF(N13<0.3,"soal diperbaiki",IF(N13<0.4,"soal diterima tapi perlu diperbaiki","soal diterima baik"))) -> soal diterima baik | Q13: 8 | R13: =B12 -> 0 | S13: =C12 -> 0 | T13: =D12 -> 1 | U13: =E12 -> 1 | V13: =F12 -> 0 | W13: =G12 -> 1 | X13: =H12 -> 0 | Y13: =I12 -> 0 | ... AA13: =K12 -> 1 | AB13: =SUM(R13:AA13)/COUNT(R13:AA13) -> 0.4 | AC13: =1-AB13 -> 0.6 | AD13: =AB13*AC13 -> 0.24
A14: 10. Variasi dalam proses dibagi menjadi 2 yaitu, variasi umum dan variasi khusus. Variasi umum adalah … | B14: 1 | C14: 1 | D14: 1 | E14: 1 | F14: 1 | G14: 0 | H14: 1 | I14: 0 | J14: 0 | K14: 0 | L14: =SUM(B14:K14)/10 -> 0.6 | M14: =IF(L14<0.31,"sukar",IF(L14<0.71,"sedang","mudah")) -> sedang | N14: =ABS((SUM(B14:E14)-SUM(F14,H14:J14))*2/8) -> 0.5 | O14: =IF(N14<0.2,"soal dibuang",IF(N14<0.3,"soal diperbaiki",IF(N14<0.4,"soal diterima tapi perlu diperbaiki","soal diterima baik"))) -> soal diterima baik | Q14: 9 | R14: =B13 -> 1 | S14: =C13 -> 1 | T14: =D13 -> 1 | U14: =E13 -> 1 | V14: =F13 -> 0 | W14: =G13 -> 1 | X14: =H13 -> 0 | Y14: =I13 -> 1 | ... AA14: =K13 -> 1 | AB14: =SUM(R14:AA14)/COUNT(R14:AA14) -> 0.8 | AC14: =1-AB14 -> 0.2 | AD14: =AB14*AC14 -> 0.16
A15: 11. Apa yang dimaksud dengan confidence level dalam sampling? | B15: 1 | C15: 1 | D15: 1 | E15: 1 | F15: 0 | G15: 0 | H15: 0 | I15: 0 | J15: 0 | K15: 0 | L15: =SUM(B15:K15)/10 -> 0.4 | M15: =IF(L15<0.31,"sukar",IF(L15<0.71,"sedang","mudah")) -> sedang | N15: =ABS((SUM(B15:E15)-SUM(F15,H15:J15))*2/8) -> 1 | O15: =IF(N15<0.2,"soal dibuang",IF(N15<0.3,"soal diperbaiki",IF(N15<0.4,"soal diterima tapi perlu diperbaiki","soal diterima baik"))) -> soal diterima baik | Q15: 10 | R15: =B14 -> 1 | S15: =C14 -> 1 | T15: =D14 -> 1 | U15: =E14 -> 1 | V15: =F14 -> 1 | W15: =G14 -> 0 | X15: =H14 -> 1 | Y15: =I14 -> 0 | ... AA15: =K14 -> 0 | AB15: =SUM(R15:AA15)/COUNT(R15:AA15) -> 0.6 | AC15: =1-AB15 -> 0.4 | AD15: =AB15*AC15 -> 0.24
A16: 12. Jika pendamping audit untuk suatu area berulang kali terlambat atau tidak tersedia, pilihan terbaik apa yang tersedia bagi auditor? | B16: 1 | C16: 1 | D16: 1 | E16: 1 | F16: 0 | G16: 1 | H16: 0 | I16: 0 | J16: 0 | K16: 1 | L16: =SUM(B16:K16)/10 -> 0.6 | M16: =IF(L16<0.31,"sukar",IF(L16<0.71,"sedang","mudah")) -> sedang | N16: =ABS((SUM(B16:E16)-SUM(F16,H16:J16))*2/8) -> 1 | O16: =IF(N16<0.2,"soal dibuang",IF(N16<0.3,"soal diperbaiki",IF(N16<0.4,"soal diterima tapi perlu diperbaiki","soal diterima baik"))) -> soal diterima baik | Q16: 11 | R16: =B15 -> 1 | S16: =C15 -> 1 | T16: =D15 -> 1 | U16: =E15 -> 1 | V16: =F15 -> 0 | W16: =G15 -> 0 | X16: =H15 -> 0 | Y16: =I15 -> 0 | ... AA16: =K15 -> 0 | AB16: =SUM(R16:AA16)/COUNT(R16:AA16) -> 0.4 | AC16: =1-AB16 -> 0.6 | AD16: =AB16*AC16 -> 0.24
A17: 13. Dalam pelaksanaan audit, auditor dapat menggunakan checklist sebagai alat bantu dalam pelaksanaan audit. Beberapa fungsi dari checklist audit adalah, kecuali … | B17: 1 | C17: 1 | D17: 1 | E17: 1 | F17: 0 | G17: 1 | H17: 0 | I17: 1 | J17: 1 | K17: 1 | L17: =SUM(B17:K17)/10 -> 0.8 | M17: =IF(L17<0.31,"sukar",IF(L17<0.71,"sedang","mudah")) -> mudah | N17: =ABS((SUM(B17:E17)-SUM(F17,H17:J17))*2/8) -> 0.5 | O17: =IF(N17<0.2,"soal dibuang",IF(N17<0.3,"soal diperbaiki",IF(N17<0.4,"soal diterima tapi perlu diperbaiki","soal diterima baik"))) -> soal diterima baik | Q17: 12 | R17: =B16 -> 1 | S17: =C16 -> 1 | T17: =D16 -> 1 | U17: =E16 -> 1 | V17: =F16 -> 0 | W17: =G16 -> 1 | X17: =H16 -> 0 | Y17: =I16 -> 0 | ... AA17: =K16 -> 1 | AB17: =SUM(R17:AA17)/COUNT(R17:AA17) -> 0.6 | AC17: =1-AB17 -> 0.4 | AD17: =AB17*AC17 -> 0.24
... A104: Dapat turut serta dalam kegiatan audit di bawah arahan dan bimbingan auditor | B104: 0 | C104: 0 | D104: 1 | E104: 1 | F104: 0 | G104: 1 | H104: 0 | I104: 0 | J104: 0 | K104: 1 | L104: =SUM(B104:K104)/10 -> 0.4 | M104: =IF(L104<0.31,"sukar",IF(L104<0.71,"sedang","mudah")) -> sedang | N104: =ABS((SUM(B104:E104)-SUM(F104,H104:J104))*2/8) -> 0.5 | O104: =IF(N104<0.2,"soal dibuang",IF(N104<0.3,"soal diperbaiki",IF(N104<0.4,"soal diterima tapi perlu diperbaiki","soal diterima baik"))) -> soal diterima baik | Q104: 99 | R104: =B103 -> 1 | S104: =C103 -> 1 | T104: =D103 -> 1 | U104: =E103 -> 1 | V104: =F103 -> 0 | W104: =G103 -> 1 | X104: =H103 -> 0 | Y104: =I103 -> 1 | ... AA104: =K103 -> 1 | AB104: =SUM(R104:AA104)/COUNT(R104:AA104) -> 0.8 | AC104: =1-AB104 -> 0.2 | AD104: =AB104*AC104 -> 0.16
B105: =SUM(B5:B104) -> 81 | C105: =SUM(C5:C104) -> 81 | D105: =SUM(D5:D104) -> 82 | E105: =SUM(E5:E104) -> 82 | F105: =SUM(F5:F104) -> 20 | G105: =SUM(G5:G104) -> 53 | H105: =SUM(H5:H104) -> 20 | I105: =SUM(I5:I104) -> 24 | ... K105: =SUM(K5:K104) -> 53 | O105: =COUNTIF(O5:O104,"soal dibuang") -> 0 | Q105: 100 | R105: =B104 -> 0 | S105: =C104 -> 0 | T105: =D104 -> 1 | U105: =E104 -> 1 | V105: =F104 -> 0 | W105: =G104 -> 1 | X105: =H104 -> 0 | Y105: =I104 -> 0 | ... AA105: =K104 -> 1 | AB105: =SUM(R105:AA105)/COUNT(R105:AA105) -> 0.4 | AC105: =1-AB105 -> 0.6 | AD105: =AB105*AC105 -> 0.24
B106: Bawah | C106: Bawah | D106: Bawah | E106: Bawah | F106: Bawah | G106: Atas | H106: Atas | I106: Atas | J106: Atas | K106: Atas | M106: =COUNTIF(M5:M104,"mudah") -> 18 | Q106: Skor | R106: =SUM(R6:R105) -> 81 | S106: =SUM(S6:S105) -> 81 | T106: =SUM(T6:T105) -> 82 | U106: =SUM(U6:U105) -> 82 | V106: =SUM(V6:V105) -> 20 | W106: =SUM(W6:W105) -> 53 | X106: =SUM(X6:X105) -> 20 | Y106: =SUM(Y6:Y105) -> 24 | ... AA106: =SUM(AA6:AA105) -> 53 | AD106: =SUM(AD6:AD105) -> 21.76 | AE106: Total
M107: =COUNTIF(M5:M104,"sedang") -> 72 | Q107: Jumlah Skor | R107: =SUM(R106:AA106) -> 520
B108: Soal Mudah | E108: 40 | M108: =100-M106-M107 -> 10 | Q108: X bar | R108: =$R$107/10 -> 52 | S108: =$R$108/10 -> 5.2 | T108: =$R$108/10 -> 5.2 | U108: =$R$108/10 -> 5.2 | V108: =$R$108/10 -> 5.2 | W108: =$R$108/10 -> 5.2 | X108: =$R$107/10 -> 52 | Y108: =$R$108/10 -> 5.2 | Z108: =$R$108/10 -> 5.2 | AA108: =$R$108/10 -> 5.2
B109: Soal Sedang | E109: 30 | Q109: X-Xbar | R109: =R106-R108 -> 29 | S109: =S106-S108 -> 75.8 | T109: =T106-T108 -> 76.8 | U109: =U106-U108 -> 76.8 | V109: =V106-V108 -> 14.8 | W109: =W106-W108 -> 47.8 | X109: =X106-X108 -> -32 | Y109: =Y106-Y108 -> 18.8 | ... AA109: =AA106-AA108 -> 47.8
B110: Soal Sukar | E110: 30 | Q110: (X-Xbar)^2 | R110: =R109^2 -> 841 | S110: =S109^2 -> 5745.64 | T110: =T109^2 -> 5898.24 | U110: =U109^2 -> 5898.24 | V110: =V109^2 -> 219.04 | W110: =W109^2 -> 2284.84 | X110: =X109^2 -> 1024 | Y110: =Y109^2 -> 353.44 | ... AA110: =AA109^2 -> 2284.84
Q111: variance | R111: =SUM(R110:AA110)/10 -> 2490.272
Q112: st dev | R112: =SQRT(R111) -> 49.902625
Q113: Reliabilitas | R113: =100/(100-1)*(1-AD106/R111) -> 1.0012747 | S113: Tinggi

Sheet DIF-Rasch- LAD
A1: UJI RASCH DIF (Pendekatan PROX) — Skema Lead Auditor SPMI Terintegrasi ISO 21001:2018
A3: Ambang DIF (logit) - Moderat | B3: 0.5 | J3: Ringkasan Signifikansi Statistik (t-test) | P3: Ringkasan Kesimpulan Praktis (Kontras)
A4: Ambang DIF (logit) - Besar | B4: 1 | K4: DIF Besar - review | N4: =COUNTIF($AA$11:$AA$110,"DIF Besar - review") -> 0 | P4: Berpotensi Bias - Tinjau Konten | T4: =COUNTIF($AB$11:$AB$110,"Berpotensi Bias - Tinjau Konten") -> 0
A5: Ambang |t| minimum | B5: 2 | K5: DIF Moderat - cek | N5: =COUNTIF($AA$11:$AA$110,"DIF Moderat - cek") -> 0 | P5: Indikasi Ringan - Pantau | T5: =COUNTIF($AB$11:$AB$110,"Indikasi Ringan - Pantau") -> 0
A6: Kontras DIF Maksimum (data ini) | B6: =_xlfn.AGGREGATE(14,6,ABS(X11:X110),1) -> 0 | K6: Negligible | N6: =COUNTIF($AA$11:$AA$110,"Negligible") -> 100 | P6: Tidak Ada Indikasi Bias | T6: =COUNTIF($AB$11:$AB$110,"Tidak Ada Indikasi Bias") -> 100
J7: Keterangan: Tidak Ada Indikasi Bias artinya butir soal telah objektif, netral, serta adil tanpa terpengaruh pandangan pribadi maupun kepentingan kelompok
A8: Jenis Kelamin | B8: =LAD!B2 -> Perempuan | C8: =LAD!C2 -> Laki-Laki | D8: =LAD!D2 -> Perempuan | E8: =LAD!E2 -> Laki-Laki | F8: =LAD!F2 -> Perempuan | G8: =LAD!G2 -> Perempuan | H8: =LAD!H2 -> Laki-Laki | I8: =LAD!I2 -> Perempuan | ... K8: =LAD!K2 -> Laki-Laki
A9: Soal | B9: Asesi | L9: N (L) | M9: N (P) | N9: S (L) | O9: S (P) | P9: S adj (L) | Q9: S adj (P) | R9: β mentah (L) | S9: β mentah (P) | T9: β center (L) | U9: β center (P) | V9: SE (L) | W9: SE (P) | X9: Kontras DIF | Y9: SE Gabungan | Z9: t-stat | AA9: Klasifikasi DIF | AB9: Kesimpulan Praktis (Kontras)
B10: 1 | C10: 2 | D10: 3 | E10: 4 | F10: 5 | G10: 6 | H10: 7 | I10: 8 | J10: 9 | K10: 10
A11: =LAD!A5 -> 1. Hal-hal yang mempengaruhi cakupan program audit adalah … | B11: =LAD!B5 -> 0 | C11: =LAD!C5 -> 0 | D11: =LAD!D5 -> 1 | E11: =LAD!E5 -> 1 | F11: =LAD!F5 -> 1 | G11: =LAD!G5 -> 0 | H11: =LAD!H5 -> 1 | ... K11: =LAD!K5 -> 0 | L11: =COUNTIF($B$8:$K$8,"Laki-Laki") -> 5 | M11: =COUNTIF($B$8:$K$8,"Perempuan") -> 5 | N11: =SUMIF($B$8:$K$8,"Laki-Laki",B11:K11) -> 3 | O11: =SUMIF($B$8:$K$8,"Perempuan",B11:K11) -> 3 | P11: =IF(N11=0,0.3,IF(N11=L11,L11-0.3,N11)) -> 3 | Q11: =IF(O11=0,0.3,IF(O11=M11,M11-0.3,O11)) -> 3 | R11: =LN((L11-P11)/P11) -> -0.40546511 | S11: =LN((M11-Q11)/Q11) -> -0.40546511 | T11: =R11-AVERAGE($R$11:$R$110) -> -0.31078016 | U11: =S11-AVERAGE($S$11:$S$110) -> -0.31078016 | V11: =SQRT(1/P11+1/(L11-P11)) -> 0.91287093 | W11: =SQRT(1/Q11+1/(M11-Q11)) -> 0.91287093 | X11: =T11-U11 -> 0 | Y11: =SQRT(V11^2+W11^2) -> 1.2909944 | Z11: =X11/Y11 -> 0 | AA11: =IF(AND(ABS(X11)>=$B$4,ABS(Z11)>=$B$5),"DIF Besar - review",IF(AND(ABS(X11)>=$B$3,ABS(Z11)>=$B$5),"DIF Moderat - cek","Negligible")) -> Negligible | AB11: =IF(ABS(X11)>=$B$4,"Berpotensi Bias - Tinjau Konten",IF(ABS(X11)>=$B$3,"Indikasi Ringan - Pantau","Tidak Ada Indikasi Bias")) -> Tidak Ada Indikasi Bias
A12: =LAD!A6 -> 2. Manakah dari berikut ini yang merupakan manfaat terbesar dari program audit internal bagi suatu organisasi? | B12: =LAD!B6 -> 1 | C12: =LAD!C6 -> 1 | D12: =LAD!D6 -> 1 | E12: =LAD!E6 -> 1 | F12: =LAD!F6 -> 0 | G12: =LAD!G6 -> 0 | H12: =LAD!H6 -> 0 | ... K12: =LAD!K6 -> 0 | L12: =COUNTIF($B$8:$K$8,"Laki-Laki") -> 5 | M12: =COUNTIF($B$8:$K$8,"Perempuan") -> 5 | N12: =SUMIF($B$8:$K$8,"Laki-Laki",B12:K12) -> 2 | O12: =SUMIF($B$8:$K$8,"Perempuan",B12:K12) -> 2 | P12: =IF(N12=0,0.3,IF(N12=L12,L12-0.3,N12)) -> 2 | Q12: =IF(O12=0,0.3,IF(O12=M12,M12-0.3,O12)) -> 2 | R12: =LN((L12-P12)/P12) -> 0.40546511 | S12: =LN((M12-Q12)/Q12) -> 0.40546511 | T12: =R12-AVERAGE($R$11:$R$110) -> 0.50015005 | U12: =S12-AVERAGE($S$11:$S$110) -> 0.50015005 | V12: =SQRT(1/P12+1/(L12-P12)) -> 0.91287093 | W12: =SQRT(1/Q12+1/(M12-Q12)) -> 0.91287093 | X12: =T12-U12 -> 0 | Y12: =SQRT(V12^2+W12^2) -> 1.2909944 | Z12: =X12/Y12 -> 0 | AA12: =IF(AND(ABS(X12)>=$B$4,ABS(Z12)>=$B$5),"DIF Besar - review",IF(AND(ABS(X12)>=$B$3,ABS(Z12)>=$B$5),"DIF Moderat - cek","Negligible")) -> Negligible | AB12: =IF(ABS(X12)>=$B$4,"Berpotensi Bias - Tinjau Konten",IF(ABS(X12)>=$B$3,"Indikasi Ringan - Pantau","Tidak Ada Indikasi Bias")) -> Tidak Ada Indikasi Bias
A13: =LAD!A7 -> 3. Manakah dari berikut ini yang merupakan peran paling mendasar dari fungsi audit? | B13: =LAD!B7 -> 1 | C13: =LAD!C7 -> 1 | D13: =LAD!D7 -> 1 | E13: =LAD!E7 -> 1 | F13: =LAD!F7 -> 0 | G13: =LAD!G7 -> 0 | H13: =LAD!H7 -> 0 | ... K13: =LAD!K7 -> 0 | L13: =COUNTIF($B$8:$K$8,"Laki-Laki") -> 5 | M13: =COUNTIF($B$8:$K$8,"Perempuan") -> 5 | N13: =SUMIF($B$8:$K$8,"Laki-Laki",B13:K13) -> 2 | O13: =SUMIF($B$8:$K$8,"Perempuan",B13:K13) -> 2 | P13: =IF(N13=0,0.3,IF(N13=L13,L13-0.3,N13)) -> 2 | Q13: =IF(O13=0,0.3,IF(O13=M13,M13-0.3,O13)) -> 2 | R13: =LN((L13-P13)/P13) -> 0.40546511 | S13: =LN((M13-Q13)/Q13) -> 0.40546511 | T13: =R13-AVERAGE($R$11:$R$110) -> 0.50015005 | U13: =S13-AVERAGE($S$11:$S$110) -> 0.50015005 | V13: =SQRT(1/P13+1/(L13-P13)) -> 0.91287093 | W13: =SQRT(1/Q13+1/(M13-Q13)) -> 0.91287093 | X13: =T13-U13 -> 0 | Y13: =SQRT(V13^2+W13^2) -> 1.2909944 | Z13: =X13/Y13 -> 0 | AA13: =IF(AND(ABS(X13)>=$B$4,ABS(Z13)>=$B$5),"DIF Besar - review",IF(AND(ABS(X13)>=$B$3,ABS(Z13)>=$B$5),"DIF Moderat - cek","Negligible")) -> Negligible | AB13: =IF(ABS(X13)>=$B$4,"Berpotensi Bias - Tinjau Konten",IF(ABS(X13)>=$B$3,"Indikasi Ringan - Pantau","Tidak Ada Indikasi Bias")) -> Tidak Ada Indikasi Bias
A14: =LAD!A8 -> 4. Personal behavior yang diperlukan untuk menjadi auditor yang ideal, kecuali … | B14: =LAD!B8 -> 1 | C14: =LAD!C8 -> 1 | D14: =LAD!D8 -> 0 | E14: =LAD!E8 -> 0 | F14: =LAD!F8 -> 0 | G14: =LAD!G8 -> 1 | H14: =LAD!H8 -> 0 | ... K14: =LAD!K8 -> 1 | L14: =COUNTIF($B$8:$K$8,"Laki-Laki") -> 5 | M14: =COUNTIF($B$8:$K$8,"Perempuan") -> 5 | N14: =SUMIF($B$8:$K$8,"Laki-Laki",B14:K14) -> 2 | O14: =SUMIF($B$8:$K$8,"Perempuan",B14:K14) -> 2 | P14: =IF(N14=0,0.3,IF(N14=L14,L14-0.3,N14)) -> 2 | Q14: =IF(O14=0,0.3,IF(O14=M14,M14-0.3,O14)) -> 2 | R14: =LN((L14-P14)/P14) -> 0.40546511 | S14: =LN((M14-Q14)/Q14) -> 0.40546511 | T14: =R14-AVERAGE($R$11:$R$110) -> 0.50015005 | U14: =S14-AVERAGE($S$11:$S$110) -> 0.50015005 | V14: =SQRT(1/P14+1/(L14-P14)) -> 0.91287093 | W14: =SQRT(1/Q14+1/(M14-Q14)) -> 0.91287093 | X14: =T14-U14 -> 0 | Y14: =SQRT(V14^2+W14^2) -> 1.2909944 | Z14: =X14/Y14 -> 0 | AA14: =IF(AND(ABS(X14)>=$B$4,ABS(Z14)>=$B$5),"DIF Besar - review",IF(AND(ABS(X14)>=$B$3,ABS(Z14)>=$B$5),"DIF Moderat - cek","Negligible")) -> Negligible | AB14: =IF(ABS(X14)>=$B$4,"Berpotensi Bias - Tinjau Konten",IF(ABS(X14)>=$B$3,"Indikasi Ringan - Pantau","Tidak Ada Indikasi Bias")) -> Tidak Ada Indikasi Bias
A15: =LAD!A9 -> 5. Pengetahuan umum dan keahlian auditor mencakup, kecuali … | B15: =LAD!B9 -> 1 | C15: =LAD!C9 -> 1 | D15: =LAD!D9 -> 0 | E15: =LAD!E9 -> 0 | F15: =LAD!F9 -> 0 | G15: =LAD!G9 -> 0 | H15: =LAD!H9 -> 0 | ... K15: =LAD!K9 -> 0 | L15: =COUNTIF($B$8:$K$8,"Laki-Laki") -> 5 | M15: =COUNTIF($B$8:$K$8,"Perempuan") -> 5 | N15: =SUMIF($B$8:$K$8,"Laki-Laki",B15:K15) -> 1 | O15: =SUMIF($B$8:$K$8,"Perempuan",B15:K15) -> 1 | P15: =IF(N15=0,0.3,IF(N15=L15,L15-0.3,N15)) -> 1 | Q15: =IF(O15=0,0.3,IF(O15=M15,M15-0.3,O15)) -> 1 | R15: =LN((L15-P15)/P15) -> 1.3862944 | S15: =LN((M15-Q15)/Q15) -> 1.3862944 | T15: =R15-AVERAGE($R$11:$R$110) -> 1.4809793 | U15: =S15-AVERAGE($S$11:$S$110) -> 1.4809793 | V15: =SQRT(1/P15+1/(L15-P15)) -> 1.118034 | W15: =SQRT(1/Q15+1/(M15-Q15)) -> 1.118034 | X15: =T15-U15 -> 0 | Y15: =SQRT(V15^2+W15^2) -> 1.5811388 | Z15: =X15/Y15 -> 0 | AA15: =IF(AND(ABS(X15)>=$B$4,ABS(Z15)>=$B$5),"DIF Besar - review",IF(AND(ABS(X15)>=$B$3,ABS(Z15)>=$B$5),"DIF Moderat - cek","Negligible")) -> Negligible | AB15: =IF(ABS(X15)>=$B$4,"Berpotensi Bias - Tinjau Konten",IF(ABS(X15)>=$B$3,"Indikasi Ringan - Pantau","Tidak Ada Indikasi Bias")) -> Tidak Ada Indikasi Bias
A16: =LAD!A10 -> 6. Kriteria independen auditor mencakup kebebasan dari … | B16: =LAD!B10 -> 1 | C16: =LAD!C10 -> 1 | D16: =LAD!D10 -> 0 | E16: =LAD!E10 -> 0 | F16: =LAD!F10 -> 0 | G16: =LAD!G10 -> 1 | H16: =LAD!H10 -> 0 | ... K16: =LAD!K10 -> 1 | L16: =COUNTIF($B$8:$K$8,"Laki-Laki") -> 5 | M16: =COUNTIF($B$8:$K$8,"Perempuan") -> 5 | N16: =SUMIF($B$8:$K$8,"Laki-Laki",B16:K16) -> 2 | O16: =SUMIF($B$8:$K$8,"Perempuan",B16:K16) -> 2 | P16: =IF(N16=0,0.3,IF(N16=L16,L16-0.3,N16)) -> 2 | Q16: =IF(O16=0,0.3,IF(O16=M16,M16-0.3,O16)) -> 2 | R16: =LN((L16-P16)/P16) -> 0.40546511 | S16: =LN((M16-Q16)/Q16) -> 0.40546511 | T16: =R16-AVERAGE($R$11:$R$110) -> 0.50015005 | U16: =S16-AVERAGE($S$11:$S$110) -> 0.50015005 | V16: =SQRT(1/P16+1/(L16-P16)) -> 0.91287093 | W16: =SQRT(1/Q16+1/(M16-Q16)) -> 0.91287093 | X16: =T16-U16 -> 0 | Y16: =SQRT(V16^2+W16^2) -> 1.2909944 | Z16: =X16/Y16 -> 0 | AA16: =IF(AND(ABS(X16)>=$B$4,ABS(Z16)>=$B$5),"DIF Besar - review",IF(AND(ABS(X16)>=$B$3,ABS(Z16)>=$B$5),"DIF Moderat - cek","Negligible")) -> Negligible | AB16: =IF(ABS(X16)>=$B$4,"Berpotensi Bias - Tinjau Konten",IF(ABS(X16)>=$B$3,"Indikasi Ringan - Pantau","Tidak Ada Indikasi Bias")) -> Tidak Ada Indikasi Bias
A17: =LAD!A11 -> 7. Auditor dapat menggunakan flowchart dalam melaksanakan kegiatan untuk … | B17: =LAD!B11 -> 1 | C17: =LAD!C11 -> 1 | D17: =LAD!D11 -> 1 | E17: =LAD!E11 -> 1 | F17: =LAD!F11 -> 0 | G17: =LAD!G11 -> 1 | H17: =LAD!H11 -> 0 | ... K17: =LAD!K11 -> 1 | L17: =COUNTIF($B$8:$K$8,"Laki-Laki") -> 5 | M17: =COUNTIF($B$8:$K$8,"Perempuan") -> 5 | N17: =SUMIF($B$8:$K$8,"Laki-Laki",B17:K17) -> 3 | O17: =SUMIF($B$8:$K$8,"Perempuan",B17:K17) -> 3 | P17: =IF(N17=0,0.3,IF(N17=L17,L17-0.3,N17)) -> 3 | Q17: =IF(O17=0,0.3,IF(O17=M17,M17-0.3,O17)) -> 3 | R17: =LN((L17-P17)/P17) -> -0.40546511 | S17: =LN((M17-Q17)/Q17) -> -0.40546511 | T17: =R17-AVERAGE($R$11:$R$110) -> -0.31078016 | U17: =S17-AVERAGE($S$11:$S$110) -> -0.31078016 | V17: =SQRT(1/P17+1/(L17-P17)) -> 0.91287093 | W17: =SQRT(1/Q17+1/(M17-Q17)) -> 0.91287093 | X17: =T17-U17 -> 0 | Y17: =SQRT(V17^2+W17^2) -> 1.2909944 | Z17: =X17/Y17 -> 0 | AA17: =IF(AND(ABS(X17)>=$B$4,ABS(Z17)>=$B$5),"DIF Besar - review",IF(AND(ABS(X17)>=$B$3,ABS(Z17)>=$B$5),"DIF Moderat - cek","Negligible")) -> Negligible | AB17: =IF(ABS(X17)>=$B$4,"Berpotensi Bias - Tinjau Konten",IF(ABS(X17)>=$B$3,"Indikasi Ringan - Pantau","Tidak Ada Indikasi Bias")) -> Tidak Ada Indikasi Bias
A18: =LAD!A12 -> 8. Berikut merupakan komponen yang umum diidentifikasi pada diagram sebab akibat, kecuali … | B18: =LAD!B12 -> 0 | C18: =LAD!C12 -> 0 | D18: =LAD!D12 -> 1 | E18: =LAD!E12 -> 1 | F18: =LAD!F12 -> 0 | G18: =LAD!G12 -> 1 | H18: =LAD!H12 -> 0 | ... K18: =LAD!K12 -> 1 | L18: =COUNTIF($B$8:$K$8,"Laki-Laki") -> 5 | M18: =COUNTIF($B$8:$K$8,"Perempuan") -> 5 | N18: =SUMIF($B$8:$K$8,"Laki-Laki",B18:K18) -> 2 | O18: =SUMIF($B$8:$K$8,"Perempuan",B18:K18) -> 2 | P18: =IF(N18=0,0.3,IF(N18=L18,L18-0.3,N18)) -> 2 | Q18: =IF(O18=0,0.3,IF(O18=M18,M18-0.3,O18)) -> 2 | R18: =LN((L18-P18)/P18) -> 0.40546511 | S18: =LN((M18-Q18)/Q18) -> 0.40546511 | T18: =R18-AVERAGE($R$11:$R$110) -> 0.50015005 | U18: =S18-AVERAGE($S$11:$S$110) -> 0.50015005 | V18: =SQRT(1/P18+1/(L18-P18)) -> 0.91287093 | W18: =SQRT(1/Q18+1/(M18-Q18)) -> 0.91287093 | X18: =T18-U18 -> 0 | Y18: =SQRT(V18^2+W18^2) -> 1.2909944 | Z18: =X18/Y18 -> 0 | AA18: =IF(AND(ABS(X18)>=$B$4,ABS(Z18)>=$B$5),"DIF Besar - review",IF(AND(ABS(X18)>=$B$3,ABS(Z18)>=$B$5),"DIF Moderat - cek","Negligible")) -> Negligible | AB18: =IF(ABS(X18)>=$B$4,"Berpotensi Bias - Tinjau Konten",IF(ABS(X18)>=$B$3,"Indikasi Ringan - Pantau","Tidak Ada Indikasi Bias")) -> Tidak Ada Indikasi Bias
A19: =LAD!A13 -> 9. Alat statisitik mana yang tergolong kualitatif? | B19: =LAD!B13 -> 1 | C19: =LAD!C13 -> 1 | D19: =LAD!D13 -> 1 | E19: =LAD!E13 -> 1 | F19: =LAD!F13 -> 0 | G19: =LAD!G13 -> 1 | H19: =LAD!H13 -> 0 | ... K19: =LAD!K13 -> 1 | L19: =COUNTIF($B$8:$K$8,"Laki-Laki") -> 5 | M19: =COUNTIF($B$8:$K$8,"Perempuan") -> 5 | N19: =SUMIF($B$8:$K$8,"Laki-Laki",B19:K19) -> 4 | O19: =SUMIF($B$8:$K$8,"Perempuan",B19:K19) -> 4 | P19: =IF(N19=0,0.3,IF(N19=L19,L19-0.3,N19)) -> 4 | Q19: =IF(O19=0,0.3,IF(O19=M19,M19-0.3,O19)) -> 4 | R19: =LN((L19-P19)/P19) -> -1.3862944 | S19: =LN((M19-Q19)/Q19) -> -1.3862944 | T19: =R19-AVERAGE($R$11:$R$110) -> -1.2916094 | U19: =S19-AVERAGE($S$11:$S$110) -> -1.2916094 | V19: =SQRT(1/P19+1/(L19-P19)) -> 1.118034 | W19: =SQRT(1/Q19+1/(M19-Q19)) -> 1.118034 | X19: =T19-U19 -> 0 | Y19: =SQRT(V19^2+W19^2) -> 1.5811388 | Z19: =X19/Y19 -> 0 | AA19: =IF(AND(ABS(X19)>=$B$4,ABS(Z19)>=$B$5),"DIF Besar - review",IF(AND(ABS(X19)>=$B$3,ABS(Z19)>=$B$5),"DIF Moderat - cek","Negligible")) -> Negligible | AB19: =IF(ABS(X19)>=$B$4,"Berpotensi Bias - Tinjau Konten",IF(ABS(X19)>=$B$3,"Indikasi Ringan - Pantau","Tidak Ada Indikasi Bias")) -> Tidak Ada Indikasi Bias
A20: =LAD!A14 -> 10. Variasi dalam proses dibagi menjadi 2 yaitu, variasi umum dan variasi khusus. Variasi umum adalah … | B20: =LAD!B14 -> 1 | C20: =LAD!C14 -> 1 | D20: =LAD!D14 -> 1 | E20: =LAD!E14 -> 1 | F20: =LAD!F14 -> 1 | G20: =LAD!G14 -> 0 | H20: =LAD!H14 -> 1 | ... K20: =LAD!K14 -> 0 | L20: =COUNTIF($B$8:$K$8,"Laki-Laki") -> 5 | M20: =COUNTIF($B$8:$K$8,"Perempuan") -> 5 | N20: =SUMIF($B$8:$K$8,"Laki-Laki",B20:K20) -> 3 | O20: =SUMIF($B$8:$K$8,"Perempuan",B20:K20) -> 3 | P20: =IF(N20=0,0.3,IF(N20=L20,L20-0.3,N20)) -> 3 | Q20: =IF(O20=0,0.3,IF(O20=M20,M20-0.3,O20)) -> 3 | R20: =LN((L20-P20)/P20) -> -0.40546511 | S20: =LN((M20-Q20)/Q20) -> -0.40546511 | T20: =R20-AVERAGE($R$11:$R$110) -> -0.31078016 | U20: =S20-AVERAGE($S$11:$S$110) -> -0.31078016 | V20: =SQRT(1/P20+1/(L20-P20)) -> 0.91287093 | W20: =SQRT(1/Q20+1/(M20-Q20)) -> 0.91287093 | X20: =T20-U20 -> 0 | Y20: =SQRT(V20^2+W20^2) -> 1.2909944 | Z20: =X20/Y20 -> 0 | AA20: =IF(AND(ABS(X20)>=$B$4,ABS(Z20)>=$B$5),"DIF Besar - review",IF(AND(ABS(X20)>=$B$3,ABS(Z20)>=$B$5),"DIF Moderat - cek","Negligible")) -> Negligible | AB20: =IF(ABS(X20)>=$B$4,"Berpotensi Bias - Tinjau Konten",IF(ABS(X20)>=$B$3,"Indikasi Ringan - Pantau","Tidak Ada Indikasi Bias")) -> Tidak Ada Indikasi Bias
A21: =LAD!A15 -> 11. Apa yang dimaksud dengan confidence level dalam sampling? | B21: =LAD!B15 -> 1 | C21: =LAD!C15 -> 1 | D21: =LAD!D15 -> 1 | E21: =LAD!E15 -> 1 | F21: =LAD!F15 -> 0 | G21: =LAD!G15 -> 0 | H21: =LAD!H15 -> 0 | ... K21: =LAD!K15 -> 0 | L21: =COUNTIF($B$8:$K$8,"Laki-Laki") -> 5 | M21: =COUNTIF($B$8:$K$8,"Perempuan") -> 5 | N21: =SUMIF($B$8:$K$8,"Laki-Laki",B21:K21) -> 2 | O21: =SUMIF($B$8:$K$8,"Perempuan",B21:K21) -> 2 | P21: =IF(N21=0,0.3,IF(N21=L21,L21-0.3,N21)) -> 2 | Q21: =IF(O21=0,0.3,IF(O21=M21,M21-0.3,O21)) -> 2 | R21: =LN((L21-P21)/P21) -> 0.40546511 | S21: =LN((M21-Q21)/Q21) -> 0.40546511 | T21: =R21-AVERAGE($R$11:$R$110) -> 0.50015005 | U21: =S21-AVERAGE($S$11:$S$110) -> 0.50015005 | V21: =SQRT(1/P21+1/(L21-P21)) -> 0.91287093 | W21: =SQRT(1/Q21+1/(M21-Q21)) -> 0.91287093 | X21: =T21-U21 -> 0 | Y21: =SQRT(V21^2+W21^2) -> 1.2909944 | Z21: =X21/Y21 -> 0 | AA21: =IF(AND(ABS(X21)>=$B$4,ABS(Z21)>=$B$5),"DIF Besar - review",IF(AND(ABS(X21)>=$B$3,ABS(Z21)>=$B$5),"DIF Moderat - cek","Negligible")) -> Negligible | AB21: =IF(ABS(X21)>=$B$4,"Berpotensi Bias - Tinjau Konten",IF(ABS(X21)>=$B$3,"Indikasi Ringan - Pantau","Tidak Ada Indikasi Bias")) -> Tidak Ada Indikasi Bias
